[2025-04-23T22:42:06.919+0000] {taskinstance.py:1956} INFO - Dependencies all met for dep_context=non-requeueable deps ti=<TaskInstance: mbta_kafka_consumer_dag.run_kafka_consumer scheduled__2025-04-23T22:35:00+00:00 [queued]>
[2025-04-23T22:42:06.925+0000] {taskinstance.py:1956} INFO - Dependencies all met for dep_context=requeueable deps ti=<TaskInstance: mbta_kafka_consumer_dag.run_kafka_consumer scheduled__2025-04-23T22:35:00+00:00 [queued]>
[2025-04-23T22:42:06.925+0000] {taskinstance.py:2170} INFO - Starting attempt 2 of 2
[2025-04-23T22:42:06.934+0000] {taskinstance.py:2191} INFO - Executing <Task(PythonOperator): run_kafka_consumer> on 2025-04-23 22:35:00+00:00
[2025-04-23T22:42:06.937+0000] {standard_task_runner.py:60} INFO - Started process 458 to run task
[2025-04-23T22:42:06.940+0000] {standard_task_runner.py:87} INFO - Running: ['***', 'tasks', 'run', 'mbta_kafka_consumer_dag', 'run_kafka_consumer', 'scheduled__2025-04-23T22:35:00+00:00', '--job-id', '664', '--raw', '--subdir', 'DAGS_FOLDER/mbta_kafka_consumer_dag.py', '--cfg-path', '/tmp/tmp5ru1vmb6']
[2025-04-23T22:42:06.942+0000] {standard_task_runner.py:88} INFO - Job 664: Subtask run_kafka_consumer
[2025-04-23T22:42:06.985+0000] {task_command.py:423} INFO - Running <TaskInstance: mbta_kafka_consumer_dag.run_kafka_consumer scheduled__2025-04-23T22:35:00+00:00 [running]> on host d0e890afb95b
[2025-04-23T22:42:07.049+0000] {taskinstance.py:2480} INFO - Exporting env vars: AIRFLOW_CTX_DAG_OWNER='***' AIRFLOW_CTX_DAG_ID='mbta_kafka_consumer_dag' AIRFLOW_CTX_TASK_ID='run_kafka_consumer' AIRFLOW_CTX_EXECUTION_DATE='2025-04-23T22:35:00+00:00' AIRFLOW_CTX_TRY_NUMBER='2' AIRFLOW_CTX_DAG_RUN_ID='scheduled__2025-04-23T22:35:00+00:00'
[2025-04-23T22:42:07.051+0000] {connection.py:370} INFO - Snowflake Connector for Python Version: 3.6.0, Python Version: 3.9.18, Platform: Linux-6.10.14-linuxkit-aarch64-with-glibc2.36
[2025-04-23T22:42:07.051+0000] {connection.py:1171} INFO - This connection is in OCSP Fail Open Mode. TLS Certificates would be checked for validity and revocation status. Any other Certificate Revocation related exceptions or OCSP Responder failures would be disregarded in favor of connectivity.
[2025-04-23T22:42:07.845+0000] {mbta_kafka_consumer.py:45} INFO - âœ… Connected to Snowflake successfully.
[2025-04-23T22:42:07.846+0000] {mbta_kafka_consumer.py:220} INFO - ðŸš€ Starting MBTA Kafka Consumer...
[2025-04-23T22:42:07.853+0000] {conn.py:1532} WARNING - DNS lookup failed for kafka:9092, exception was [Errno -2] Name or service not known. Is your advertised.listeners (called advertised.host.name before Kafka 9) correct and resolvable?
[2025-04-23T22:42:07.853+0000] {conn.py:322} ERROR - <BrokerConnection client_id=kafka-python-2.1.5, node_id=bootstrap-0 host=kafka:9092 <connecting> [unspecified None]>: DNS lookup failed for kafka:9092 (0)
[2025-04-23T22:42:07.853+0000] {conn.py:936} ERROR - <BrokerConnection client_id=kafka-python-2.1.5, node_id=bootstrap-0 host=kafka:9092 <connecting> [unspecified None]>: Closing connection. KafkaConnectionError: DNS failure
[2025-04-23T22:42:07.854+0000] {client_async.py:1048} WARNING - No node available during check_version; sleeping 0.04 secs
[2025-04-23T22:42:07.898+0000] {conn.py:1532} WARNING - DNS lookup failed for kafka:9092, exception was [Errno -2] Name or service not known. Is your advertised.listeners (called advertised.host.name before Kafka 9) correct and resolvable?
[2025-04-23T22:42:07.898+0000] {conn.py:322} ERROR - <BrokerConnection client_id=kafka-python-2.1.5, node_id=bootstrap-0 host=kafka:9092 <connecting> [unspecified None]>: DNS lookup failed for kafka:9092 (0)
[2025-04-23T22:42:07.899+0000] {conn.py:936} ERROR - <BrokerConnection client_id=kafka-python-2.1.5, node_id=bootstrap-0 host=kafka:9092 <connecting> [unspecified None]>: Closing connection. KafkaConnectionError: DNS failure
[2025-04-23T22:42:07.899+0000] {client_async.py:1048} WARNING - No node available during check_version; sleeping 0.11 secs
[2025-04-23T22:42:08.017+0000] {conn.py:1532} WARNING - DNS lookup failed for kafka:9092, exception was [Errno -2] Name or service not known. Is your advertised.listeners (called advertised.host.name before Kafka 9) correct and resolvable?
[2025-04-23T22:42:08.018+0000] {conn.py:322} ERROR - <BrokerConnection client_id=kafka-python-2.1.5, node_id=bootstrap-0 host=kafka:9092 <connecting> [unspecified None]>: DNS lookup failed for kafka:9092 (0)
[2025-04-23T22:42:08.019+0000] {conn.py:936} ERROR - <BrokerConnection client_id=kafka-python-2.1.5, node_id=bootstrap-0 host=kafka:9092 <connecting> [unspecified None]>: Closing connection. KafkaConnectionError: DNS failure
[2025-04-23T22:42:08.019+0000] {client_async.py:1048} WARNING - No node available during check_version; sleeping 0.18 secs
[2025-04-23T22:42:08.206+0000] {conn.py:1532} WARNING - DNS lookup failed for kafka:9092, exception was [Errno -2] Name or service not known. Is your advertised.listeners (called advertised.host.name before Kafka 9) correct and resolvable?
[2025-04-23T22:42:08.208+0000] {conn.py:322} ERROR - <BrokerConnection client_id=kafka-python-2.1.5, node_id=bootstrap-0 host=kafka:9092 <connecting> [unspecified None]>: DNS lookup failed for kafka:9092 (0)
[2025-04-23T22:42:08.208+0000] {conn.py:936} ERROR - <BrokerConnection client_id=kafka-python-2.1.5, node_id=bootstrap-0 host=kafka:9092 <connecting> [unspecified None]>: Closing connection. KafkaConnectionError: DNS failure
[2025-04-23T22:42:08.209+0000] {client_async.py:1048} WARNING - No node available during check_version; sleeping 0.37 secs
[2025-04-23T22:42:08.592+0000] {conn.py:1532} WARNING - DNS lookup failed for kafka:9092, exception was [Errno -2] Name or service not known. Is your advertised.listeners (called advertised.host.name before Kafka 9) correct and resolvable?
[2025-04-23T22:42:08.593+0000] {conn.py:322} ERROR - <BrokerConnection client_id=kafka-python-2.1.5, node_id=bootstrap-0 host=kafka:9092 <connecting> [unspecified None]>: DNS lookup failed for kafka:9092 (0)
[2025-04-23T22:42:08.594+0000] {conn.py:936} ERROR - <BrokerConnection client_id=kafka-python-2.1.5, node_id=bootstrap-0 host=kafka:9092 <connecting> [unspecified None]>: Closing connection. KafkaConnectionError: DNS failure
[2025-04-23T22:42:08.595+0000] {client_async.py:1048} WARNING - No node available during check_version; sleeping 0.68 secs
[2025-04-23T22:42:09.284+0000] {conn.py:1532} WARNING - DNS lookup failed for kafka:9092, exception was [Errno -2] Name or service not known. Is your advertised.listeners (called advertised.host.name before Kafka 9) correct and resolvable?
[2025-04-23T22:42:09.285+0000] {conn.py:322} ERROR - <BrokerConnection client_id=kafka-python-2.1.5, node_id=bootstrap-0 host=kafka:9092 <connecting> [unspecified None]>: DNS lookup failed for kafka:9092 (0)
[2025-04-23T22:42:09.285+0000] {conn.py:936} ERROR - <BrokerConnection client_id=kafka-python-2.1.5, node_id=bootstrap-0 host=kafka:9092 <connecting> [unspecified None]>: Closing connection. KafkaConnectionError: DNS failure
[2025-04-23T22:42:09.285+0000] {client_async.py:1048} WARNING - No node available during check_version; sleeping 0.56 secs
[2025-04-23T22:42:09.852+0000] {taskinstance.py:2698} ERROR - Task failed with exception
Traceback (most recent call last):
  File "/home/airflow/.local/lib/python3.9/site-packages/airflow/models/taskinstance.py", line 433, in _execute_task
    result = execute_callable(context=context, **execute_callable_kwargs)
  File "/home/airflow/.local/lib/python3.9/site-packages/airflow/operators/python.py", line 199, in execute
    return_value = self.execute_callable()
  File "/home/airflow/.local/lib/python3.9/site-packages/airflow/operators/python.py", line 216, in execute_callable
    return self.python_callable(*self.op_args, **self.op_kwargs)
  File "/opt/airflow/dags/mbta_kafka_consumer.py", line 221, in consume_messages
    consumer = KafkaConsumer(
  File "/home/airflow/.local/lib/python3.9/site-packages/kafka/consumer/group.py", line 383, in __init__
    self._client = self.config['kafka_client'](metrics=self._metrics, **self.config)
  File "/home/airflow/.local/lib/python3.9/site-packages/kafka/client_async.py", line 262, in __init__
    self.config['api_version'] = self.check_version()
  File "/home/airflow/.local/lib/python3.9/site-packages/kafka/client_async.py", line 1073, in check_version
    raise Errors.NoBrokersAvailable()
kafka.errors.NoBrokersAvailable: NoBrokersAvailable
[2025-04-23T22:42:09.871+0000] {taskinstance.py:1138} INFO - Marking task as FAILED. dag_id=mbta_kafka_consumer_dag, task_id=run_kafka_consumer, execution_date=20250423T223500, start_date=20250423T224206, end_date=20250423T224209
[2025-04-23T22:42:09.881+0000] {standard_task_runner.py:107} ERROR - Failed to execute job 664 for task run_kafka_consumer (NoBrokersAvailable; 458)
[2025-04-23T22:42:09.896+0000] {local_task_job_runner.py:234} INFO - Task exited with return code 1
[2025-04-23T22:42:09.927+0000] {taskinstance.py:3280} INFO - 0 downstream tasks scheduled from follow-on schedule check
