[2025-04-22T19:30:01.753+0000] {taskinstance.py:1956} INFO - Dependencies all met for dep_context=non-requeueable deps ti=<TaskInstance: mbta_kafka_consumer_dag.run_kafka_consumer scheduled__2025-04-22T19:25:00+00:00 [queued]>
[2025-04-22T19:30:01.763+0000] {taskinstance.py:1956} INFO - Dependencies all met for dep_context=requeueable deps ti=<TaskInstance: mbta_kafka_consumer_dag.run_kafka_consumer scheduled__2025-04-22T19:25:00+00:00 [queued]>
[2025-04-22T19:30:01.763+0000] {taskinstance.py:2170} INFO - Starting attempt 1 of 2
[2025-04-22T19:30:01.773+0000] {taskinstance.py:2191} INFO - Executing <Task(PythonOperator): run_kafka_consumer> on 2025-04-22 19:25:00+00:00
[2025-04-22T19:30:01.779+0000] {standard_task_runner.py:60} INFO - Started process 927 to run task
[2025-04-22T19:30:01.784+0000] {standard_task_runner.py:87} INFO - Running: ['***', 'tasks', 'run', 'mbta_kafka_consumer_dag', 'run_kafka_consumer', 'scheduled__2025-04-22T19:25:00+00:00', '--job-id', '83', '--raw', '--subdir', 'DAGS_FOLDER/mbta_kafka_consumer_dag.py', '--cfg-path', '/tmp/tmpnakpqd1r']
[2025-04-22T19:30:01.790+0000] {standard_task_runner.py:88} INFO - Job 83: Subtask run_kafka_consumer
[2025-04-22T19:30:01.808+0000] {logging_mixin.py:188} WARNING - /home/***/.local/lib/python3.9/site-packages/***/settings.py:194 DeprecationWarning: The sql_alchemy_conn option in [core] has been moved to the sql_alchemy_conn option in [database] - the old setting has been used, but please update your config.
[2025-04-22T19:30:01.854+0000] {task_command.py:423} INFO - Running <TaskInstance: mbta_kafka_consumer_dag.run_kafka_consumer scheduled__2025-04-22T19:25:00+00:00 [running]> on host 2c22c90a5849
[2025-04-22T19:30:01.926+0000] {taskinstance.py:2480} INFO - Exporting env vars: AIRFLOW_CTX_DAG_OWNER='***' AIRFLOW_CTX_DAG_ID='mbta_kafka_consumer_dag' AIRFLOW_CTX_TASK_ID='run_kafka_consumer' AIRFLOW_CTX_EXECUTION_DATE='2025-04-22T19:25:00+00:00' AIRFLOW_CTX_TRY_NUMBER='1' AIRFLOW_CTX_DAG_RUN_ID='scheduled__2025-04-22T19:25:00+00:00'
[2025-04-22T19:30:01.927+0000] {connection.py:370} INFO - Snowflake Connector for Python Version: 3.6.0, Python Version: 3.9.18, Platform: Linux-6.10.14-linuxkit-aarch64-with-glibc2.36
[2025-04-22T19:30:01.927+0000] {connection.py:1171} INFO - This connection is in OCSP Fail Open Mode. TLS Certificates would be checked for validity and revocation status. Any other Certificate Revocation related exceptions or OCSP Responder failures would be disregarded in favor of connectivity.
[2025-04-22T19:30:02.891+0000] {mbta_kafka_consumer.py:45} INFO - âœ… Connected to Snowflake successfully.
[2025-04-22T19:30:02.892+0000] {mbta_kafka_consumer.py:219} INFO - ðŸš€ Starting MBTA Kafka Consumer...
[2025-04-22T19:30:02.897+0000] {conn.py:1532} WARNING - DNS lookup failed for kafka:9092, exception was [Errno -2] Name or service not known. Is your advertised.listeners (called advertised.host.name before Kafka 9) correct and resolvable?
[2025-04-22T19:30:02.898+0000] {conn.py:322} ERROR - <BrokerConnection client_id=kafka-python-2.1.5, node_id=bootstrap-0 host=kafka:9092 <connecting> [unspecified None]>: DNS lookup failed for kafka:9092 (0)
[2025-04-22T19:30:02.898+0000] {conn.py:936} ERROR - <BrokerConnection client_id=kafka-python-2.1.5, node_id=bootstrap-0 host=kafka:9092 <connecting> [unspecified None]>: Closing connection. KafkaConnectionError: DNS failure
[2025-04-22T19:30:02.898+0000] {client_async.py:1048} WARNING - No node available during check_version; sleeping 0.04 secs
[2025-04-22T19:30:02.947+0000] {conn.py:1532} WARNING - DNS lookup failed for kafka:9092, exception was [Errno -2] Name or service not known. Is your advertised.listeners (called advertised.host.name before Kafka 9) correct and resolvable?
[2025-04-22T19:30:02.947+0000] {conn.py:322} ERROR - <BrokerConnection client_id=kafka-python-2.1.5, node_id=bootstrap-0 host=kafka:9092 <connecting> [unspecified None]>: DNS lookup failed for kafka:9092 (0)
[2025-04-22T19:30:02.948+0000] {conn.py:936} ERROR - <BrokerConnection client_id=kafka-python-2.1.5, node_id=bootstrap-0 host=kafka:9092 <connecting> [unspecified None]>: Closing connection. KafkaConnectionError: DNS failure
[2025-04-22T19:30:02.948+0000] {client_async.py:1048} WARNING - No node available during check_version; sleeping 0.09 secs
[2025-04-22T19:30:03.045+0000] {conn.py:1532} WARNING - DNS lookup failed for kafka:9092, exception was [Errno -2] Name or service not known. Is your advertised.listeners (called advertised.host.name before Kafka 9) correct and resolvable?
[2025-04-22T19:30:03.045+0000] {conn.py:322} ERROR - <BrokerConnection client_id=kafka-python-2.1.5, node_id=bootstrap-0 host=kafka:9092 <connecting> [unspecified None]>: DNS lookup failed for kafka:9092 (0)
[2025-04-22T19:30:03.046+0000] {conn.py:936} ERROR - <BrokerConnection client_id=kafka-python-2.1.5, node_id=bootstrap-0 host=kafka:9092 <connecting> [unspecified None]>: Closing connection. KafkaConnectionError: DNS failure
[2025-04-22T19:30:03.046+0000] {client_async.py:1048} WARNING - No node available during check_version; sleeping 0.17 secs
[2025-04-22T19:30:03.219+0000] {conn.py:1532} WARNING - DNS lookup failed for kafka:9092, exception was [Errno -2] Name or service not known. Is your advertised.listeners (called advertised.host.name before Kafka 9) correct and resolvable?
[2025-04-22T19:30:03.219+0000] {conn.py:322} ERROR - <BrokerConnection client_id=kafka-python-2.1.5, node_id=bootstrap-0 host=kafka:9092 <connecting> [unspecified None]>: DNS lookup failed for kafka:9092 (0)
[2025-04-22T19:30:03.220+0000] {conn.py:936} ERROR - <BrokerConnection client_id=kafka-python-2.1.5, node_id=bootstrap-0 host=kafka:9092 <connecting> [unspecified None]>: Closing connection. KafkaConnectionError: DNS failure
[2025-04-22T19:30:03.221+0000] {client_async.py:1048} WARNING - No node available during check_version; sleeping 0.37 secs
[2025-04-22T19:30:03.601+0000] {conn.py:1532} WARNING - DNS lookup failed for kafka:9092, exception was [Errno -2] Name or service not known. Is your advertised.listeners (called advertised.host.name before Kafka 9) correct and resolvable?
[2025-04-22T19:30:03.602+0000] {conn.py:322} ERROR - <BrokerConnection client_id=kafka-python-2.1.5, node_id=bootstrap-0 host=kafka:9092 <connecting> [unspecified None]>: DNS lookup failed for kafka:9092 (0)
[2025-04-22T19:30:03.602+0000] {conn.py:936} ERROR - <BrokerConnection client_id=kafka-python-2.1.5, node_id=bootstrap-0 host=kafka:9092 <connecting> [unspecified None]>: Closing connection. KafkaConnectionError: DNS failure
[2025-04-22T19:30:03.603+0000] {client_async.py:1048} WARNING - No node available during check_version; sleeping 0.87 secs
[2025-04-22T19:30:04.487+0000] {conn.py:1532} WARNING - DNS lookup failed for kafka:9092, exception was [Errno -2] Name or service not known. Is your advertised.listeners (called advertised.host.name before Kafka 9) correct and resolvable?
[2025-04-22T19:30:04.490+0000] {conn.py:322} ERROR - <BrokerConnection client_id=kafka-python-2.1.5, node_id=bootstrap-0 host=kafka:9092 <connecting> [unspecified None]>: DNS lookup failed for kafka:9092 (0)
[2025-04-22T19:30:04.495+0000] {conn.py:936} ERROR - <BrokerConnection client_id=kafka-python-2.1.5, node_id=bootstrap-0 host=kafka:9092 <connecting> [unspecified None]>: Closing connection. KafkaConnectionError: DNS failure
[2025-04-22T19:30:04.497+0000] {client_async.py:1048} WARNING - No node available during check_version; sleeping 0.40 secs
[2025-04-22T19:30:04.900+0000] {taskinstance.py:2698} ERROR - Task failed with exception
Traceback (most recent call last):
  File "/home/airflow/.local/lib/python3.9/site-packages/airflow/models/taskinstance.py", line 433, in _execute_task
    result = execute_callable(context=context, **execute_callable_kwargs)
  File "/home/airflow/.local/lib/python3.9/site-packages/airflow/operators/python.py", line 199, in execute
    return_value = self.execute_callable()
  File "/home/airflow/.local/lib/python3.9/site-packages/airflow/operators/python.py", line 216, in execute_callable
    return self.python_callable(*self.op_args, **self.op_kwargs)
  File "/opt/airflow/dags/mbta_kafka_consumer.py", line 220, in consume_messages
    consumer = KafkaConsumer(
  File "/home/airflow/.local/lib/python3.9/site-packages/kafka/consumer/group.py", line 383, in __init__
    self._client = self.config['kafka_client'](metrics=self._metrics, **self.config)
  File "/home/airflow/.local/lib/python3.9/site-packages/kafka/client_async.py", line 262, in __init__
    self.config['api_version'] = self.check_version()
  File "/home/airflow/.local/lib/python3.9/site-packages/kafka/client_async.py", line 1073, in check_version
    raise Errors.NoBrokersAvailable()
kafka.errors.NoBrokersAvailable: NoBrokersAvailable
[2025-04-22T19:30:04.923+0000] {taskinstance.py:1138} INFO - Marking task as UP_FOR_RETRY. dag_id=mbta_kafka_consumer_dag, task_id=run_kafka_consumer, execution_date=20250422T192500, start_date=20250422T193001, end_date=20250422T193004
[2025-04-22T19:30:04.943+0000] {standard_task_runner.py:107} ERROR - Failed to execute job 83 for task run_kafka_consumer (NoBrokersAvailable; 927)
[2025-04-22T19:30:04.977+0000] {local_task_job_runner.py:234} INFO - Task exited with return code 1
[2025-04-22T19:30:05.010+0000] {taskinstance.py:3280} INFO - 0 downstream tasks scheduled from follow-on schedule check
