[2025-04-24T17:30:01.033+0000] {taskinstance.py:1956} INFO - Dependencies all met for dep_context=non-requeueable deps ti=<TaskInstance: mbta_kafka_consumer_dag.run_kafka_consumer scheduled__2025-04-24T17:25:00+00:00 [queued]>
[2025-04-24T17:30:01.038+0000] {taskinstance.py:1956} INFO - Dependencies all met for dep_context=requeueable deps ti=<TaskInstance: mbta_kafka_consumer_dag.run_kafka_consumer scheduled__2025-04-24T17:25:00+00:00 [queued]>
[2025-04-24T17:30:01.038+0000] {taskinstance.py:2170} INFO - Starting attempt 1 of 2
[2025-04-24T17:30:01.046+0000] {taskinstance.py:2191} INFO - Executing <Task(PythonOperator): run_kafka_consumer> on 2025-04-24 17:25:00+00:00
[2025-04-24T17:30:01.049+0000] {standard_task_runner.py:60} INFO - Started process 1073 to run task
[2025-04-24T17:30:01.052+0000] {standard_task_runner.py:87} INFO - Running: ['***', 'tasks', 'run', 'mbta_kafka_consumer_dag', 'run_kafka_consumer', 'scheduled__2025-04-24T17:25:00+00:00', '--job-id', '1044', '--raw', '--subdir', 'DAGS_FOLDER/mbta_kafka_consumer_dag.py', '--cfg-path', '/tmp/tmpu1i3k0_3']
[2025-04-24T17:30:01.054+0000] {standard_task_runner.py:88} INFO - Job 1044: Subtask run_kafka_consumer
[2025-04-24T17:30:01.099+0000] {task_command.py:423} INFO - Running <TaskInstance: mbta_kafka_consumer_dag.run_kafka_consumer scheduled__2025-04-24T17:25:00+00:00 [running]> on host 2f7111ce7fe0
[2025-04-24T17:30:01.162+0000] {taskinstance.py:2480} INFO - Exporting env vars: AIRFLOW_CTX_DAG_OWNER='***' AIRFLOW_CTX_DAG_ID='mbta_kafka_consumer_dag' AIRFLOW_CTX_TASK_ID='run_kafka_consumer' AIRFLOW_CTX_EXECUTION_DATE='2025-04-24T17:25:00+00:00' AIRFLOW_CTX_TRY_NUMBER='1' AIRFLOW_CTX_DAG_RUN_ID='scheduled__2025-04-24T17:25:00+00:00'
[2025-04-24T17:30:01.163+0000] {connection.py:370} INFO - Snowflake Connector for Python Version: 3.6.0, Python Version: 3.9.18, Platform: Linux-6.10.14-linuxkit-aarch64-with-glibc2.36
[2025-04-24T17:30:01.164+0000] {connection.py:1171} INFO - This connection is in OCSP Fail Open Mode. TLS Certificates would be checked for validity and revocation status. Any other Certificate Revocation related exceptions or OCSP Responder failures would be disregarded in favor of connectivity.
[2025-04-24T17:30:05.172+0000] {connectionpool.py:824} WARNING - Retrying (Retry(total=0, connect=None, read=None, redirect=None, status=None)) after connection broken by 'NewConnectionError('<snowflake.connector.vendored.urllib3.connection.HTTPSConnection object at 0xffff964dd370>: Failed to establish a new connection: [Errno -3] Temporary failure in name resolution')': /session/v1/login-request?request_id=6d2b3142-83e4-41df-8fc7-95486a5ebcc7&databaseName=MBTA_DB2&schemaName=MBTA_SCHEMA2&warehouse=MBTA_WH2&request_guid=9deebce3-5bac-4864-9043-a3edbfff5595
[2025-04-24T17:30:14.216+0000] {connectionpool.py:824} WARNING - Retrying (Retry(total=0, connect=None, read=None, redirect=None, status=None)) after connection broken by 'NewConnectionError('<snowflake.connector.vendored.urllib3.connection.HTTPSConnection object at 0xffff964ddc10>: Failed to establish a new connection: [Errno -3] Temporary failure in name resolution')': /session/v1/login-request?request_id=1c384d40-a7e3-4da8-a6f0-46f3c672e561&databaseName=MBTA_DB2&schemaName=MBTA_SCHEMA2&warehouse=MBTA_WH2&request_guid=c32cbf34-80d6-4388-8150-d1cc327ca380
[2025-04-24T17:30:22.250+0000] {mbta_kafka_consumer.py:55} ERROR - ‚ùå Error connecting to Snowflake: 250001: 250001: Could not connect to Snowflake backend after 2 attempt(s).Aborting
[2025-04-24T17:30:22.282+0000] {local_task_job_runner.py:234} INFO - Task exited with return code 1
[2025-04-24T17:30:22.318+0000] {taskinstance.py:3280} INFO - 0 downstream tasks scheduled from follow-on schedule check
