[2025-04-25T04:17:32.249+0000] {taskinstance.py:1956} INFO - Dependencies all met for dep_context=non-requeueable deps ti=<TaskInstance: mbta_kafka_consumer_dag.run_kafka_consumer scheduled__2025-04-25T04:10:00+00:00 [queued]>
[2025-04-25T04:17:32.254+0000] {taskinstance.py:1956} INFO - Dependencies all met for dep_context=requeueable deps ti=<TaskInstance: mbta_kafka_consumer_dag.run_kafka_consumer scheduled__2025-04-25T04:10:00+00:00 [queued]>
[2025-04-25T04:17:32.255+0000] {taskinstance.py:2170} INFO - Starting attempt 2 of 2
[2025-04-25T04:17:32.262+0000] {taskinstance.py:2191} INFO - Executing <Task(PythonOperator): run_kafka_consumer> on 2025-04-25 04:10:00+00:00
[2025-04-25T04:17:32.265+0000] {standard_task_runner.py:60} INFO - Started process 1337 to run task
[2025-04-25T04:17:32.272+0000] {standard_task_runner.py:87} INFO - Running: ['***', 'tasks', 'run', 'mbta_kafka_consumer_dag', 'run_kafka_consumer', 'scheduled__2025-04-25T04:10:00+00:00', '--job-id', '1308', '--raw', '--subdir', 'DAGS_FOLDER/mbta_kafka_consumer_dag.py', '--cfg-path', '/tmp/tmpr9wapmy1']
[2025-04-25T04:17:32.275+0000] {standard_task_runner.py:88} INFO - Job 1308: Subtask run_kafka_consumer
[2025-04-25T04:17:32.315+0000] {task_command.py:423} INFO - Running <TaskInstance: mbta_kafka_consumer_dag.run_kafka_consumer scheduled__2025-04-25T04:10:00+00:00 [running]> on host f72d543edf4d
[2025-04-25T04:17:32.372+0000] {taskinstance.py:2480} INFO - Exporting env vars: AIRFLOW_CTX_DAG_OWNER='***' AIRFLOW_CTX_DAG_ID='mbta_kafka_consumer_dag' AIRFLOW_CTX_TASK_ID='run_kafka_consumer' AIRFLOW_CTX_EXECUTION_DATE='2025-04-25T04:10:00+00:00' AIRFLOW_CTX_TRY_NUMBER='2' AIRFLOW_CTX_DAG_RUN_ID='scheduled__2025-04-25T04:10:00+00:00'
[2025-04-25T04:17:32.375+0000] {connection.py:370} INFO - Snowflake Connector for Python Version: 3.6.0, Python Version: 3.9.18, Platform: Linux-6.10.14-linuxkit-aarch64-with-glibc2.36
[2025-04-25T04:17:32.376+0000] {connection.py:1171} INFO - This connection is in OCSP Fail Open Mode. TLS Certificates would be checked for validity and revocation status. Any other Certificate Revocation related exceptions or OCSP Responder failures would be disregarded in favor of connectivity.
[2025-04-25T04:17:32.381+0000] {connectionpool.py:824} WARNING - Retrying (Retry(total=0, connect=None, read=None, redirect=None, status=None)) after connection broken by 'NewConnectionError('<snowflake.connector.vendored.urllib3.connection.HTTPSConnection object at 0xffff860fba30>: Failed to establish a new connection: [Errno -3] Temporary failure in name resolution')': /session/v1/login-request?request_id=c2859059-b892-4a09-aeb9-99845eaa917c&databaseName=MBTA_DB2&schemaName=MBTA_SCHEMA2&warehouse=MBTA_WH2&request_guid=5a521370-faaf-4cf6-b989-7d27a93b67b9
[2025-04-25T04:17:41.417+0000] {connectionpool.py:824} WARNING - Retrying (Retry(total=0, connect=None, read=None, redirect=None, status=None)) after connection broken by 'NewConnectionError('<snowflake.connector.vendored.urllib3.connection.HTTPSConnection object at 0xffff860c1250>: Failed to establish a new connection: [Errno -3] Temporary failure in name resolution')': /session/v1/login-request?request_id=6d422ce5-863a-4833-a011-1f331a593e7d&databaseName=MBTA_DB2&schemaName=MBTA_SCHEMA2&warehouse=MBTA_WH2&request_guid=7d780693-9fb0-4a90-9ea2-3a4fab6ce7ac
[2025-04-25T04:17:45.445+0000] {mbta_kafka_consumer.py:55} ERROR - ‚ùå Error connecting to Snowflake: 250001: 250001: Could not connect to Snowflake backend after 2 attempt(s).Aborting
[2025-04-25T04:17:45.484+0000] {local_task_job_runner.py:234} INFO - Task exited with return code 1
[2025-04-25T04:17:45.527+0000] {taskinstance.py:3280} INFO - 0 downstream tasks scheduled from follow-on schedule check
