[2025-04-24T01:52:06.596+0000] {taskinstance.py:1956} INFO - Dependencies all met for dep_context=non-requeueable deps ti=<TaskInstance: mbta_ingestion_dag.load_to_snowflake scheduled__2025-04-24T01:45:00+00:00 [queued]>
[2025-04-24T01:52:06.601+0000] {taskinstance.py:1956} INFO - Dependencies all met for dep_context=requeueable deps ti=<TaskInstance: mbta_ingestion_dag.load_to_snowflake scheduled__2025-04-24T01:45:00+00:00 [queued]>
[2025-04-24T01:52:06.601+0000] {taskinstance.py:2170} INFO - Starting attempt 2 of 2
[2025-04-24T01:52:06.608+0000] {taskinstance.py:2191} INFO - Executing <Task(PythonOperator): load_to_snowflake> on 2025-04-24 01:45:00+00:00
[2025-04-24T01:52:06.618+0000] {standard_task_runner.py:60} INFO - Started process 326 to run task
[2025-04-24T01:52:06.625+0000] {standard_task_runner.py:87} INFO - Running: ['***', 'tasks', 'run', 'mbta_ingestion_dag', 'load_to_snowflake', 'scheduled__2025-04-24T01:45:00+00:00', '--job-id', '803', '--raw', '--subdir', 'DAGS_FOLDER/mbta_ingestion_dag.py', '--cfg-path', '/tmp/tmpjdejq7q4']
[2025-04-24T01:52:06.630+0000] {standard_task_runner.py:88} INFO - Job 803: Subtask load_to_snowflake
[2025-04-24T01:52:06.689+0000] {task_command.py:423} INFO - Running <TaskInstance: mbta_ingestion_dag.load_to_snowflake scheduled__2025-04-24T01:45:00+00:00 [running]> on host 2c6b88bcb39d
[2025-04-24T01:52:06.756+0000] {taskinstance.py:2480} INFO - Exporting env vars: AIRFLOW_CTX_DAG_OWNER='***' AIRFLOW_CTX_DAG_ID='mbta_ingestion_dag' AIRFLOW_CTX_TASK_ID='load_to_snowflake' AIRFLOW_CTX_EXECUTION_DATE='2025-04-24T01:45:00+00:00' AIRFLOW_CTX_TRY_NUMBER='2' AIRFLOW_CTX_DAG_RUN_ID='scheduled__2025-04-24T01:45:00+00:00'
[2025-04-24T01:52:06.758+0000] {mbta_ingestion_dag.py:35} INFO - ðŸš€ Launching Kafka consumer to process and load data into Snowflake...
[2025-04-24T01:52:06.758+0000] {connection.py:370} INFO - Snowflake Connector for Python Version: 3.6.0, Python Version: 3.9.18, Platform: Linux-6.10.14-linuxkit-aarch64-with-glibc2.36
[2025-04-24T01:52:06.759+0000] {connection.py:1171} INFO - This connection is in OCSP Fail Open Mode. TLS Certificates would be checked for validity and revocation status. Any other Certificate Revocation related exceptions or OCSP Responder failures would be disregarded in favor of connectivity.
[2025-04-24T01:52:07.411+0000] {mbta_kafka_consumer.py:52} INFO - âœ… Connected to Snowflake successfully.
[2025-04-24T01:52:07.412+0000] {mbta_kafka_consumer.py:266} INFO - ðŸš€ Starting MBTA Kafka Consumer...
[2025-04-24T01:52:07.418+0000] {conn.py:1532} WARNING - DNS lookup failed for kafka:9092, exception was [Errno -2] Name or service not known. Is your advertised.listeners (called advertised.host.name before Kafka 9) correct and resolvable?
[2025-04-24T01:52:07.419+0000] {conn.py:322} ERROR - <BrokerConnection client_id=kafka-python-2.1.5, node_id=bootstrap-0 host=kafka:9092 <connecting> [unspecified None]>: DNS lookup failed for kafka:9092 (0)
[2025-04-24T01:52:07.419+0000] {conn.py:936} ERROR - <BrokerConnection client_id=kafka-python-2.1.5, node_id=bootstrap-0 host=kafka:9092 <connecting> [unspecified None]>: Closing connection. KafkaConnectionError: DNS failure
[2025-04-24T01:52:07.419+0000] {client_async.py:1048} WARNING - No node available during check_version; sleeping 0.05 secs
[2025-04-24T01:52:07.483+0000] {conn.py:1532} WARNING - DNS lookup failed for kafka:9092, exception was [Errno -2] Name or service not known. Is your advertised.listeners (called advertised.host.name before Kafka 9) correct and resolvable?
[2025-04-24T01:52:07.484+0000] {conn.py:322} ERROR - <BrokerConnection client_id=kafka-python-2.1.5, node_id=bootstrap-0 host=kafka:9092 <connecting> [unspecified None]>: DNS lookup failed for kafka:9092 (0)
[2025-04-24T01:52:07.485+0000] {conn.py:936} ERROR - <BrokerConnection client_id=kafka-python-2.1.5, node_id=bootstrap-0 host=kafka:9092 <connecting> [unspecified None]>: Closing connection. KafkaConnectionError: DNS failure
[2025-04-24T01:52:07.485+0000] {client_async.py:1048} WARNING - No node available during check_version; sleeping 0.10 secs
[2025-04-24T01:52:07.588+0000] {conn.py:1532} WARNING - DNS lookup failed for kafka:9092, exception was [Errno -2] Name or service not known. Is your advertised.listeners (called advertised.host.name before Kafka 9) correct and resolvable?
[2025-04-24T01:52:07.589+0000] {conn.py:322} ERROR - <BrokerConnection client_id=kafka-python-2.1.5, node_id=bootstrap-0 host=kafka:9092 <connecting> [unspecified None]>: DNS lookup failed for kafka:9092 (0)
[2025-04-24T01:52:07.589+0000] {conn.py:936} ERROR - <BrokerConnection client_id=kafka-python-2.1.5, node_id=bootstrap-0 host=kafka:9092 <connecting> [unspecified None]>: Closing connection. KafkaConnectionError: DNS failure
[2025-04-24T01:52:07.589+0000] {client_async.py:1048} WARNING - No node available during check_version; sleeping 0.17 secs
[2025-04-24T01:52:07.770+0000] {conn.py:1532} WARNING - DNS lookup failed for kafka:9092, exception was [Errno -2] Name or service not known. Is your advertised.listeners (called advertised.host.name before Kafka 9) correct and resolvable?
[2025-04-24T01:52:07.771+0000] {conn.py:322} ERROR - <BrokerConnection client_id=kafka-python-2.1.5, node_id=bootstrap-0 host=kafka:9092 <connecting> [unspecified None]>: DNS lookup failed for kafka:9092 (0)
[2025-04-24T01:52:07.772+0000] {conn.py:936} ERROR - <BrokerConnection client_id=kafka-python-2.1.5, node_id=bootstrap-0 host=kafka:9092 <connecting> [unspecified None]>: Closing connection. KafkaConnectionError: DNS failure
[2025-04-24T01:52:07.773+0000] {client_async.py:1048} WARNING - No node available during check_version; sleeping 0.45 secs
[2025-04-24T01:52:08.226+0000] {conn.py:1532} WARNING - DNS lookup failed for kafka:9092, exception was [Errno -2] Name or service not known. Is your advertised.listeners (called advertised.host.name before Kafka 9) correct and resolvable?
[2025-04-24T01:52:08.226+0000] {conn.py:322} ERROR - <BrokerConnection client_id=kafka-python-2.1.5, node_id=bootstrap-0 host=kafka:9092 <connecting> [unspecified None]>: DNS lookup failed for kafka:9092 (0)
[2025-04-24T01:52:08.226+0000] {conn.py:936} ERROR - <BrokerConnection client_id=kafka-python-2.1.5, node_id=bootstrap-0 host=kafka:9092 <connecting> [unspecified None]>: Closing connection. KafkaConnectionError: DNS failure
[2025-04-24T01:52:08.227+0000] {client_async.py:1048} WARNING - No node available during check_version; sleeping 0.72 secs
[2025-04-24T01:52:08.950+0000] {conn.py:1532} WARNING - DNS lookup failed for kafka:9092, exception was [Errno -2] Name or service not known. Is your advertised.listeners (called advertised.host.name before Kafka 9) correct and resolvable?
[2025-04-24T01:52:08.952+0000] {conn.py:322} ERROR - <BrokerConnection client_id=kafka-python-2.1.5, node_id=bootstrap-0 host=kafka:9092 <connecting> [unspecified None]>: DNS lookup failed for kafka:9092 (0)
[2025-04-24T01:52:08.952+0000] {conn.py:936} ERROR - <BrokerConnection client_id=kafka-python-2.1.5, node_id=bootstrap-0 host=kafka:9092 <connecting> [unspecified None]>: Closing connection. KafkaConnectionError: DNS failure
[2025-04-24T01:52:08.953+0000] {client_async.py:1048} WARNING - No node available during check_version; sleeping 0.46 secs
[2025-04-24T01:52:09.417+0000] {taskinstance.py:2698} ERROR - Task failed with exception
Traceback (most recent call last):
  File "/home/airflow/.local/lib/python3.9/site-packages/airflow/models/taskinstance.py", line 433, in _execute_task
    result = execute_callable(context=context, **execute_callable_kwargs)
  File "/home/airflow/.local/lib/python3.9/site-packages/airflow/operators/python.py", line 199, in execute
    return_value = self.execute_callable()
  File "/home/airflow/.local/lib/python3.9/site-packages/airflow/operators/python.py", line 216, in execute_callable
    return self.python_callable(*self.op_args, **self.op_kwargs)
  File "/opt/airflow/dags/mbta_ingestion_dag.py", line 36, in load_to_snowflake
    consume_messages()  # pulls and merges into Snowflake
  File "/opt/airflow/dags/mbta_kafka_consumer.py", line 267, in consume_messages
    consumer = KafkaConsumer(
  File "/home/airflow/.local/lib/python3.9/site-packages/kafka/consumer/group.py", line 383, in __init__
    self._client = self.config['kafka_client'](metrics=self._metrics, **self.config)
  File "/home/airflow/.local/lib/python3.9/site-packages/kafka/client_async.py", line 262, in __init__
    self.config['api_version'] = self.check_version()
  File "/home/airflow/.local/lib/python3.9/site-packages/kafka/client_async.py", line 1073, in check_version
    raise Errors.NoBrokersAvailable()
kafka.errors.NoBrokersAvailable: NoBrokersAvailable
[2025-04-24T01:52:09.450+0000] {taskinstance.py:1138} INFO - Marking task as FAILED. dag_id=mbta_ingestion_dag, task_id=load_to_snowflake, execution_date=20250424T014500, start_date=20250424T015206, end_date=20250424T015209
[2025-04-24T01:52:09.467+0000] {standard_task_runner.py:107} ERROR - Failed to execute job 803 for task load_to_snowflake (NoBrokersAvailable; 326)
[2025-04-24T01:52:09.515+0000] {local_task_job_runner.py:234} INFO - Task exited with return code 1
[2025-04-24T01:52:09.557+0000] {taskinstance.py:3280} INFO - 0 downstream tasks scheduled from follow-on schedule check
[2025-04-24T01:57:13.550+0000] {taskinstance.py:1956} INFO - Dependencies all met for dep_context=non-requeueable deps ti=<TaskInstance: mbta_ingestion_dag.load_to_snowflake scheduled__2025-04-24T01:45:00+00:00 [queued]>
[2025-04-24T01:57:13.557+0000] {taskinstance.py:1956} INFO - Dependencies all met for dep_context=requeueable deps ti=<TaskInstance: mbta_ingestion_dag.load_to_snowflake scheduled__2025-04-24T01:45:00+00:00 [queued]>
[2025-04-24T01:57:13.558+0000] {taskinstance.py:2170} INFO - Starting attempt 2 of 2
[2025-04-24T01:57:13.574+0000] {taskinstance.py:2191} INFO - Executing <Task(PythonOperator): load_to_snowflake> on 2025-04-24 01:45:00+00:00
[2025-04-24T01:57:13.587+0000] {standard_task_runner.py:60} INFO - Started process 195 to run task
[2025-04-24T01:57:13.600+0000] {standard_task_runner.py:87} INFO - Running: ['***', 'tasks', 'run', 'mbta_ingestion_dag', 'load_to_snowflake', 'scheduled__2025-04-24T01:45:00+00:00', '--job-id', '814', '--raw', '--subdir', 'DAGS_FOLDER/mbta_ingestion_dag.py', '--cfg-path', '/tmp/tmpcnrebypb']
[2025-04-24T01:57:13.608+0000] {standard_task_runner.py:88} INFO - Job 814: Subtask load_to_snowflake
[2025-04-24T01:57:13.695+0000] {task_command.py:423} INFO - Running <TaskInstance: mbta_ingestion_dag.load_to_snowflake scheduled__2025-04-24T01:45:00+00:00 [running]> on host 2691bd6fd735
[2025-04-24T01:57:13.896+0000] {taskinstance.py:2480} INFO - Exporting env vars: AIRFLOW_CTX_DAG_OWNER='***' AIRFLOW_CTX_DAG_ID='mbta_ingestion_dag' AIRFLOW_CTX_TASK_ID='load_to_snowflake' AIRFLOW_CTX_EXECUTION_DATE='2025-04-24T01:45:00+00:00' AIRFLOW_CTX_TRY_NUMBER='2' AIRFLOW_CTX_DAG_RUN_ID='scheduled__2025-04-24T01:45:00+00:00'
[2025-04-24T01:57:13.898+0000] {mbta_ingestion_dag.py:35} INFO - ðŸš€ Launching Kafka consumer to process and load data into Snowflake...
[2025-04-24T01:57:13.898+0000] {connection.py:370} INFO - Snowflake Connector for Python Version: 3.6.0, Python Version: 3.9.18, Platform: Linux-6.10.14-linuxkit-aarch64-with-glibc2.36
[2025-04-24T01:57:13.899+0000] {connection.py:1171} INFO - This connection is in OCSP Fail Open Mode. TLS Certificates would be checked for validity and revocation status. Any other Certificate Revocation related exceptions or OCSP Responder failures would be disregarded in favor of connectivity.
[2025-04-24T01:57:15.144+0000] {mbta_kafka_consumer.py:52} INFO - âœ… Connected to Snowflake successfully.
[2025-04-24T01:57:15.151+0000] {mbta_kafka_consumer.py:269} INFO - ðŸš€ Starting MBTA Kafka Consumer...
[2025-04-24T01:57:15.162+0000] {conn.py:1532} WARNING - DNS lookup failed for kafka:9092, exception was [Errno -2] Name or service not known. Is your advertised.listeners (called advertised.host.name before Kafka 9) correct and resolvable?
[2025-04-24T01:57:15.163+0000] {conn.py:322} ERROR - <BrokerConnection client_id=kafka-python-2.1.5, node_id=bootstrap-0 host=kafka:9092 <connecting> [unspecified None]>: DNS lookup failed for kafka:9092 (0)
[2025-04-24T01:57:15.163+0000] {conn.py:936} ERROR - <BrokerConnection client_id=kafka-python-2.1.5, node_id=bootstrap-0 host=kafka:9092 <connecting> [unspecified None]>: Closing connection. KafkaConnectionError: DNS failure
[2025-04-24T01:57:15.166+0000] {client_async.py:1048} WARNING - No node available during check_version; sleeping 0.04 secs
[2025-04-24T01:57:15.216+0000] {conn.py:1532} WARNING - DNS lookup failed for kafka:9092, exception was [Errno -2] Name or service not known. Is your advertised.listeners (called advertised.host.name before Kafka 9) correct and resolvable?
[2025-04-24T01:57:15.217+0000] {conn.py:322} ERROR - <BrokerConnection client_id=kafka-python-2.1.5, node_id=bootstrap-0 host=kafka:9092 <connecting> [unspecified None]>: DNS lookup failed for kafka:9092 (0)
[2025-04-24T01:57:15.218+0000] {conn.py:936} ERROR - <BrokerConnection client_id=kafka-python-2.1.5, node_id=bootstrap-0 host=kafka:9092 <connecting> [unspecified None]>: Closing connection. KafkaConnectionError: DNS failure
[2025-04-24T01:57:15.218+0000] {client_async.py:1048} WARNING - No node available during check_version; sleeping 0.11 secs
[2025-04-24T01:57:15.330+0000] {conn.py:1532} WARNING - DNS lookup failed for kafka:9092, exception was [Errno -2] Name or service not known. Is your advertised.listeners (called advertised.host.name before Kafka 9) correct and resolvable?
[2025-04-24T01:57:15.331+0000] {conn.py:322} ERROR - <BrokerConnection client_id=kafka-python-2.1.5, node_id=bootstrap-0 host=kafka:9092 <connecting> [unspecified None]>: DNS lookup failed for kafka:9092 (0)
[2025-04-24T01:57:15.331+0000] {conn.py:936} ERROR - <BrokerConnection client_id=kafka-python-2.1.5, node_id=bootstrap-0 host=kafka:9092 <connecting> [unspecified None]>: Closing connection. KafkaConnectionError: DNS failure
[2025-04-24T01:57:15.331+0000] {client_async.py:1048} WARNING - No node available during check_version; sleeping 0.23 secs
[2025-04-24T01:57:15.569+0000] {conn.py:1532} WARNING - DNS lookup failed for kafka:9092, exception was [Errno -2] Name or service not known. Is your advertised.listeners (called advertised.host.name before Kafka 9) correct and resolvable?
[2025-04-24T01:57:15.570+0000] {conn.py:322} ERROR - <BrokerConnection client_id=kafka-python-2.1.5, node_id=bootstrap-0 host=kafka:9092 <connecting> [unspecified None]>: DNS lookup failed for kafka:9092 (0)
[2025-04-24T01:57:15.570+0000] {conn.py:936} ERROR - <BrokerConnection client_id=kafka-python-2.1.5, node_id=bootstrap-0 host=kafka:9092 <connecting> [unspecified None]>: Closing connection. KafkaConnectionError: DNS failure
[2025-04-24T01:57:15.570+0000] {client_async.py:1048} WARNING - No node available during check_version; sleeping 0.34 secs
[2025-04-24T01:57:15.914+0000] {conn.py:1532} WARNING - DNS lookup failed for kafka:9092, exception was [Errno -2] Name or service not known. Is your advertised.listeners (called advertised.host.name before Kafka 9) correct and resolvable?
[2025-04-24T01:57:15.915+0000] {conn.py:322} ERROR - <BrokerConnection client_id=kafka-python-2.1.5, node_id=bootstrap-0 host=kafka:9092 <connecting> [unspecified None]>: DNS lookup failed for kafka:9092 (0)
[2025-04-24T01:57:15.915+0000] {conn.py:936} ERROR - <BrokerConnection client_id=kafka-python-2.1.5, node_id=bootstrap-0 host=kafka:9092 <connecting> [unspecified None]>: Closing connection. KafkaConnectionError: DNS failure
[2025-04-24T01:57:15.915+0000] {client_async.py:1048} WARNING - No node available during check_version; sleeping 0.91 secs
[2025-04-24T01:57:16.860+0000] {conn.py:1532} WARNING - DNS lookup failed for kafka:9092, exception was [Errno -2] Name or service not known. Is your advertised.listeners (called advertised.host.name before Kafka 9) correct and resolvable?
[2025-04-24T01:57:16.868+0000] {conn.py:322} ERROR - <BrokerConnection client_id=kafka-python-2.1.5, node_id=bootstrap-0 host=kafka:9092 <connecting> [unspecified None]>: DNS lookup failed for kafka:9092 (0)
[2025-04-24T01:57:16.870+0000] {conn.py:936} ERROR - <BrokerConnection client_id=kafka-python-2.1.5, node_id=bootstrap-0 host=kafka:9092 <connecting> [unspecified None]>: Closing connection. KafkaConnectionError: DNS failure
[2025-04-24T01:57:16.885+0000] {client_async.py:1048} WARNING - No node available during check_version; sleeping 0.27 secs
[2025-04-24T01:57:17.166+0000] {taskinstance.py:2698} ERROR - Task failed with exception
Traceback (most recent call last):
  File "/home/airflow/.local/lib/python3.9/site-packages/airflow/models/taskinstance.py", line 433, in _execute_task
    result = execute_callable(context=context, **execute_callable_kwargs)
  File "/home/airflow/.local/lib/python3.9/site-packages/airflow/operators/python.py", line 199, in execute
    return_value = self.execute_callable()
  File "/home/airflow/.local/lib/python3.9/site-packages/airflow/operators/python.py", line 216, in execute_callable
    return self.python_callable(*self.op_args, **self.op_kwargs)
  File "/opt/airflow/dags/mbta_ingestion_dag.py", line 36, in load_to_snowflake
    consume_messages()  # pulls and merges into Snowflake
  File "/opt/airflow/dags/mbta_kafka_consumer.py", line 270, in consume_messages
    consumer = KafkaConsumer(
  File "/home/airflow/.local/lib/python3.9/site-packages/kafka/consumer/group.py", line 383, in __init__
    self._client = self.config['kafka_client'](metrics=self._metrics, **self.config)
  File "/home/airflow/.local/lib/python3.9/site-packages/kafka/client_async.py", line 262, in __init__
    self.config['api_version'] = self.check_version()
  File "/home/airflow/.local/lib/python3.9/site-packages/kafka/client_async.py", line 1073, in check_version
    raise Errors.NoBrokersAvailable()
kafka.errors.NoBrokersAvailable: NoBrokersAvailable
[2025-04-24T01:57:17.245+0000] {taskinstance.py:1138} INFO - Marking task as FAILED. dag_id=mbta_ingestion_dag, task_id=load_to_snowflake, execution_date=20250424T014500, start_date=20250424T015713, end_date=20250424T015717
[2025-04-24T01:57:17.308+0000] {standard_task_runner.py:107} ERROR - Failed to execute job 814 for task load_to_snowflake (NoBrokersAvailable; 195)
[2025-04-24T01:57:17.389+0000] {local_task_job_runner.py:234} INFO - Task exited with return code 1
[2025-04-24T01:57:17.464+0000] {taskinstance.py:3280} INFO - 0 downstream tasks scheduled from follow-on schedule check
