[2025-04-23T21:00:14.740+0000] {taskinstance.py:1956} INFO - Dependencies all met for dep_context=non-requeueable deps ti=<TaskInstance: mbta_ingestion_dag.load_to_snowflake scheduled__2025-04-23T20:55:00+00:00 [queued]>
[2025-04-23T21:00:14.778+0000] {taskinstance.py:1956} INFO - Dependencies all met for dep_context=requeueable deps ti=<TaskInstance: mbta_ingestion_dag.load_to_snowflake scheduled__2025-04-23T20:55:00+00:00 [queued]>
[2025-04-23T21:00:14.779+0000] {taskinstance.py:2170} INFO - Starting attempt 1 of 2
[2025-04-23T21:00:14.822+0000] {taskinstance.py:2191} INFO - Executing <Task(PythonOperator): load_to_snowflake> on 2025-04-23 20:55:00+00:00
[2025-04-23T21:00:14.839+0000] {standard_task_runner.py:60} INFO - Started process 359 to run task
[2025-04-23T21:00:14.841+0000] {standard_task_runner.py:87} INFO - Running: ['***', 'tasks', 'run', 'mbta_ingestion_dag', 'load_to_snowflake', 'scheduled__2025-04-23T20:55:00+00:00', '--job-id', '614', '--raw', '--subdir', 'DAGS_FOLDER/mbta_ingestion_dag.py', '--cfg-path', '/tmp/tmpq5plcuq3']
[2025-04-23T21:00:14.843+0000] {standard_task_runner.py:88} INFO - Job 614: Subtask load_to_snowflake
[2025-04-23T21:00:14.935+0000] {task_command.py:423} INFO - Running <TaskInstance: mbta_ingestion_dag.load_to_snowflake scheduled__2025-04-23T20:55:00+00:00 [running]> on host d0e890afb95b
[2025-04-23T21:00:15.112+0000] {taskinstance.py:2480} INFO - Exporting env vars: AIRFLOW_CTX_DAG_OWNER='***' AIRFLOW_CTX_DAG_ID='mbta_ingestion_dag' AIRFLOW_CTX_TASK_ID='load_to_snowflake' AIRFLOW_CTX_EXECUTION_DATE='2025-04-23T20:55:00+00:00' AIRFLOW_CTX_TRY_NUMBER='1' AIRFLOW_CTX_DAG_RUN_ID='scheduled__2025-04-23T20:55:00+00:00'
[2025-04-23T21:00:15.115+0000] {mbta_ingestion_dag.py:35} INFO - ðŸš€ Launching Kafka consumer to process and load data into Snowflake...
[2025-04-23T21:00:15.118+0000] {connection.py:370} INFO - Snowflake Connector for Python Version: 3.6.0, Python Version: 3.9.18, Platform: Linux-6.10.14-linuxkit-aarch64-with-glibc2.36
[2025-04-23T21:00:15.127+0000] {connection.py:1171} INFO - This connection is in OCSP Fail Open Mode. TLS Certificates would be checked for validity and revocation status. Any other Certificate Revocation related exceptions or OCSP Responder failures would be disregarded in favor of connectivity.
[2025-04-23T21:00:15.870+0000] {mbta_kafka_consumer.py:45} INFO - âœ… Connected to Snowflake successfully.
[2025-04-23T21:00:15.872+0000] {mbta_kafka_consumer.py:220} INFO - ðŸš€ Starting MBTA Kafka Consumer...
[2025-04-23T21:00:15.880+0000] {conn.py:1532} WARNING - DNS lookup failed for kafka:9092, exception was [Errno -2] Name or service not known. Is your advertised.listeners (called advertised.host.name before Kafka 9) correct and resolvable?
[2025-04-23T21:00:15.881+0000] {conn.py:322} ERROR - <BrokerConnection client_id=kafka-python-2.1.5, node_id=bootstrap-0 host=kafka:9092 <connecting> [unspecified None]>: DNS lookup failed for kafka:9092 (0)
[2025-04-23T21:00:15.884+0000] {conn.py:936} ERROR - <BrokerConnection client_id=kafka-python-2.1.5, node_id=bootstrap-0 host=kafka:9092 <connecting> [unspecified None]>: Closing connection. KafkaConnectionError: DNS failure
[2025-04-23T21:00:15.885+0000] {client_async.py:1048} WARNING - No node available during check_version; sleeping 0.05 secs
[2025-04-23T21:00:15.939+0000] {conn.py:1532} WARNING - DNS lookup failed for kafka:9092, exception was [Errno -2] Name or service not known. Is your advertised.listeners (called advertised.host.name before Kafka 9) correct and resolvable?
[2025-04-23T21:00:15.943+0000] {conn.py:322} ERROR - <BrokerConnection client_id=kafka-python-2.1.5, node_id=bootstrap-0 host=kafka:9092 <connecting> [unspecified None]>: DNS lookup failed for kafka:9092 (0)
[2025-04-23T21:00:15.943+0000] {conn.py:936} ERROR - <BrokerConnection client_id=kafka-python-2.1.5, node_id=bootstrap-0 host=kafka:9092 <connecting> [unspecified None]>: Closing connection. KafkaConnectionError: DNS failure
[2025-04-23T21:00:15.945+0000] {client_async.py:1048} WARNING - No node available during check_version; sleeping 0.11 secs
[2025-04-23T21:00:16.059+0000] {conn.py:1532} WARNING - DNS lookup failed for kafka:9092, exception was [Errno -2] Name or service not known. Is your advertised.listeners (called advertised.host.name before Kafka 9) correct and resolvable?
[2025-04-23T21:00:16.061+0000] {conn.py:322} ERROR - <BrokerConnection client_id=kafka-python-2.1.5, node_id=bootstrap-0 host=kafka:9092 <connecting> [unspecified None]>: DNS lookup failed for kafka:9092 (0)
[2025-04-23T21:00:16.062+0000] {conn.py:936} ERROR - <BrokerConnection client_id=kafka-python-2.1.5, node_id=bootstrap-0 host=kafka:9092 <connecting> [unspecified None]>: Closing connection. KafkaConnectionError: DNS failure
[2025-04-23T21:00:16.063+0000] {client_async.py:1048} WARNING - No node available during check_version; sleeping 0.19 secs
[2025-04-23T21:00:16.259+0000] {conn.py:1532} WARNING - DNS lookup failed for kafka:9092, exception was [Errno -2] Name or service not known. Is your advertised.listeners (called advertised.host.name before Kafka 9) correct and resolvable?
[2025-04-23T21:00:16.260+0000] {conn.py:322} ERROR - <BrokerConnection client_id=kafka-python-2.1.5, node_id=bootstrap-0 host=kafka:9092 <connecting> [unspecified None]>: DNS lookup failed for kafka:9092 (0)
[2025-04-23T21:00:16.261+0000] {conn.py:936} ERROR - <BrokerConnection client_id=kafka-python-2.1.5, node_id=bootstrap-0 host=kafka:9092 <connecting> [unspecified None]>: Closing connection. KafkaConnectionError: DNS failure
[2025-04-23T21:00:16.263+0000] {client_async.py:1048} WARNING - No node available during check_version; sleeping 0.47 secs
[2025-04-23T21:00:16.735+0000] {conn.py:1532} WARNING - DNS lookup failed for kafka:9092, exception was [Errno -2] Name or service not known. Is your advertised.listeners (called advertised.host.name before Kafka 9) correct and resolvable?
[2025-04-23T21:00:16.737+0000] {conn.py:322} ERROR - <BrokerConnection client_id=kafka-python-2.1.5, node_id=bootstrap-0 host=kafka:9092 <connecting> [unspecified None]>: DNS lookup failed for kafka:9092 (0)
[2025-04-23T21:00:16.737+0000] {conn.py:936} ERROR - <BrokerConnection client_id=kafka-python-2.1.5, node_id=bootstrap-0 host=kafka:9092 <connecting> [unspecified None]>: Closing connection. KafkaConnectionError: DNS failure
[2025-04-23T21:00:16.739+0000] {client_async.py:1048} WARNING - No node available during check_version; sleeping 0.73 secs
[2025-04-23T21:00:17.475+0000] {conn.py:1532} WARNING - DNS lookup failed for kafka:9092, exception was [Errno -2] Name or service not known. Is your advertised.listeners (called advertised.host.name before Kafka 9) correct and resolvable?
[2025-04-23T21:00:17.476+0000] {conn.py:322} ERROR - <BrokerConnection client_id=kafka-python-2.1.5, node_id=bootstrap-0 host=kafka:9092 <connecting> [unspecified None]>: DNS lookup failed for kafka:9092 (0)
[2025-04-23T21:00:17.477+0000] {conn.py:936} ERROR - <BrokerConnection client_id=kafka-python-2.1.5, node_id=bootstrap-0 host=kafka:9092 <connecting> [unspecified None]>: Closing connection. KafkaConnectionError: DNS failure
[2025-04-23T21:00:17.477+0000] {client_async.py:1048} WARNING - No node available during check_version; sleeping 0.40 secs
[2025-04-23T21:00:17.880+0000] {taskinstance.py:2698} ERROR - Task failed with exception
Traceback (most recent call last):
  File "/home/airflow/.local/lib/python3.9/site-packages/airflow/models/taskinstance.py", line 433, in _execute_task
    result = execute_callable(context=context, **execute_callable_kwargs)
  File "/home/airflow/.local/lib/python3.9/site-packages/airflow/operators/python.py", line 199, in execute
    return_value = self.execute_callable()
  File "/home/airflow/.local/lib/python3.9/site-packages/airflow/operators/python.py", line 216, in execute_callable
    return self.python_callable(*self.op_args, **self.op_kwargs)
  File "/opt/airflow/dags/mbta_ingestion_dag.py", line 36, in load_to_snowflake
    consume_messages()  # pulls and merges into Snowflake
  File "/opt/airflow/dags/mbta_kafka_consumer.py", line 221, in consume_messages
    consumer = KafkaConsumer(
  File "/home/airflow/.local/lib/python3.9/site-packages/kafka/consumer/group.py", line 383, in __init__
    self._client = self.config['kafka_client'](metrics=self._metrics, **self.config)
  File "/home/airflow/.local/lib/python3.9/site-packages/kafka/client_async.py", line 262, in __init__
    self.config['api_version'] = self.check_version()
  File "/home/airflow/.local/lib/python3.9/site-packages/kafka/client_async.py", line 1073, in check_version
    raise Errors.NoBrokersAvailable()
kafka.errors.NoBrokersAvailable: NoBrokersAvailable
[2025-04-23T21:00:17.960+0000] {taskinstance.py:1138} INFO - Marking task as UP_FOR_RETRY. dag_id=mbta_ingestion_dag, task_id=load_to_snowflake, execution_date=20250423T205500, start_date=20250423T210014, end_date=20250423T210017
[2025-04-23T21:00:18.029+0000] {standard_task_runner.py:107} ERROR - Failed to execute job 614 for task load_to_snowflake (NoBrokersAvailable; 359)
[2025-04-23T21:00:18.094+0000] {local_task_job_runner.py:234} INFO - Task exited with return code 1
[2025-04-23T21:00:18.178+0000] {taskinstance.py:3280} INFO - 0 downstream tasks scheduled from follow-on schedule check
