[2025-04-18T19:57:24.566+0000] {taskinstance.py:1956} INFO - Dependencies all met for dep_context=non-requeueable deps ti=<TaskInstance: mbta_ingestion_dag.load_to_snowflake scheduled__2025-04-18T19:50:00+00:00 [queued]>
[2025-04-18T19:57:24.580+0000] {taskinstance.py:1956} INFO - Dependencies all met for dep_context=requeueable deps ti=<TaskInstance: mbta_ingestion_dag.load_to_snowflake scheduled__2025-04-18T19:50:00+00:00 [queued]>
[2025-04-18T19:57:24.581+0000] {taskinstance.py:2170} INFO - Starting attempt 2 of 2
[2025-04-18T19:57:24.592+0000] {taskinstance.py:2191} INFO - Executing <Task(PythonOperator): load_to_snowflake> on 2025-04-18 19:50:00+00:00
[2025-04-18T19:57:24.598+0000] {standard_task_runner.py:60} INFO - Started process 3424 to run task
[2025-04-18T19:57:24.602+0000] {standard_task_runner.py:87} INFO - Running: ['***', 'tasks', 'run', 'mbta_ingestion_dag', 'load_to_snowflake', 'scheduled__2025-04-18T19:50:00+00:00', '--job-id', '109', '--raw', '--subdir', 'DAGS_FOLDER/mbta_ingestion_dag.py', '--cfg-path', '/tmp/tmpdsp3729v']
[2025-04-18T19:57:24.607+0000] {standard_task_runner.py:88} INFO - Job 109: Subtask load_to_snowflake
[2025-04-18T19:57:24.802+0000] {task_command.py:423} INFO - Running <TaskInstance: mbta_ingestion_dag.load_to_snowflake scheduled__2025-04-18T19:50:00+00:00 [running]> on host 4144a051706e
[2025-04-18T19:57:25.025+0000] {taskinstance.py:2480} INFO - Exporting env vars: AIRFLOW_CTX_DAG_OWNER='***' AIRFLOW_CTX_DAG_ID='mbta_ingestion_dag' AIRFLOW_CTX_TASK_ID='load_to_snowflake' AIRFLOW_CTX_EXECUTION_DATE='2025-04-18T19:50:00+00:00' AIRFLOW_CTX_TRY_NUMBER='2' AIRFLOW_CTX_DAG_RUN_ID='scheduled__2025-04-18T19:50:00+00:00'
[2025-04-18T19:57:25.028+0000] {mbta_ingestion_dag.py:35} INFO - üöÄ Launching Kafka consumer to process and load data into Snowflake...
[2025-04-18T19:57:25.029+0000] {connection.py:370} INFO - Snowflake Connector for Python Version: 3.6.0, Python Version: 3.9.18, Platform: Linux-6.10.14-linuxkit-aarch64-with-glibc2.36
[2025-04-18T19:57:25.030+0000] {connection.py:1171} INFO - This connection is in OCSP Fail Open Mode. TLS Certificates would be checked for validity and revocation status. Any other Certificate Revocation related exceptions or OCSP Responder failures would be disregarded in favor of connectivity.
[2025-04-18T19:57:25.048+0000] {connectionpool.py:824} WARNING - Retrying (Retry(total=0, connect=None, read=None, redirect=None, status=None)) after connection broken by 'NewConnectionError('<snowflake.connector.vendored.urllib3.connection.HTTPSConnection object at 0xffff68c45a30>: Failed to establish a new connection: [Errno -3] Temporary failure in name resolution')': /session/v1/login-request?request_id=a5dfc61a-c6f1-4ce4-bb45-af1defa4cf75&databaseName=MBTA_DB2&schemaName=MBTA_SCHEMA2&warehouse=MBTA_WH2&request_guid=55395b2c-089a-4133-a6d2-d27082e6cf1e
[2025-04-18T19:57:34.112+0000] {connectionpool.py:824} WARNING - Retrying (Retry(total=0, connect=None, read=None, redirect=None, status=None)) after connection broken by 'NewConnectionError('<snowflake.connector.vendored.urllib3.connection.HTTPSConnection object at 0xffff68afd190>: Failed to establish a new connection: [Errno -3] Temporary failure in name resolution')': /session/v1/login-request?request_id=6dbca363-f1c9-404a-bd90-1177e6bedfb7&databaseName=MBTA_DB2&schemaName=MBTA_SCHEMA2&warehouse=MBTA_WH2&request_guid=3ada4e1c-685b-4b1a-8374-458f57857f67
[2025-04-18T19:57:38.143+0000] {mbta_kafka_consumer.py:48} ERROR - ‚ùå Error connecting to Snowflake: 250001: 250001: Could not connect to Snowflake backend after 2 attempt(s).Aborting
[2025-04-18T19:57:38.191+0000] {local_task_job_runner.py:234} INFO - Task exited with return code 1
[2025-04-18T19:57:38.216+0000] {taskinstance.py:3280} INFO - 0 downstream tasks scheduled from follow-on schedule check
