[2025-04-18T21:35:01.051+0000] {taskinstance.py:1956} INFO - Dependencies all met for dep_context=non-requeueable deps ti=<TaskInstance: mbta_kafka_consumer_dag.run_kafka_consumer scheduled__2025-04-18T21:30:00+00:00 [queued]>
[2025-04-18T21:35:01.058+0000] {taskinstance.py:1956} INFO - Dependencies all met for dep_context=requeueable deps ti=<TaskInstance: mbta_kafka_consumer_dag.run_kafka_consumer scheduled__2025-04-18T21:30:00+00:00 [queued]>
[2025-04-18T21:35:01.058+0000] {taskinstance.py:2170} INFO - Starting attempt 1 of 2
[2025-04-18T21:35:01.065+0000] {taskinstance.py:2191} INFO - Executing <Task(PythonOperator): run_kafka_consumer> on 2025-04-18 21:30:00+00:00
[2025-04-18T21:35:01.068+0000] {standard_task_runner.py:60} INFO - Started process 6858 to run task
[2025-04-18T21:35:01.070+0000] {standard_task_runner.py:87} INFO - Running: ['***', 'tasks', 'run', 'mbta_kafka_consumer_dag', 'run_kafka_consumer', 'scheduled__2025-04-18T21:30:00+00:00', '--job-id', '225', '--raw', '--subdir', 'DAGS_FOLDER/mbta_kafka_consumer_dag.py', '--cfg-path', '/tmp/tmpjspn36ul']
[2025-04-18T21:35:01.073+0000] {standard_task_runner.py:88} INFO - Job 225: Subtask run_kafka_consumer
[2025-04-18T21:35:01.102+0000] {task_command.py:423} INFO - Running <TaskInstance: mbta_kafka_consumer_dag.run_kafka_consumer scheduled__2025-04-18T21:30:00+00:00 [running]> on host 4144a051706e
[2025-04-18T21:35:01.145+0000] {taskinstance.py:2480} INFO - Exporting env vars: AIRFLOW_CTX_DAG_OWNER='***' AIRFLOW_CTX_DAG_ID='mbta_kafka_consumer_dag' AIRFLOW_CTX_TASK_ID='run_kafka_consumer' AIRFLOW_CTX_EXECUTION_DATE='2025-04-18T21:30:00+00:00' AIRFLOW_CTX_TRY_NUMBER='1' AIRFLOW_CTX_DAG_RUN_ID='scheduled__2025-04-18T21:30:00+00:00'
[2025-04-18T21:35:01.146+0000] {connection.py:370} INFO - Snowflake Connector for Python Version: 3.6.0, Python Version: 3.9.18, Platform: Linux-6.10.14-linuxkit-aarch64-with-glibc2.36
[2025-04-18T21:35:01.147+0000] {connection.py:1171} INFO - This connection is in OCSP Fail Open Mode. TLS Certificates would be checked for validity and revocation status. Any other Certificate Revocation related exceptions or OCSP Responder failures would be disregarded in favor of connectivity.
[2025-04-18T21:35:01.151+0000] {connectionpool.py:824} WARNING - Retrying (Retry(total=0, connect=None, read=None, redirect=None, status=None)) after connection broken by 'NewConnectionError('<snowflake.connector.vendored.urllib3.connection.HTTPSConnection object at 0xffff68c8d400>: Failed to establish a new connection: [Errno -3] Temporary failure in name resolution')': /session/v1/login-request?request_id=21406828-9815-47a0-9ed5-8cc08ee8328b&databaseName=MBTA_DB2&schemaName=MBTA_SCHEMA2&warehouse=MBTA_WH2&request_guid=f94a6aad-098e-4c27-8dc9-dc42ff60481f
[2025-04-18T21:35:10.209+0000] {connectionpool.py:824} WARNING - Retrying (Retry(total=0, connect=None, read=None, redirect=None, status=None)) after connection broken by 'NewConnectionError('<snowflake.connector.vendored.urllib3.connection.HTTPSConnection object at 0xffff68c8dca0>: Failed to establish a new connection: [Errno -3] Temporary failure in name resolution')': /session/v1/login-request?request_id=4c86c5ff-b860-4eb7-ad04-6c405e259c72&databaseName=MBTA_DB2&schemaName=MBTA_SCHEMA2&warehouse=MBTA_WH2&request_guid=a6cdb528-8eb3-4e33-bc75-884d5011aafc
[2025-04-18T21:35:14.256+0000] {mbta_kafka_consumer.py:48} ERROR - ‚ùå Error connecting to Snowflake: 250001: 250001: Could not connect to Snowflake backend after 2 attempt(s).Aborting
[2025-04-18T21:35:14.311+0000] {local_task_job_runner.py:234} INFO - Task exited with return code 1
[2025-04-18T21:35:14.338+0000] {taskinstance.py:3280} INFO - 0 downstream tasks scheduled from follow-on schedule check
