[2025-04-25T04:55:01.330+0000] {taskinstance.py:1956} INFO - Dependencies all met for dep_context=non-requeueable deps ti=<TaskInstance: mbta_kafka_consumer_dag.run_kafka_consumer scheduled__2025-04-25T04:50:00+00:00 [queued]>
[2025-04-25T04:55:01.336+0000] {taskinstance.py:1956} INFO - Dependencies all met for dep_context=requeueable deps ti=<TaskInstance: mbta_kafka_consumer_dag.run_kafka_consumer scheduled__2025-04-25T04:50:00+00:00 [queued]>
[2025-04-25T04:55:01.336+0000] {taskinstance.py:2170} INFO - Starting attempt 1 of 2
[2025-04-25T04:55:01.345+0000] {taskinstance.py:2191} INFO - Executing <Task(PythonOperator): run_kafka_consumer> on 2025-04-25 04:50:00+00:00
[2025-04-25T04:55:01.349+0000] {standard_task_runner.py:60} INFO - Started process 2634 to run task
[2025-04-25T04:55:01.352+0000] {standard_task_runner.py:87} INFO - Running: ['***', 'tasks', 'run', 'mbta_kafka_consumer_dag', 'run_kafka_consumer', 'scheduled__2025-04-25T04:50:00+00:00', '--job-id', '1353', '--raw', '--subdir', 'DAGS_FOLDER/mbta_kafka_consumer_dag.py', '--cfg-path', '/tmp/tmpkwguw38m']
[2025-04-25T04:55:01.357+0000] {standard_task_runner.py:88} INFO - Job 1353: Subtask run_kafka_consumer
[2025-04-25T04:55:01.394+0000] {task_command.py:423} INFO - Running <TaskInstance: mbta_kafka_consumer_dag.run_kafka_consumer scheduled__2025-04-25T04:50:00+00:00 [running]> on host f72d543edf4d
[2025-04-25T04:55:01.455+0000] {taskinstance.py:2480} INFO - Exporting env vars: AIRFLOW_CTX_DAG_OWNER='***' AIRFLOW_CTX_DAG_ID='mbta_kafka_consumer_dag' AIRFLOW_CTX_TASK_ID='run_kafka_consumer' AIRFLOW_CTX_EXECUTION_DATE='2025-04-25T04:50:00+00:00' AIRFLOW_CTX_TRY_NUMBER='1' AIRFLOW_CTX_DAG_RUN_ID='scheduled__2025-04-25T04:50:00+00:00'
[2025-04-25T04:55:01.456+0000] {connection.py:370} INFO - Snowflake Connector for Python Version: 3.6.0, Python Version: 3.9.18, Platform: Linux-6.10.14-linuxkit-aarch64-with-glibc2.36
[2025-04-25T04:55:01.457+0000] {connection.py:1171} INFO - This connection is in OCSP Fail Open Mode. TLS Certificates would be checked for validity and revocation status. Any other Certificate Revocation related exceptions or OCSP Responder failures would be disregarded in favor of connectivity.
[2025-04-25T04:55:09.470+0000] {connectionpool.py:824} WARNING - Retrying (Retry(total=0, connect=None, read=None, redirect=None, status=None)) after connection broken by 'NewConnectionError('<snowflake.connector.vendored.urllib3.connection.HTTPSConnection object at 0xffff86103040>: Failed to establish a new connection: [Errno -3] Temporary failure in name resolution')': /session/v1/login-request?request_id=5d434006-b2b7-4b8f-b04f-c01a55ed1133&databaseName=MBTA_DB2&schemaName=MBTA_SCHEMA2&warehouse=MBTA_WH2&request_guid=846ec616-1868-4768-9f9c-739a6033140c
[2025-04-25T04:55:22.515+0000] {connectionpool.py:824} WARNING - Retrying (Retry(total=0, connect=None, read=None, redirect=None, status=None)) after connection broken by 'NewConnectionError('<snowflake.connector.vendored.urllib3.connection.HTTPSConnection object at 0xffff86103940>: Failed to establish a new connection: [Errno -3] Temporary failure in name resolution')': /session/v1/login-request?request_id=0cd3b6bd-1ed1-4307-8766-20bc7580274b&databaseName=MBTA_DB2&schemaName=MBTA_SCHEMA2&warehouse=MBTA_WH2&request_guid=80eb391c-ad5f-4382-8c61-7d7e5635f7db
[2025-04-25T04:55:26.534+0000] {mbta_kafka_consumer.py:55} ERROR - ‚ùå Error connecting to Snowflake: 250001: 250001: Could not connect to Snowflake backend after 2 attempt(s).Aborting
[2025-04-25T04:55:26.567+0000] {local_task_job_runner.py:234} INFO - Task exited with return code 1
[2025-04-25T04:55:26.602+0000] {taskinstance.py:3280} INFO - 0 downstream tasks scheduled from follow-on schedule check
