[2025-04-18T01:00:07.330+0000] {taskinstance.py:1956} INFO - Dependencies all met for dep_context=non-requeueable deps ti=<TaskInstance: mbta_ingestion_dag.load_to_snowflake scheduled__2025-04-18T00:00:00+00:00 [queued]>
[2025-04-18T01:00:07.335+0000] {taskinstance.py:1956} INFO - Dependencies all met for dep_context=requeueable deps ti=<TaskInstance: mbta_ingestion_dag.load_to_snowflake scheduled__2025-04-18T00:00:00+00:00 [queued]>
[2025-04-18T01:00:07.336+0000] {taskinstance.py:2170} INFO - Starting attempt 1 of 2
[2025-04-18T01:00:07.346+0000] {taskinstance.py:2191} INFO - Executing <Task(PythonOperator): load_to_snowflake> on 2025-04-18 00:00:00+00:00
[2025-04-18T01:00:07.351+0000] {standard_task_runner.py:60} INFO - Started process 4861 to run task
[2025-04-18T01:00:07.355+0000] {standard_task_runner.py:87} INFO - Running: ['***', 'tasks', 'run', 'mbta_ingestion_dag', 'load_to_snowflake', 'scheduled__2025-04-18T00:00:00+00:00', '--job-id', '24', '--raw', '--subdir', 'DAGS_FOLDER/mbta_ingestion_dag.py', '--cfg-path', '/tmp/tmpoga8z0hu']
[2025-04-18T01:00:07.358+0000] {standard_task_runner.py:88} INFO - Job 24: Subtask load_to_snowflake
[2025-04-18T01:00:07.401+0000] {task_command.py:423} INFO - Running <TaskInstance: mbta_ingestion_dag.load_to_snowflake scheduled__2025-04-18T00:00:00+00:00 [running]> on host 4c52e6b69c7a
[2025-04-18T01:00:07.470+0000] {taskinstance.py:2480} INFO - Exporting env vars: AIRFLOW_CTX_DAG_OWNER='***' AIRFLOW_CTX_DAG_ID='mbta_ingestion_dag' AIRFLOW_CTX_TASK_ID='load_to_snowflake' AIRFLOW_CTX_EXECUTION_DATE='2025-04-18T00:00:00+00:00' AIRFLOW_CTX_TRY_NUMBER='1' AIRFLOW_CTX_DAG_RUN_ID='scheduled__2025-04-18T00:00:00+00:00'
[2025-04-18T01:00:07.471+0000] {mbta_ingestion_dag.py:35} INFO - 🚀 Launching Kafka consumer to process and load data into Snowflake...
[2025-04-18T01:00:07.471+0000] {connection.py:370} INFO - Snowflake Connector for Python Version: 3.6.0, Python Version: 3.9.18, Platform: Linux-6.10.14-linuxkit-aarch64-with-glibc2.36
[2025-04-18T01:00:07.472+0000] {connection.py:1171} INFO - This connection is in OCSP Fail Open Mode. TLS Certificates would be checked for validity and revocation status. Any other Certificate Revocation related exceptions or OCSP Responder failures would be disregarded in favor of connectivity.
[2025-04-18T01:00:08.640+0000] {mbta_kafka_consumer.py:45} INFO - ✅ Connected to Snowflake successfully.
[2025-04-18T01:00:08.644+0000] {mbta_kafka_consumer.py:219} INFO - 🚀 Starting MBTA Kafka Consumer...
[2025-04-18T01:00:08.648+0000] {conn.py:395} INFO - <BrokerConnection client_id=kafka-python-2.1.5, node_id=bootstrap-0 host=kafka:9092 <connecting> [IPv4 ('172.18.0.4', 9092)]>: connecting to kafka:9092 [('172.18.0.4', 9092) IPv4]
[2025-04-18T01:00:08.657+0000] {conn.py:615} INFO - <BrokerConnection client_id=kafka-python-2.1.5, node_id=bootstrap-0 host=kafka:9092 <checking_api_versions_recv> [IPv4 ('172.18.0.4', 9092)]>: Broker version identified as 2.6
[2025-04-18T01:00:08.658+0000] {conn.py:456} INFO - <BrokerConnection client_id=kafka-python-2.1.5, node_id=bootstrap-0 host=kafka:9092 <connected> [IPv4 ('172.18.0.4', 9092)]>: Connection complete.
[2025-04-18T01:00:08.659+0000] {consumer.py:119} WARNING - group_id is None: disabling auto-commit.
[2025-04-18T01:00:08.659+0000] {subscription_state.py:182} INFO - Updating subscribed topics to: ('mbta_alerts', 'mbta_routes', 'mbta_stops', 'mbta_vehicles', 'mbta_predictions')
[2025-04-18T01:00:08.664+0000] {subscription_state.py:254} INFO - Updated partition assignment: [('mbta_routes', 0), ('mbta_alerts', 0), ('mbta_predictions', 0), ('mbta_vehicles', 0), ('mbta_stops', 0)]
[2025-04-18T01:00:08.665+0000] {conn.py:395} INFO - <BrokerConnection client_id=kafka-python-2.1.5, node_id=1 host=kafka:9092 <connecting> [IPv4 ('172.18.0.4', 9092)]>: connecting to kafka:9092 [('172.18.0.4', 9092) IPv4]
[2025-04-18T01:00:08.665+0000] {conn.py:456} INFO - <BrokerConnection client_id=kafka-python-2.1.5, node_id=1 host=kafka:9092 <connected> [IPv4 ('172.18.0.4', 9092)]>: Connection complete.
[2025-04-18T01:00:08.665+0000] {conn.py:936} INFO - <BrokerConnection client_id=kafka-python-2.1.5, node_id=bootstrap-0 host=kafka:9092 <connected> [IPv4 ('172.18.0.4', 9092)]>: Closing connection. 
[2025-04-18T01:00:35.488+0000] {conn.py:1153} ERROR - <BrokerConnection client_id=kafka-python-2.1.5, node_id=1 host=kafka:9092 <connected> [IPv4 ('172.18.0.4', 9092)]>: socket disconnected
[2025-04-18T01:00:35.541+0000] {conn.py:936} ERROR - <BrokerConnection client_id=kafka-python-2.1.5, node_id=1 host=kafka:9092 <connected> [IPv4 ('172.18.0.4', 9092)]>: Closing connection. KafkaConnectionError: socket disconnected
[2025-04-18T01:00:35.559+0000] {client_async.py:388} WARNING - Node 1 connection failed -- refreshing metadata
[2025-04-18T01:00:35.568+0000] {fetcher.py:735} ERROR - Fetch to node 1 failed: KafkaConnectionError: socket disconnected
[2025-04-18T01:00:35.572+0000] {fetcher.py:735} ERROR - Fetch to node 1 failed: NodeNotReadyError: 1
[2025-04-18T01:00:35.676+0000] {conn.py:395} INFO - <BrokerConnection client_id=kafka-python-2.1.5, node_id=1 host=kafka:9092 <connecting> [IPv4 ('172.18.0.4', 9092)]>: connecting to kafka:9092 [('172.18.0.4', 9092) IPv4]
[2025-04-18T01:00:35.682+0000] {conn.py:428} ERROR - <BrokerConnection client_id=kafka-python-2.1.5, node_id=1 host=kafka:9092 <connecting> [IPv4 ('172.18.0.4', 9092)]>: Connect attempt returned error 111. Disconnecting.
[2025-04-18T01:00:35.686+0000] {conn.py:936} ERROR - <BrokerConnection client_id=kafka-python-2.1.5, node_id=1 host=kafka:9092 <connecting> [IPv4 ('172.18.0.4', 9092)]>: Closing connection. KafkaConnectionError: 111 ECONNREFUSED
[2025-04-18T01:00:35.688+0000] {client_async.py:388} WARNING - Node 1 connection failed -- refreshing metadata
[2025-04-18T01:00:35.791+0000] {fetcher.py:735} ERROR - Fetch to node 1 failed: NodeNotReadyError: 1
[2025-04-18T01:00:35.793+0000] {conn.py:395} INFO - <BrokerConnection client_id=kafka-python-2.1.5, node_id=1 host=kafka:9092 <connecting> [IPv4 ('172.18.0.4', 9092)]>: connecting to kafka:9092 [('172.18.0.4', 9092) IPv4]
[2025-04-18T01:00:35.796+0000] {conn.py:428} ERROR - <BrokerConnection client_id=kafka-python-2.1.5, node_id=1 host=kafka:9092 <connecting> [IPv4 ('172.18.0.4', 9092)]>: Connect attempt returned error 111. Disconnecting.
[2025-04-18T01:00:35.800+0000] {conn.py:936} ERROR - <BrokerConnection client_id=kafka-python-2.1.5, node_id=1 host=kafka:9092 <connecting> [IPv4 ('172.18.0.4', 9092)]>: Closing connection. KafkaConnectionError: 111 ECONNREFUSED
[2025-04-18T01:00:35.801+0000] {client_async.py:388} WARNING - Node 1 connection failed -- refreshing metadata
[2025-04-18T01:00:36.014+0000] {fetcher.py:735} ERROR - Fetch to node 1 failed: NodeNotReadyError: 1
[2025-04-18T01:00:36.018+0000] {conn.py:395} INFO - <BrokerConnection client_id=kafka-python-2.1.5, node_id=1 host=kafka:9092 <connecting> [IPv4 ('172.18.0.4', 9092)]>: connecting to kafka:9092 [('172.18.0.4', 9092) IPv4]
[2025-04-18T01:00:36.020+0000] {conn.py:428} ERROR - <BrokerConnection client_id=kafka-python-2.1.5, node_id=1 host=kafka:9092 <connecting> [IPv4 ('172.18.0.4', 9092)]>: Connect attempt returned error 111. Disconnecting.
[2025-04-18T01:00:36.021+0000] {conn.py:936} ERROR - <BrokerConnection client_id=kafka-python-2.1.5, node_id=1 host=kafka:9092 <connecting> [IPv4 ('172.18.0.4', 9092)]>: Closing connection. KafkaConnectionError: 111 ECONNREFUSED
[2025-04-18T01:00:36.022+0000] {client_async.py:388} WARNING - Node 1 connection failed -- refreshing metadata
[2025-04-18T01:00:36.448+0000] {fetcher.py:735} ERROR - Fetch to node 1 failed: NodeNotReadyError: 1
[2025-04-18T01:00:36.454+0000] {conn.py:1532} WARNING - DNS lookup failed for kafka:9092, exception was [Errno -2] Name or service not known. Is your advertised.listeners (called advertised.host.name before Kafka 9) correct and resolvable?
[2025-04-18T01:00:36.455+0000] {conn.py:322} ERROR - <BrokerConnection client_id=kafka-python-2.1.5, node_id=1 host=kafka:9092 <connecting> [IPv4 ('172.18.0.4', 9092)]>: DNS lookup failed for kafka:9092 (0)
[2025-04-18T01:00:36.455+0000] {conn.py:936} ERROR - <BrokerConnection client_id=kafka-python-2.1.5, node_id=1 host=kafka:9092 <connecting> [IPv4 ('172.18.0.4', 9092)]>: Closing connection. KafkaConnectionError: DNS failure
[2025-04-18T01:00:36.456+0000] {client_async.py:388} WARNING - Node 1 connection failed -- refreshing metadata
[2025-04-18T01:00:37.362+0000] {fetcher.py:735} ERROR - Fetch to node 1 failed: NodeNotReadyError: 1
[2025-04-18T01:00:37.366+0000] {conn.py:1532} WARNING - DNS lookup failed for kafka:9092, exception was [Errno -2] Name or service not known. Is your advertised.listeners (called advertised.host.name before Kafka 9) correct and resolvable?
[2025-04-18T01:00:37.366+0000] {conn.py:322} ERROR - <BrokerConnection client_id=kafka-python-2.1.5, node_id=1 host=kafka:9092 <connecting> [IPv4 ('172.18.0.4', 9092)]>: DNS lookup failed for kafka:9092 (0)
[2025-04-18T01:00:37.367+0000] {conn.py:936} ERROR - <BrokerConnection client_id=kafka-python-2.1.5, node_id=1 host=kafka:9092 <connecting> [IPv4 ('172.18.0.4', 9092)]>: Closing connection. KafkaConnectionError: DNS failure
[2025-04-18T01:00:37.367+0000] {client_async.py:388} WARNING - Node 1 connection failed -- refreshing metadata
[2025-04-18T01:00:39.035+0000] {fetcher.py:735} ERROR - Fetch to node 1 failed: NodeNotReadyError: 1
[2025-04-18T01:00:39.042+0000] {conn.py:1532} WARNING - DNS lookup failed for kafka:9092, exception was [Errno -2] Name or service not known. Is your advertised.listeners (called advertised.host.name before Kafka 9) correct and resolvable?
[2025-04-18T01:00:39.043+0000] {conn.py:322} ERROR - <BrokerConnection client_id=kafka-python-2.1.5, node_id=1 host=kafka:9092 <connecting> [IPv4 ('172.18.0.4', 9092)]>: DNS lookup failed for kafka:9092 (0)
[2025-04-18T01:00:39.043+0000] {conn.py:936} ERROR - <BrokerConnection client_id=kafka-python-2.1.5, node_id=1 host=kafka:9092 <connecting> [IPv4 ('172.18.0.4', 9092)]>: Closing connection. KafkaConnectionError: DNS failure
[2025-04-18T01:00:39.043+0000] {client_async.py:388} WARNING - Node 1 connection failed -- refreshing metadata
[2025-04-18T01:00:42.378+0000] {fetcher.py:735} ERROR - Fetch to node 1 failed: NodeNotReadyError: 1
[2025-04-18T01:00:42.383+0000] {conn.py:1532} WARNING - DNS lookup failed for kafka:9092, exception was [Errno -2] Name or service not known. Is your advertised.listeners (called advertised.host.name before Kafka 9) correct and resolvable?
[2025-04-18T01:00:42.384+0000] {conn.py:322} ERROR - <BrokerConnection client_id=kafka-python-2.1.5, node_id=1 host=kafka:9092 <connecting> [IPv4 ('172.18.0.4', 9092)]>: DNS lookup failed for kafka:9092 (0)
[2025-04-18T01:00:42.384+0000] {conn.py:936} ERROR - <BrokerConnection client_id=kafka-python-2.1.5, node_id=1 host=kafka:9092 <connecting> [IPv4 ('172.18.0.4', 9092)]>: Closing connection. KafkaConnectionError: DNS failure
[2025-04-18T01:00:42.385+0000] {client_async.py:388} WARNING - Node 1 connection failed -- refreshing metadata
[2025-04-18T01:00:48.044+0000] {fetcher.py:735} ERROR - Fetch to node 1 failed: NodeNotReadyError: 1
[2025-04-18T01:00:48.054+0000] {conn.py:1532} WARNING - DNS lookup failed for kafka:9092, exception was [Errno -2] Name or service not known. Is your advertised.listeners (called advertised.host.name before Kafka 9) correct and resolvable?
[2025-04-18T01:00:48.055+0000] {conn.py:322} ERROR - <BrokerConnection client_id=kafka-python-2.1.5, node_id=1 host=kafka:9092 <connecting> [IPv4 ('172.18.0.4', 9092)]>: DNS lookup failed for kafka:9092 (0)
[2025-04-18T01:00:48.055+0000] {conn.py:936} ERROR - <BrokerConnection client_id=kafka-python-2.1.5, node_id=1 host=kafka:9092 <connecting> [IPv4 ('172.18.0.4', 9092)]>: Closing connection. KafkaConnectionError: DNS failure
[2025-04-18T01:00:48.056+0000] {client_async.py:388} WARNING - Node 1 connection failed -- refreshing metadata
[2025-04-18T01:01:00.591+0000] {fetcher.py:735} ERROR - Fetch to node 1 failed: NodeNotReadyError: 1
[2025-04-18T01:01:00.600+0000] {conn.py:1532} WARNING - DNS lookup failed for kafka:9092, exception was [Errno -2] Name or service not known. Is your advertised.listeners (called advertised.host.name before Kafka 9) correct and resolvable?
[2025-04-18T01:01:00.600+0000] {conn.py:322} ERROR - <BrokerConnection client_id=kafka-python-2.1.5, node_id=1 host=kafka:9092 <connecting> [IPv4 ('172.18.0.4', 9092)]>: DNS lookup failed for kafka:9092 (0)
[2025-04-18T01:01:00.601+0000] {conn.py:936} ERROR - <BrokerConnection client_id=kafka-python-2.1.5, node_id=1 host=kafka:9092 <connecting> [IPv4 ('172.18.0.4', 9092)]>: Closing connection. KafkaConnectionError: DNS failure
[2025-04-18T01:01:00.604+0000] {client_async.py:388} WARNING - Node 1 connection failed -- refreshing metadata
[2025-04-18T01:01:24.625+0000] {fetcher.py:735} ERROR - Fetch to node 1 failed: NodeNotReadyError: 1
[2025-04-18T01:01:24.650+0000] {conn.py:1532} WARNING - DNS lookup failed for kafka:9092, exception was [Errno -2] Name or service not known. Is your advertised.listeners (called advertised.host.name before Kafka 9) correct and resolvable?
[2025-04-18T01:01:24.652+0000] {conn.py:322} ERROR - <BrokerConnection client_id=kafka-python-2.1.5, node_id=1 host=kafka:9092 <connecting> [IPv4 ('172.18.0.4', 9092)]>: DNS lookup failed for kafka:9092 (0)
[2025-04-18T01:01:24.655+0000] {conn.py:936} ERROR - <BrokerConnection client_id=kafka-python-2.1.5, node_id=1 host=kafka:9092 <connecting> [IPv4 ('172.18.0.4', 9092)]>: Closing connection. KafkaConnectionError: DNS failure
[2025-04-18T01:01:24.656+0000] {client_async.py:388} WARNING - Node 1 connection failed -- refreshing metadata
[2025-04-18T01:01:51.098+0000] {fetcher.py:735} ERROR - Fetch to node 1 failed: NodeNotReadyError: 1
[2025-04-18T01:01:51.143+0000] {conn.py:1532} WARNING - DNS lookup failed for kafka:9092, exception was [Errno -2] Name or service not known. Is your advertised.listeners (called advertised.host.name before Kafka 9) correct and resolvable?
[2025-04-18T01:01:51.143+0000] {conn.py:322} ERROR - <BrokerConnection client_id=kafka-python-2.1.5, node_id=1 host=kafka:9092 <connecting> [IPv4 ('172.18.0.4', 9092)]>: DNS lookup failed for kafka:9092 (0)
[2025-04-18T01:01:51.144+0000] {conn.py:936} ERROR - <BrokerConnection client_id=kafka-python-2.1.5, node_id=1 host=kafka:9092 <connecting> [IPv4 ('172.18.0.4', 9092)]>: Closing connection. KafkaConnectionError: DNS failure
[2025-04-18T01:01:51.145+0000] {client_async.py:388} WARNING - Node 1 connection failed -- refreshing metadata
[2025-04-18T01:02:25.092+0000] {fetcher.py:735} ERROR - Fetch to node 1 failed: NodeNotReadyError: 1
[2025-04-18T01:02:25.127+0000] {conn.py:1532} WARNING - DNS lookup failed for kafka:9092, exception was [Errno -2] Name or service not known. Is your advertised.listeners (called advertised.host.name before Kafka 9) correct and resolvable?
[2025-04-18T01:02:25.128+0000] {conn.py:322} ERROR - <BrokerConnection client_id=kafka-python-2.1.5, node_id=1 host=kafka:9092 <connecting> [IPv4 ('172.18.0.4', 9092)]>: DNS lookup failed for kafka:9092 (0)
[2025-04-18T01:02:25.129+0000] {conn.py:936} ERROR - <BrokerConnection client_id=kafka-python-2.1.5, node_id=1 host=kafka:9092 <connecting> [IPv4 ('172.18.0.4', 9092)]>: Closing connection. KafkaConnectionError: DNS failure
[2025-04-18T01:02:25.135+0000] {client_async.py:388} WARNING - Node 1 connection failed -- refreshing metadata
[2025-04-18T01:03:00.913+0000] {fetcher.py:735} ERROR - Fetch to node 1 failed: NodeNotReadyError: 1
[2025-04-18T01:03:00.928+0000] {conn.py:1532} WARNING - DNS lookup failed for kafka:9092, exception was [Errno -2] Name or service not known. Is your advertised.listeners (called advertised.host.name before Kafka 9) correct and resolvable?
[2025-04-18T01:03:00.928+0000] {conn.py:322} ERROR - <BrokerConnection client_id=kafka-python-2.1.5, node_id=1 host=kafka:9092 <connecting> [IPv4 ('172.18.0.4', 9092)]>: DNS lookup failed for kafka:9092 (0)
[2025-04-18T01:03:00.929+0000] {conn.py:936} ERROR - <BrokerConnection client_id=kafka-python-2.1.5, node_id=1 host=kafka:9092 <connecting> [IPv4 ('172.18.0.4', 9092)]>: Closing connection. KafkaConnectionError: DNS failure
[2025-04-18T01:03:00.930+0000] {client_async.py:388} WARNING - Node 1 connection failed -- refreshing metadata
[2025-04-18T01:03:25.928+0000] {fetcher.py:735} ERROR - Fetch to node 1 failed: NodeNotReadyError: 1
[2025-04-18T01:03:25.941+0000] {conn.py:1532} WARNING - DNS lookup failed for kafka:9092, exception was [Errno -2] Name or service not known. Is your advertised.listeners (called advertised.host.name before Kafka 9) correct and resolvable?
[2025-04-18T01:03:25.942+0000] {conn.py:322} ERROR - <BrokerConnection client_id=kafka-python-2.1.5, node_id=1 host=kafka:9092 <connecting> [IPv4 ('172.18.0.4', 9092)]>: DNS lookup failed for kafka:9092 (0)
[2025-04-18T01:03:25.943+0000] {conn.py:936} ERROR - <BrokerConnection client_id=kafka-python-2.1.5, node_id=1 host=kafka:9092 <connecting> [IPv4 ('172.18.0.4', 9092)]>: Closing connection. KafkaConnectionError: DNS failure
[2025-04-18T01:03:25.944+0000] {client_async.py:388} WARNING - Node 1 connection failed -- refreshing metadata
[2025-04-18T01:04:00.030+0000] {fetcher.py:735} ERROR - Fetch to node 1 failed: NodeNotReadyError: 1
[2025-04-18T01:04:00.050+0000] {conn.py:1532} WARNING - DNS lookup failed for kafka:9092, exception was [Errno -2] Name or service not known. Is your advertised.listeners (called advertised.host.name before Kafka 9) correct and resolvable?
[2025-04-18T01:04:00.051+0000] {conn.py:322} ERROR - <BrokerConnection client_id=kafka-python-2.1.5, node_id=1 host=kafka:9092 <connecting> [IPv4 ('172.18.0.4', 9092)]>: DNS lookup failed for kafka:9092 (0)
[2025-04-18T01:04:00.052+0000] {conn.py:936} ERROR - <BrokerConnection client_id=kafka-python-2.1.5, node_id=1 host=kafka:9092 <connecting> [IPv4 ('172.18.0.4', 9092)]>: Closing connection. KafkaConnectionError: DNS failure
[2025-04-18T01:04:00.054+0000] {client_async.py:388} WARNING - Node 1 connection failed -- refreshing metadata
[2025-04-18T01:04:30.916+0000] {fetcher.py:735} ERROR - Fetch to node 1 failed: NodeNotReadyError: 1
[2025-04-18T01:04:30.927+0000] {conn.py:1532} WARNING - DNS lookup failed for kafka:9092, exception was [Errno -2] Name or service not known. Is your advertised.listeners (called advertised.host.name before Kafka 9) correct and resolvable?
[2025-04-18T01:04:30.929+0000] {conn.py:322} ERROR - <BrokerConnection client_id=kafka-python-2.1.5, node_id=1 host=kafka:9092 <connecting> [IPv4 ('172.18.0.4', 9092)]>: DNS lookup failed for kafka:9092 (0)
[2025-04-18T01:04:30.930+0000] {conn.py:936} ERROR - <BrokerConnection client_id=kafka-python-2.1.5, node_id=1 host=kafka:9092 <connecting> [IPv4 ('172.18.0.4', 9092)]>: Closing connection. KafkaConnectionError: DNS failure
[2025-04-18T01:04:30.935+0000] {client_async.py:388} WARNING - Node 1 connection failed -- refreshing metadata
[2025-04-18T01:04:56.745+0000] {fetcher.py:735} ERROR - Fetch to node 1 failed: NodeNotReadyError: 1
[2025-04-18T01:04:56.765+0000] {conn.py:1532} WARNING - DNS lookup failed for kafka:9092, exception was [Errno -2] Name or service not known. Is your advertised.listeners (called advertised.host.name before Kafka 9) correct and resolvable?
[2025-04-18T01:04:56.765+0000] {conn.py:322} ERROR - <BrokerConnection client_id=kafka-python-2.1.5, node_id=1 host=kafka:9092 <connecting> [IPv4 ('172.18.0.4', 9092)]>: DNS lookup failed for kafka:9092 (0)
[2025-04-18T01:04:56.766+0000] {conn.py:936} ERROR - <BrokerConnection client_id=kafka-python-2.1.5, node_id=1 host=kafka:9092 <connecting> [IPv4 ('172.18.0.4', 9092)]>: Closing connection. KafkaConnectionError: DNS failure
[2025-04-18T01:04:56.768+0000] {client_async.py:388} WARNING - Node 1 connection failed -- refreshing metadata
[2025-04-18T01:05:22.181+0000] {fetcher.py:735} ERROR - Fetch to node 1 failed: NodeNotReadyError: 1
[2025-04-18T01:05:22.193+0000] {conn.py:1532} WARNING - DNS lookup failed for kafka:9092, exception was [Errno -2] Name or service not known. Is your advertised.listeners (called advertised.host.name before Kafka 9) correct and resolvable?
[2025-04-18T01:05:22.193+0000] {conn.py:322} ERROR - <BrokerConnection client_id=kafka-python-2.1.5, node_id=1 host=kafka:9092 <connecting> [IPv4 ('172.18.0.4', 9092)]>: DNS lookup failed for kafka:9092 (0)
[2025-04-18T01:05:22.194+0000] {conn.py:936} ERROR - <BrokerConnection client_id=kafka-python-2.1.5, node_id=1 host=kafka:9092 <connecting> [IPv4 ('172.18.0.4', 9092)]>: Closing connection. KafkaConnectionError: DNS failure
[2025-04-18T01:05:22.195+0000] {client_async.py:388} WARNING - Node 1 connection failed -- refreshing metadata
[2025-04-18T01:05:56.389+0000] {fetcher.py:735} ERROR - Fetch to node 1 failed: NodeNotReadyError: 1
[2025-04-18T01:05:56.404+0000] {conn.py:1532} WARNING - DNS lookup failed for kafka:9092, exception was [Errno -2] Name or service not known. Is your advertised.listeners (called advertised.host.name before Kafka 9) correct and resolvable?
[2025-04-18T01:05:56.404+0000] {conn.py:322} ERROR - <BrokerConnection client_id=kafka-python-2.1.5, node_id=1 host=kafka:9092 <connecting> [IPv4 ('172.18.0.4', 9092)]>: DNS lookup failed for kafka:9092 (0)
[2025-04-18T01:05:56.405+0000] {conn.py:936} ERROR - <BrokerConnection client_id=kafka-python-2.1.5, node_id=1 host=kafka:9092 <connecting> [IPv4 ('172.18.0.4', 9092)]>: Closing connection. KafkaConnectionError: DNS failure
[2025-04-18T01:05:56.407+0000] {client_async.py:388} WARNING - Node 1 connection failed -- refreshing metadata
[2025-04-18T01:06:21.554+0000] {fetcher.py:735} ERROR - Fetch to node 1 failed: NodeNotReadyError: 1
[2025-04-18T01:06:21.570+0000] {conn.py:1532} WARNING - DNS lookup failed for kafka:9092, exception was [Errno -2] Name or service not known. Is your advertised.listeners (called advertised.host.name before Kafka 9) correct and resolvable?
[2025-04-18T01:06:21.570+0000] {conn.py:322} ERROR - <BrokerConnection client_id=kafka-python-2.1.5, node_id=1 host=kafka:9092 <connecting> [IPv4 ('172.18.0.4', 9092)]>: DNS lookup failed for kafka:9092 (0)
[2025-04-18T01:06:21.571+0000] {conn.py:936} ERROR - <BrokerConnection client_id=kafka-python-2.1.5, node_id=1 host=kafka:9092 <connecting> [IPv4 ('172.18.0.4', 9092)]>: Closing connection. KafkaConnectionError: DNS failure
[2025-04-18T01:06:21.572+0000] {client_async.py:388} WARNING - Node 1 connection failed -- refreshing metadata
[2025-04-18T01:06:57.215+0000] {fetcher.py:735} ERROR - Fetch to node 1 failed: NodeNotReadyError: 1
[2025-04-18T01:06:57.232+0000] {conn.py:1532} WARNING - DNS lookup failed for kafka:9092, exception was [Errno -2] Name or service not known. Is your advertised.listeners (called advertised.host.name before Kafka 9) correct and resolvable?
[2025-04-18T01:06:57.232+0000] {conn.py:322} ERROR - <BrokerConnection client_id=kafka-python-2.1.5, node_id=1 host=kafka:9092 <connecting> [IPv4 ('172.18.0.4', 9092)]>: DNS lookup failed for kafka:9092 (0)
[2025-04-18T01:06:57.233+0000] {conn.py:936} ERROR - <BrokerConnection client_id=kafka-python-2.1.5, node_id=1 host=kafka:9092 <connecting> [IPv4 ('172.18.0.4', 9092)]>: Closing connection. KafkaConnectionError: DNS failure
[2025-04-18T01:06:57.234+0000] {client_async.py:388} WARNING - Node 1 connection failed -- refreshing metadata
[2025-04-18T01:07:28.068+0000] {fetcher.py:735} ERROR - Fetch to node 1 failed: NodeNotReadyError: 1
[2025-04-18T01:07:28.082+0000] {conn.py:1532} WARNING - DNS lookup failed for kafka:9092, exception was [Errno -2] Name or service not known. Is your advertised.listeners (called advertised.host.name before Kafka 9) correct and resolvable?
[2025-04-18T01:07:28.082+0000] {conn.py:322} ERROR - <BrokerConnection client_id=kafka-python-2.1.5, node_id=1 host=kafka:9092 <connecting> [IPv4 ('172.18.0.4', 9092)]>: DNS lookup failed for kafka:9092 (0)
[2025-04-18T01:07:28.083+0000] {conn.py:936} ERROR - <BrokerConnection client_id=kafka-python-2.1.5, node_id=1 host=kafka:9092 <connecting> [IPv4 ('172.18.0.4', 9092)]>: Closing connection. KafkaConnectionError: DNS failure
[2025-04-18T01:07:28.083+0000] {client_async.py:388} WARNING - Node 1 connection failed -- refreshing metadata
[2025-04-18T01:07:55.634+0000] {fetcher.py:735} ERROR - Fetch to node 1 failed: NodeNotReadyError: 1
[2025-04-18T01:07:55.641+0000] {conn.py:1532} WARNING - DNS lookup failed for kafka:9092, exception was [Errno -2] Name or service not known. Is your advertised.listeners (called advertised.host.name before Kafka 9) correct and resolvable?
[2025-04-18T01:07:55.641+0000] {conn.py:322} ERROR - <BrokerConnection client_id=kafka-python-2.1.5, node_id=1 host=kafka:9092 <connecting> [IPv4 ('172.18.0.4', 9092)]>: DNS lookup failed for kafka:9092 (0)
[2025-04-18T01:07:55.642+0000] {conn.py:936} ERROR - <BrokerConnection client_id=kafka-python-2.1.5, node_id=1 host=kafka:9092 <connecting> [IPv4 ('172.18.0.4', 9092)]>: Closing connection. KafkaConnectionError: DNS failure
[2025-04-18T01:07:55.642+0000] {client_async.py:388} WARNING - Node 1 connection failed -- refreshing metadata
[2025-04-18T01:08:25.068+0000] {fetcher.py:735} ERROR - Fetch to node 1 failed: NodeNotReadyError: 1
[2025-04-18T01:08:25.078+0000] {conn.py:1532} WARNING - DNS lookup failed for kafka:9092, exception was [Errno -2] Name or service not known. Is your advertised.listeners (called advertised.host.name before Kafka 9) correct and resolvable?
[2025-04-18T01:08:25.079+0000] {conn.py:322} ERROR - <BrokerConnection client_id=kafka-python-2.1.5, node_id=1 host=kafka:9092 <connecting> [IPv4 ('172.18.0.4', 9092)]>: DNS lookup failed for kafka:9092 (0)
[2025-04-18T01:08:25.079+0000] {conn.py:936} ERROR - <BrokerConnection client_id=kafka-python-2.1.5, node_id=1 host=kafka:9092 <connecting> [IPv4 ('172.18.0.4', 9092)]>: Closing connection. KafkaConnectionError: DNS failure
[2025-04-18T01:08:25.080+0000] {client_async.py:388} WARNING - Node 1 connection failed -- refreshing metadata
[2025-04-18T01:08:56.720+0000] {fetcher.py:735} ERROR - Fetch to node 1 failed: NodeNotReadyError: 1
[2025-04-18T01:08:56.740+0000] {conn.py:1532} WARNING - DNS lookup failed for kafka:9092, exception was [Errno -2] Name or service not known. Is your advertised.listeners (called advertised.host.name before Kafka 9) correct and resolvable?
[2025-04-18T01:08:56.741+0000] {conn.py:322} ERROR - <BrokerConnection client_id=kafka-python-2.1.5, node_id=1 host=kafka:9092 <connecting> [IPv4 ('172.18.0.4', 9092)]>: DNS lookup failed for kafka:9092 (0)
[2025-04-18T01:08:56.742+0000] {conn.py:936} ERROR - <BrokerConnection client_id=kafka-python-2.1.5, node_id=1 host=kafka:9092 <connecting> [IPv4 ('172.18.0.4', 9092)]>: Closing connection. KafkaConnectionError: DNS failure
[2025-04-18T01:08:56.743+0000] {client_async.py:388} WARNING - Node 1 connection failed -- refreshing metadata
[2025-04-18T01:09:31.397+0000] {fetcher.py:735} ERROR - Fetch to node 1 failed: NodeNotReadyError: 1
[2025-04-18T01:09:31.417+0000] {conn.py:1532} WARNING - DNS lookup failed for kafka:9092, exception was [Errno -2] Name or service not known. Is your advertised.listeners (called advertised.host.name before Kafka 9) correct and resolvable?
[2025-04-18T01:09:31.418+0000] {conn.py:322} ERROR - <BrokerConnection client_id=kafka-python-2.1.5, node_id=1 host=kafka:9092 <connecting> [IPv4 ('172.18.0.4', 9092)]>: DNS lookup failed for kafka:9092 (0)
[2025-04-18T01:09:31.418+0000] {conn.py:936} ERROR - <BrokerConnection client_id=kafka-python-2.1.5, node_id=1 host=kafka:9092 <connecting> [IPv4 ('172.18.0.4', 9092)]>: Closing connection. KafkaConnectionError: DNS failure
[2025-04-18T01:09:31.419+0000] {client_async.py:388} WARNING - Node 1 connection failed -- refreshing metadata
[2025-04-18T01:10:03.244+0000] {fetcher.py:735} ERROR - Fetch to node 1 failed: NodeNotReadyError: 1
[2025-04-18T01:10:03.279+0000] {conn.py:1532} WARNING - DNS lookup failed for kafka:9092, exception was [Errno -2] Name or service not known. Is your advertised.listeners (called advertised.host.name before Kafka 9) correct and resolvable?
[2025-04-18T01:10:03.280+0000] {conn.py:322} ERROR - <BrokerConnection client_id=kafka-python-2.1.5, node_id=1 host=kafka:9092 <connecting> [IPv4 ('172.18.0.4', 9092)]>: DNS lookup failed for kafka:9092 (0)
[2025-04-18T01:10:03.281+0000] {conn.py:936} ERROR - <BrokerConnection client_id=kafka-python-2.1.5, node_id=1 host=kafka:9092 <connecting> [IPv4 ('172.18.0.4', 9092)]>: Closing connection. KafkaConnectionError: DNS failure
[2025-04-18T01:10:03.282+0000] {client_async.py:388} WARNING - Node 1 connection failed -- refreshing metadata
[2025-04-18T01:10:29.649+0000] {fetcher.py:735} ERROR - Fetch to node 1 failed: NodeNotReadyError: 1
[2025-04-18T01:10:29.698+0000] {conn.py:1532} WARNING - DNS lookup failed for kafka:9092, exception was [Errno -2] Name or service not known. Is your advertised.listeners (called advertised.host.name before Kafka 9) correct and resolvable?
[2025-04-18T01:10:29.699+0000] {conn.py:322} ERROR - <BrokerConnection client_id=kafka-python-2.1.5, node_id=1 host=kafka:9092 <connecting> [IPv4 ('172.18.0.4', 9092)]>: DNS lookup failed for kafka:9092 (0)
[2025-04-18T01:10:29.704+0000] {conn.py:936} ERROR - <BrokerConnection client_id=kafka-python-2.1.5, node_id=1 host=kafka:9092 <connecting> [IPv4 ('172.18.0.4', 9092)]>: Closing connection. KafkaConnectionError: DNS failure
[2025-04-18T01:10:29.713+0000] {client_async.py:388} WARNING - Node 1 connection failed -- refreshing metadata
[2025-04-18T01:11:03.021+0000] {fetcher.py:735} ERROR - Fetch to node 1 failed: NodeNotReadyError: 1
[2025-04-18T01:11:03.046+0000] {conn.py:1532} WARNING - DNS lookup failed for kafka:9092, exception was [Errno -2] Name or service not known. Is your advertised.listeners (called advertised.host.name before Kafka 9) correct and resolvable?
[2025-04-18T01:11:03.047+0000] {conn.py:322} ERROR - <BrokerConnection client_id=kafka-python-2.1.5, node_id=1 host=kafka:9092 <connecting> [IPv4 ('172.18.0.4', 9092)]>: DNS lookup failed for kafka:9092 (0)
[2025-04-18T01:11:03.048+0000] {conn.py:936} ERROR - <BrokerConnection client_id=kafka-python-2.1.5, node_id=1 host=kafka:9092 <connecting> [IPv4 ('172.18.0.4', 9092)]>: Closing connection. KafkaConnectionError: DNS failure
[2025-04-18T01:11:03.052+0000] {client_async.py:388} WARNING - Node 1 connection failed -- refreshing metadata
[2025-04-18T01:11:28.317+0000] {fetcher.py:735} ERROR - Fetch to node 1 failed: NodeNotReadyError: 1
[2025-04-18T01:11:28.358+0000] {conn.py:1532} WARNING - DNS lookup failed for kafka:9092, exception was [Errno -2] Name or service not known. Is your advertised.listeners (called advertised.host.name before Kafka 9) correct and resolvable?
[2025-04-18T01:11:28.360+0000] {conn.py:322} ERROR - <BrokerConnection client_id=kafka-python-2.1.5, node_id=1 host=kafka:9092 <connecting> [IPv4 ('172.18.0.4', 9092)]>: DNS lookup failed for kafka:9092 (0)
[2025-04-18T01:11:28.361+0000] {conn.py:936} ERROR - <BrokerConnection client_id=kafka-python-2.1.5, node_id=1 host=kafka:9092 <connecting> [IPv4 ('172.18.0.4', 9092)]>: Closing connection. KafkaConnectionError: DNS failure
[2025-04-18T01:11:28.366+0000] {client_async.py:388} WARNING - Node 1 connection failed -- refreshing metadata
[2025-04-18T01:11:54.240+0000] {fetcher.py:735} ERROR - Fetch to node 1 failed: NodeNotReadyError: 1
[2025-04-18T01:11:54.255+0000] {conn.py:1532} WARNING - DNS lookup failed for kafka:9092, exception was [Errno -2] Name or service not known. Is your advertised.listeners (called advertised.host.name before Kafka 9) correct and resolvable?
[2025-04-18T01:11:54.255+0000] {conn.py:322} ERROR - <BrokerConnection client_id=kafka-python-2.1.5, node_id=1 host=kafka:9092 <connecting> [IPv4 ('172.18.0.4', 9092)]>: DNS lookup failed for kafka:9092 (0)
[2025-04-18T01:11:54.256+0000] {conn.py:936} ERROR - <BrokerConnection client_id=kafka-python-2.1.5, node_id=1 host=kafka:9092 <connecting> [IPv4 ('172.18.0.4', 9092)]>: Closing connection. KafkaConnectionError: DNS failure
[2025-04-18T01:11:54.257+0000] {client_async.py:388} WARNING - Node 1 connection failed -- refreshing metadata
[2025-04-18T01:12:28.113+0000] {fetcher.py:735} ERROR - Fetch to node 1 failed: NodeNotReadyError: 1
[2025-04-18T01:12:28.124+0000] {conn.py:1532} WARNING - DNS lookup failed for kafka:9092, exception was [Errno -2] Name or service not known. Is your advertised.listeners (called advertised.host.name before Kafka 9) correct and resolvable?
[2025-04-18T01:12:28.124+0000] {conn.py:322} ERROR - <BrokerConnection client_id=kafka-python-2.1.5, node_id=1 host=kafka:9092 <connecting> [IPv4 ('172.18.0.4', 9092)]>: DNS lookup failed for kafka:9092 (0)
[2025-04-18T01:12:28.125+0000] {conn.py:936} ERROR - <BrokerConnection client_id=kafka-python-2.1.5, node_id=1 host=kafka:9092 <connecting> [IPv4 ('172.18.0.4', 9092)]>: Closing connection. KafkaConnectionError: DNS failure
[2025-04-18T01:12:28.126+0000] {client_async.py:388} WARNING - Node 1 connection failed -- refreshing metadata
[2025-04-18T01:12:58.117+0000] {fetcher.py:735} ERROR - Fetch to node 1 failed: NodeNotReadyError: 1
[2025-04-18T01:12:58.136+0000] {conn.py:1532} WARNING - DNS lookup failed for kafka:9092, exception was [Errno -2] Name or service not known. Is your advertised.listeners (called advertised.host.name before Kafka 9) correct and resolvable?
[2025-04-18T01:12:58.137+0000] {conn.py:322} ERROR - <BrokerConnection client_id=kafka-python-2.1.5, node_id=1 host=kafka:9092 <connecting> [IPv4 ('172.18.0.4', 9092)]>: DNS lookup failed for kafka:9092 (0)
[2025-04-18T01:12:58.138+0000] {conn.py:936} ERROR - <BrokerConnection client_id=kafka-python-2.1.5, node_id=1 host=kafka:9092 <connecting> [IPv4 ('172.18.0.4', 9092)]>: Closing connection. KafkaConnectionError: DNS failure
[2025-04-18T01:12:58.139+0000] {client_async.py:388} WARNING - Node 1 connection failed -- refreshing metadata
[2025-04-18T01:13:28.242+0000] {fetcher.py:735} ERROR - Fetch to node 1 failed: NodeNotReadyError: 1
[2025-04-18T01:13:28.260+0000] {conn.py:1532} WARNING - DNS lookup failed for kafka:9092, exception was [Errno -2] Name or service not known. Is your advertised.listeners (called advertised.host.name before Kafka 9) correct and resolvable?
[2025-04-18T01:13:28.261+0000] {conn.py:322} ERROR - <BrokerConnection client_id=kafka-python-2.1.5, node_id=1 host=kafka:9092 <connecting> [IPv4 ('172.18.0.4', 9092)]>: DNS lookup failed for kafka:9092 (0)
[2025-04-18T01:13:28.262+0000] {conn.py:936} ERROR - <BrokerConnection client_id=kafka-python-2.1.5, node_id=1 host=kafka:9092 <connecting> [IPv4 ('172.18.0.4', 9092)]>: Closing connection. KafkaConnectionError: DNS failure
[2025-04-18T01:13:28.263+0000] {client_async.py:388} WARNING - Node 1 connection failed -- refreshing metadata
[2025-04-18T01:13:52.831+0000] {fetcher.py:735} ERROR - Fetch to node 1 failed: NodeNotReadyError: 1
[2025-04-18T01:13:52.850+0000] {conn.py:1532} WARNING - DNS lookup failed for kafka:9092, exception was [Errno -2] Name or service not known. Is your advertised.listeners (called advertised.host.name before Kafka 9) correct and resolvable?
[2025-04-18T01:13:52.850+0000] {conn.py:322} ERROR - <BrokerConnection client_id=kafka-python-2.1.5, node_id=1 host=kafka:9092 <connecting> [IPv4 ('172.18.0.4', 9092)]>: DNS lookup failed for kafka:9092 (0)
[2025-04-18T01:13:52.852+0000] {conn.py:936} ERROR - <BrokerConnection client_id=kafka-python-2.1.5, node_id=1 host=kafka:9092 <connecting> [IPv4 ('172.18.0.4', 9092)]>: Closing connection. KafkaConnectionError: DNS failure
[2025-04-18T01:13:52.853+0000] {client_async.py:388} WARNING - Node 1 connection failed -- refreshing metadata
[2025-04-18T01:14:17.291+0000] {fetcher.py:735} ERROR - Fetch to node 1 failed: NodeNotReadyError: 1
[2025-04-18T01:14:17.308+0000] {conn.py:1532} WARNING - DNS lookup failed for kafka:9092, exception was [Errno -2] Name or service not known. Is your advertised.listeners (called advertised.host.name before Kafka 9) correct and resolvable?
[2025-04-18T01:14:17.309+0000] {conn.py:322} ERROR - <BrokerConnection client_id=kafka-python-2.1.5, node_id=1 host=kafka:9092 <connecting> [IPv4 ('172.18.0.4', 9092)]>: DNS lookup failed for kafka:9092 (0)
[2025-04-18T01:14:17.309+0000] {conn.py:936} ERROR - <BrokerConnection client_id=kafka-python-2.1.5, node_id=1 host=kafka:9092 <connecting> [IPv4 ('172.18.0.4', 9092)]>: Closing connection. KafkaConnectionError: DNS failure
[2025-04-18T01:14:17.311+0000] {client_async.py:388} WARNING - Node 1 connection failed -- refreshing metadata
[2025-04-18T01:14:46.949+0000] {fetcher.py:735} ERROR - Fetch to node 1 failed: NodeNotReadyError: 1
[2025-04-18T01:14:46.958+0000] {conn.py:1532} WARNING - DNS lookup failed for kafka:9092, exception was [Errno -2] Name or service not known. Is your advertised.listeners (called advertised.host.name before Kafka 9) correct and resolvable?
[2025-04-18T01:14:46.959+0000] {conn.py:322} ERROR - <BrokerConnection client_id=kafka-python-2.1.5, node_id=1 host=kafka:9092 <connecting> [IPv4 ('172.18.0.4', 9092)]>: DNS lookup failed for kafka:9092 (0)
[2025-04-18T01:14:46.959+0000] {conn.py:936} ERROR - <BrokerConnection client_id=kafka-python-2.1.5, node_id=1 host=kafka:9092 <connecting> [IPv4 ('172.18.0.4', 9092)]>: Closing connection. KafkaConnectionError: DNS failure
[2025-04-18T01:14:46.961+0000] {client_async.py:388} WARNING - Node 1 connection failed -- refreshing metadata
[2025-04-18T01:15:17.310+0000] {fetcher.py:735} ERROR - Fetch to node 1 failed: NodeNotReadyError: 1
[2025-04-18T01:15:17.320+0000] {conn.py:1532} WARNING - DNS lookup failed for kafka:9092, exception was [Errno -2] Name or service not known. Is your advertised.listeners (called advertised.host.name before Kafka 9) correct and resolvable?
[2025-04-18T01:15:17.321+0000] {conn.py:322} ERROR - <BrokerConnection client_id=kafka-python-2.1.5, node_id=1 host=kafka:9092 <connecting> [IPv4 ('172.18.0.4', 9092)]>: DNS lookup failed for kafka:9092 (0)
[2025-04-18T01:15:17.323+0000] {conn.py:936} ERROR - <BrokerConnection client_id=kafka-python-2.1.5, node_id=1 host=kafka:9092 <connecting> [IPv4 ('172.18.0.4', 9092)]>: Closing connection. KafkaConnectionError: DNS failure
[2025-04-18T01:15:17.326+0000] {client_async.py:388} WARNING - Node 1 connection failed -- refreshing metadata
[2025-04-18T01:15:52.331+0000] {fetcher.py:735} ERROR - Fetch to node 1 failed: NodeNotReadyError: 1
[2025-04-18T01:15:52.361+0000] {conn.py:1532} WARNING - DNS lookup failed for kafka:9092, exception was [Errno -2] Name or service not known. Is your advertised.listeners (called advertised.host.name before Kafka 9) correct and resolvable?
[2025-04-18T01:15:52.362+0000] {conn.py:322} ERROR - <BrokerConnection client_id=kafka-python-2.1.5, node_id=1 host=kafka:9092 <connecting> [IPv4 ('172.18.0.4', 9092)]>: DNS lookup failed for kafka:9092 (0)
[2025-04-18T01:15:52.363+0000] {conn.py:936} ERROR - <BrokerConnection client_id=kafka-python-2.1.5, node_id=1 host=kafka:9092 <connecting> [IPv4 ('172.18.0.4', 9092)]>: Closing connection. KafkaConnectionError: DNS failure
[2025-04-18T01:15:52.364+0000] {client_async.py:388} WARNING - Node 1 connection failed -- refreshing metadata
[2025-04-18T01:16:19.110+0000] {fetcher.py:735} ERROR - Fetch to node 1 failed: NodeNotReadyError: 1
[2025-04-18T01:16:19.124+0000] {conn.py:1532} WARNING - DNS lookup failed for kafka:9092, exception was [Errno -2] Name or service not known. Is your advertised.listeners (called advertised.host.name before Kafka 9) correct and resolvable?
[2025-04-18T01:16:19.125+0000] {conn.py:322} ERROR - <BrokerConnection client_id=kafka-python-2.1.5, node_id=1 host=kafka:9092 <connecting> [IPv4 ('172.18.0.4', 9092)]>: DNS lookup failed for kafka:9092 (0)
[2025-04-18T01:16:19.125+0000] {conn.py:936} ERROR - <BrokerConnection client_id=kafka-python-2.1.5, node_id=1 host=kafka:9092 <connecting> [IPv4 ('172.18.0.4', 9092)]>: Closing connection. KafkaConnectionError: DNS failure
[2025-04-18T01:16:19.126+0000] {client_async.py:388} WARNING - Node 1 connection failed -- refreshing metadata
[2025-04-18T01:16:44.950+0000] {fetcher.py:735} ERROR - Fetch to node 1 failed: NodeNotReadyError: 1
[2025-04-18T01:16:44.965+0000] {conn.py:1532} WARNING - DNS lookup failed for kafka:9092, exception was [Errno -2] Name or service not known. Is your advertised.listeners (called advertised.host.name before Kafka 9) correct and resolvable?
[2025-04-18T01:16:44.965+0000] {conn.py:322} ERROR - <BrokerConnection client_id=kafka-python-2.1.5, node_id=1 host=kafka:9092 <connecting> [IPv4 ('172.18.0.4', 9092)]>: DNS lookup failed for kafka:9092 (0)
[2025-04-18T01:16:44.966+0000] {conn.py:936} ERROR - <BrokerConnection client_id=kafka-python-2.1.5, node_id=1 host=kafka:9092 <connecting> [IPv4 ('172.18.0.4', 9092)]>: Closing connection. KafkaConnectionError: DNS failure
[2025-04-18T01:16:44.967+0000] {client_async.py:388} WARNING - Node 1 connection failed -- refreshing metadata
[2025-04-18T01:17:12.280+0000] {fetcher.py:735} ERROR - Fetch to node 1 failed: NodeNotReadyError: 1
[2025-04-18T01:17:12.294+0000] {conn.py:1532} WARNING - DNS lookup failed for kafka:9092, exception was [Errno -2] Name or service not known. Is your advertised.listeners (called advertised.host.name before Kafka 9) correct and resolvable?
[2025-04-18T01:17:12.295+0000] {conn.py:322} ERROR - <BrokerConnection client_id=kafka-python-2.1.5, node_id=1 host=kafka:9092 <connecting> [IPv4 ('172.18.0.4', 9092)]>: DNS lookup failed for kafka:9092 (0)
[2025-04-18T01:17:12.296+0000] {conn.py:936} ERROR - <BrokerConnection client_id=kafka-python-2.1.5, node_id=1 host=kafka:9092 <connecting> [IPv4 ('172.18.0.4', 9092)]>: Closing connection. KafkaConnectionError: DNS failure
[2025-04-18T01:17:12.297+0000] {client_async.py:388} WARNING - Node 1 connection failed -- refreshing metadata
[2025-04-18T01:17:47.006+0000] {fetcher.py:735} ERROR - Fetch to node 1 failed: NodeNotReadyError: 1
[2025-04-18T01:17:47.020+0000] {conn.py:1532} WARNING - DNS lookup failed for kafka:9092, exception was [Errno -2] Name or service not known. Is your advertised.listeners (called advertised.host.name before Kafka 9) correct and resolvable?
[2025-04-18T01:17:47.021+0000] {conn.py:322} ERROR - <BrokerConnection client_id=kafka-python-2.1.5, node_id=1 host=kafka:9092 <connecting> [IPv4 ('172.18.0.4', 9092)]>: DNS lookup failed for kafka:9092 (0)
[2025-04-18T01:17:47.021+0000] {conn.py:936} ERROR - <BrokerConnection client_id=kafka-python-2.1.5, node_id=1 host=kafka:9092 <connecting> [IPv4 ('172.18.0.4', 9092)]>: Closing connection. KafkaConnectionError: DNS failure
[2025-04-18T01:17:47.022+0000] {client_async.py:388} WARNING - Node 1 connection failed -- refreshing metadata
[2025-04-18T01:18:12.449+0000] {fetcher.py:735} ERROR - Fetch to node 1 failed: NodeNotReadyError: 1
[2025-04-18T01:18:12.465+0000] {conn.py:1532} WARNING - DNS lookup failed for kafka:9092, exception was [Errno -2] Name or service not known. Is your advertised.listeners (called advertised.host.name before Kafka 9) correct and resolvable?
[2025-04-18T01:18:12.466+0000] {conn.py:322} ERROR - <BrokerConnection client_id=kafka-python-2.1.5, node_id=1 host=kafka:9092 <connecting> [IPv4 ('172.18.0.4', 9092)]>: DNS lookup failed for kafka:9092 (0)
[2025-04-18T01:18:12.469+0000] {conn.py:936} ERROR - <BrokerConnection client_id=kafka-python-2.1.5, node_id=1 host=kafka:9092 <connecting> [IPv4 ('172.18.0.4', 9092)]>: Closing connection. KafkaConnectionError: DNS failure
[2025-04-18T01:18:12.470+0000] {client_async.py:388} WARNING - Node 1 connection failed -- refreshing metadata
[2025-04-18T01:18:42.367+0000] {fetcher.py:735} ERROR - Fetch to node 1 failed: NodeNotReadyError: 1
[2025-04-18T01:18:42.386+0000] {conn.py:1532} WARNING - DNS lookup failed for kafka:9092, exception was [Errno -2] Name or service not known. Is your advertised.listeners (called advertised.host.name before Kafka 9) correct and resolvable?
[2025-04-18T01:18:42.388+0000] {conn.py:322} ERROR - <BrokerConnection client_id=kafka-python-2.1.5, node_id=1 host=kafka:9092 <connecting> [IPv4 ('172.18.0.4', 9092)]>: DNS lookup failed for kafka:9092 (0)
[2025-04-18T01:18:42.390+0000] {conn.py:936} ERROR - <BrokerConnection client_id=kafka-python-2.1.5, node_id=1 host=kafka:9092 <connecting> [IPv4 ('172.18.0.4', 9092)]>: Closing connection. KafkaConnectionError: DNS failure
[2025-04-18T01:18:42.392+0000] {client_async.py:388} WARNING - Node 1 connection failed -- refreshing metadata
[2025-04-18T01:19:08.951+0000] {fetcher.py:735} ERROR - Fetch to node 1 failed: NodeNotReadyError: 1
[2025-04-18T01:19:08.969+0000] {conn.py:1532} WARNING - DNS lookup failed for kafka:9092, exception was [Errno -2] Name or service not known. Is your advertised.listeners (called advertised.host.name before Kafka 9) correct and resolvable?
[2025-04-18T01:19:08.970+0000] {conn.py:322} ERROR - <BrokerConnection client_id=kafka-python-2.1.5, node_id=1 host=kafka:9092 <connecting> [IPv4 ('172.18.0.4', 9092)]>: DNS lookup failed for kafka:9092 (0)
[2025-04-18T01:19:08.970+0000] {conn.py:936} ERROR - <BrokerConnection client_id=kafka-python-2.1.5, node_id=1 host=kafka:9092 <connecting> [IPv4 ('172.18.0.4', 9092)]>: Closing connection. KafkaConnectionError: DNS failure
[2025-04-18T01:19:08.971+0000] {client_async.py:388} WARNING - Node 1 connection failed -- refreshing metadata
[2025-04-18T01:19:37.585+0000] {fetcher.py:735} ERROR - Fetch to node 1 failed: NodeNotReadyError: 1
[2025-04-18T01:19:37.603+0000] {conn.py:1532} WARNING - DNS lookup failed for kafka:9092, exception was [Errno -2] Name or service not known. Is your advertised.listeners (called advertised.host.name before Kafka 9) correct and resolvable?
[2025-04-18T01:19:37.604+0000] {conn.py:322} ERROR - <BrokerConnection client_id=kafka-python-2.1.5, node_id=1 host=kafka:9092 <connecting> [IPv4 ('172.18.0.4', 9092)]>: DNS lookup failed for kafka:9092 (0)
[2025-04-18T01:19:37.604+0000] {conn.py:936} ERROR - <BrokerConnection client_id=kafka-python-2.1.5, node_id=1 host=kafka:9092 <connecting> [IPv4 ('172.18.0.4', 9092)]>: Closing connection. KafkaConnectionError: DNS failure
[2025-04-18T01:19:37.606+0000] {client_async.py:388} WARNING - Node 1 connection failed -- refreshing metadata
[2025-04-18T01:20:10.239+0000] {fetcher.py:735} ERROR - Fetch to node 1 failed: NodeNotReadyError: 1
[2025-04-18T01:20:10.260+0000] {conn.py:1532} WARNING - DNS lookup failed for kafka:9092, exception was [Errno -2] Name or service not known. Is your advertised.listeners (called advertised.host.name before Kafka 9) correct and resolvable?
[2025-04-18T01:20:10.261+0000] {conn.py:322} ERROR - <BrokerConnection client_id=kafka-python-2.1.5, node_id=1 host=kafka:9092 <connecting> [IPv4 ('172.18.0.4', 9092)]>: DNS lookup failed for kafka:9092 (0)
[2025-04-18T01:20:10.261+0000] {conn.py:936} ERROR - <BrokerConnection client_id=kafka-python-2.1.5, node_id=1 host=kafka:9092 <connecting> [IPv4 ('172.18.0.4', 9092)]>: Closing connection. KafkaConnectionError: DNS failure
[2025-04-18T01:20:10.263+0000] {client_async.py:388} WARNING - Node 1 connection failed -- refreshing metadata
[2025-04-18T01:20:40.757+0000] {fetcher.py:735} ERROR - Fetch to node 1 failed: NodeNotReadyError: 1
[2025-04-18T01:20:40.770+0000] {conn.py:1532} WARNING - DNS lookup failed for kafka:9092, exception was [Errno -2] Name or service not known. Is your advertised.listeners (called advertised.host.name before Kafka 9) correct and resolvable?
[2025-04-18T01:20:40.771+0000] {conn.py:322} ERROR - <BrokerConnection client_id=kafka-python-2.1.5, node_id=1 host=kafka:9092 <connecting> [IPv4 ('172.18.0.4', 9092)]>: DNS lookup failed for kafka:9092 (0)
[2025-04-18T01:20:40.772+0000] {conn.py:936} ERROR - <BrokerConnection client_id=kafka-python-2.1.5, node_id=1 host=kafka:9092 <connecting> [IPv4 ('172.18.0.4', 9092)]>: Closing connection. KafkaConnectionError: DNS failure
[2025-04-18T01:20:40.773+0000] {client_async.py:388} WARNING - Node 1 connection failed -- refreshing metadata
[2025-04-18T01:21:14.021+0000] {fetcher.py:735} ERROR - Fetch to node 1 failed: NodeNotReadyError: 1
[2025-04-18T01:21:14.048+0000] {conn.py:1532} WARNING - DNS lookup failed for kafka:9092, exception was [Errno -2] Name or service not known. Is your advertised.listeners (called advertised.host.name before Kafka 9) correct and resolvable?
[2025-04-18T01:21:14.049+0000] {conn.py:322} ERROR - <BrokerConnection client_id=kafka-python-2.1.5, node_id=1 host=kafka:9092 <connecting> [IPv4 ('172.18.0.4', 9092)]>: DNS lookup failed for kafka:9092 (0)
[2025-04-18T01:21:14.050+0000] {conn.py:936} ERROR - <BrokerConnection client_id=kafka-python-2.1.5, node_id=1 host=kafka:9092 <connecting> [IPv4 ('172.18.0.4', 9092)]>: Closing connection. KafkaConnectionError: DNS failure
[2025-04-18T01:21:14.051+0000] {client_async.py:388} WARNING - Node 1 connection failed -- refreshing metadata
[2025-04-18T01:21:39.954+0000] {fetcher.py:735} ERROR - Fetch to node 1 failed: NodeNotReadyError: 1
[2025-04-18T01:21:39.971+0000] {conn.py:1532} WARNING - DNS lookup failed for kafka:9092, exception was [Errno -2] Name or service not known. Is your advertised.listeners (called advertised.host.name before Kafka 9) correct and resolvable?
[2025-04-18T01:21:39.972+0000] {conn.py:322} ERROR - <BrokerConnection client_id=kafka-python-2.1.5, node_id=1 host=kafka:9092 <connecting> [IPv4 ('172.18.0.4', 9092)]>: DNS lookup failed for kafka:9092 (0)
[2025-04-18T01:21:39.973+0000] {conn.py:936} ERROR - <BrokerConnection client_id=kafka-python-2.1.5, node_id=1 host=kafka:9092 <connecting> [IPv4 ('172.18.0.4', 9092)]>: Closing connection. KafkaConnectionError: DNS failure
[2025-04-18T01:21:39.975+0000] {client_async.py:388} WARNING - Node 1 connection failed -- refreshing metadata
[2025-04-18T01:22:09.407+0000] {fetcher.py:735} ERROR - Fetch to node 1 failed: NodeNotReadyError: 1
[2025-04-18T01:22:09.427+0000] {conn.py:1532} WARNING - DNS lookup failed for kafka:9092, exception was [Errno -2] Name or service not known. Is your advertised.listeners (called advertised.host.name before Kafka 9) correct and resolvable?
[2025-04-18T01:22:09.428+0000] {conn.py:322} ERROR - <BrokerConnection client_id=kafka-python-2.1.5, node_id=1 host=kafka:9092 <connecting> [IPv4 ('172.18.0.4', 9092)]>: DNS lookup failed for kafka:9092 (0)
[2025-04-18T01:22:09.429+0000] {conn.py:936} ERROR - <BrokerConnection client_id=kafka-python-2.1.5, node_id=1 host=kafka:9092 <connecting> [IPv4 ('172.18.0.4', 9092)]>: Closing connection. KafkaConnectionError: DNS failure
[2025-04-18T01:22:09.430+0000] {client_async.py:388} WARNING - Node 1 connection failed -- refreshing metadata
[2025-04-18T01:22:38.232+0000] {fetcher.py:735} ERROR - Fetch to node 1 failed: NodeNotReadyError: 1
[2025-04-18T01:22:38.259+0000] {conn.py:1532} WARNING - DNS lookup failed for kafka:9092, exception was [Errno -2] Name or service not known. Is your advertised.listeners (called advertised.host.name before Kafka 9) correct and resolvable?
[2025-04-18T01:22:38.259+0000] {conn.py:322} ERROR - <BrokerConnection client_id=kafka-python-2.1.5, node_id=1 host=kafka:9092 <connecting> [IPv4 ('172.18.0.4', 9092)]>: DNS lookup failed for kafka:9092 (0)
[2025-04-18T01:22:38.260+0000] {conn.py:936} ERROR - <BrokerConnection client_id=kafka-python-2.1.5, node_id=1 host=kafka:9092 <connecting> [IPv4 ('172.18.0.4', 9092)]>: Closing connection. KafkaConnectionError: DNS failure
[2025-04-18T01:22:38.261+0000] {client_async.py:388} WARNING - Node 1 connection failed -- refreshing metadata
[2025-04-18T01:23:05.832+0000] {fetcher.py:735} ERROR - Fetch to node 1 failed: NodeNotReadyError: 1
[2025-04-18T01:23:05.843+0000] {conn.py:1532} WARNING - DNS lookup failed for kafka:9092, exception was [Errno -2] Name or service not known. Is your advertised.listeners (called advertised.host.name before Kafka 9) correct and resolvable?
[2025-04-18T01:23:05.843+0000] {conn.py:322} ERROR - <BrokerConnection client_id=kafka-python-2.1.5, node_id=1 host=kafka:9092 <connecting> [IPv4 ('172.18.0.4', 9092)]>: DNS lookup failed for kafka:9092 (0)
[2025-04-18T01:23:05.844+0000] {conn.py:936} ERROR - <BrokerConnection client_id=kafka-python-2.1.5, node_id=1 host=kafka:9092 <connecting> [IPv4 ('172.18.0.4', 9092)]>: Closing connection. KafkaConnectionError: DNS failure
[2025-04-18T01:23:05.844+0000] {client_async.py:388} WARNING - Node 1 connection failed -- refreshing metadata
[2025-04-18T01:23:33.673+0000] {fetcher.py:735} ERROR - Fetch to node 1 failed: NodeNotReadyError: 1
[2025-04-18T01:23:33.684+0000] {conn.py:1532} WARNING - DNS lookup failed for kafka:9092, exception was [Errno -2] Name or service not known. Is your advertised.listeners (called advertised.host.name before Kafka 9) correct and resolvable?
[2025-04-18T01:23:33.685+0000] {conn.py:322} ERROR - <BrokerConnection client_id=kafka-python-2.1.5, node_id=1 host=kafka:9092 <connecting> [IPv4 ('172.18.0.4', 9092)]>: DNS lookup failed for kafka:9092 (0)
[2025-04-18T01:23:33.686+0000] {conn.py:936} ERROR - <BrokerConnection client_id=kafka-python-2.1.5, node_id=1 host=kafka:9092 <connecting> [IPv4 ('172.18.0.4', 9092)]>: Closing connection. KafkaConnectionError: DNS failure
[2025-04-18T01:23:33.687+0000] {client_async.py:388} WARNING - Node 1 connection failed -- refreshing metadata
[2025-04-18T01:24:00.313+0000] {fetcher.py:735} ERROR - Fetch to node 1 failed: NodeNotReadyError: 1
[2025-04-18T01:24:00.334+0000] {conn.py:1532} WARNING - DNS lookup failed for kafka:9092, exception was [Errno -2] Name or service not known. Is your advertised.listeners (called advertised.host.name before Kafka 9) correct and resolvable?
[2025-04-18T01:24:00.334+0000] {conn.py:322} ERROR - <BrokerConnection client_id=kafka-python-2.1.5, node_id=1 host=kafka:9092 <connecting> [IPv4 ('172.18.0.4', 9092)]>: DNS lookup failed for kafka:9092 (0)
[2025-04-18T01:24:00.335+0000] {conn.py:936} ERROR - <BrokerConnection client_id=kafka-python-2.1.5, node_id=1 host=kafka:9092 <connecting> [IPv4 ('172.18.0.4', 9092)]>: Closing connection. KafkaConnectionError: DNS failure
[2025-04-18T01:24:00.336+0000] {client_async.py:388} WARNING - Node 1 connection failed -- refreshing metadata
[2025-04-18T01:24:25.181+0000] {fetcher.py:735} ERROR - Fetch to node 1 failed: NodeNotReadyError: 1
[2025-04-18T01:24:25.194+0000] {conn.py:1532} WARNING - DNS lookup failed for kafka:9092, exception was [Errno -2] Name or service not known. Is your advertised.listeners (called advertised.host.name before Kafka 9) correct and resolvable?
[2025-04-18T01:24:25.195+0000] {conn.py:322} ERROR - <BrokerConnection client_id=kafka-python-2.1.5, node_id=1 host=kafka:9092 <connecting> [IPv4 ('172.18.0.4', 9092)]>: DNS lookup failed for kafka:9092 (0)
[2025-04-18T01:24:25.195+0000] {conn.py:936} ERROR - <BrokerConnection client_id=kafka-python-2.1.5, node_id=1 host=kafka:9092 <connecting> [IPv4 ('172.18.0.4', 9092)]>: Closing connection. KafkaConnectionError: DNS failure
[2025-04-18T01:24:25.196+0000] {client_async.py:388} WARNING - Node 1 connection failed -- refreshing metadata
[2025-04-18T01:25:00.785+0000] {fetcher.py:735} ERROR - Fetch to node 1 failed: NodeNotReadyError: 1
[2025-04-18T01:25:00.802+0000] {conn.py:1532} WARNING - DNS lookup failed for kafka:9092, exception was [Errno -2] Name or service not known. Is your advertised.listeners (called advertised.host.name before Kafka 9) correct and resolvable?
[2025-04-18T01:25:00.802+0000] {conn.py:322} ERROR - <BrokerConnection client_id=kafka-python-2.1.5, node_id=1 host=kafka:9092 <connecting> [IPv4 ('172.18.0.4', 9092)]>: DNS lookup failed for kafka:9092 (0)
[2025-04-18T01:25:00.803+0000] {conn.py:936} ERROR - <BrokerConnection client_id=kafka-python-2.1.5, node_id=1 host=kafka:9092 <connecting> [IPv4 ('172.18.0.4', 9092)]>: Closing connection. KafkaConnectionError: DNS failure
[2025-04-18T01:25:00.804+0000] {client_async.py:388} WARNING - Node 1 connection failed -- refreshing metadata
[2025-04-18T01:25:30.377+0000] {fetcher.py:735} ERROR - Fetch to node 1 failed: NodeNotReadyError: 1
[2025-04-18T01:25:30.392+0000] {conn.py:1532} WARNING - DNS lookup failed for kafka:9092, exception was [Errno -2] Name or service not known. Is your advertised.listeners (called advertised.host.name before Kafka 9) correct and resolvable?
[2025-04-18T01:25:30.392+0000] {conn.py:322} ERROR - <BrokerConnection client_id=kafka-python-2.1.5, node_id=1 host=kafka:9092 <connecting> [IPv4 ('172.18.0.4', 9092)]>: DNS lookup failed for kafka:9092 (0)
[2025-04-18T01:25:30.393+0000] {conn.py:936} ERROR - <BrokerConnection client_id=kafka-python-2.1.5, node_id=1 host=kafka:9092 <connecting> [IPv4 ('172.18.0.4', 9092)]>: Closing connection. KafkaConnectionError: DNS failure
[2025-04-18T01:25:30.394+0000] {client_async.py:388} WARNING - Node 1 connection failed -- refreshing metadata
[2025-04-18T01:25:54.742+0000] {fetcher.py:735} ERROR - Fetch to node 1 failed: NodeNotReadyError: 1
[2025-04-18T01:25:54.758+0000] {conn.py:1532} WARNING - DNS lookup failed for kafka:9092, exception was [Errno -2] Name or service not known. Is your advertised.listeners (called advertised.host.name before Kafka 9) correct and resolvable?
[2025-04-18T01:25:54.759+0000] {conn.py:322} ERROR - <BrokerConnection client_id=kafka-python-2.1.5, node_id=1 host=kafka:9092 <connecting> [IPv4 ('172.18.0.4', 9092)]>: DNS lookup failed for kafka:9092 (0)
[2025-04-18T01:25:54.759+0000] {conn.py:936} ERROR - <BrokerConnection client_id=kafka-python-2.1.5, node_id=1 host=kafka:9092 <connecting> [IPv4 ('172.18.0.4', 9092)]>: Closing connection. KafkaConnectionError: DNS failure
[2025-04-18T01:25:54.760+0000] {client_async.py:388} WARNING - Node 1 connection failed -- refreshing metadata
[2025-04-18T01:26:23.787+0000] {fetcher.py:735} ERROR - Fetch to node 1 failed: NodeNotReadyError: 1
[2025-04-18T01:26:23.796+0000] {conn.py:1532} WARNING - DNS lookup failed for kafka:9092, exception was [Errno -2] Name or service not known. Is your advertised.listeners (called advertised.host.name before Kafka 9) correct and resolvable?
[2025-04-18T01:26:23.796+0000] {conn.py:322} ERROR - <BrokerConnection client_id=kafka-python-2.1.5, node_id=1 host=kafka:9092 <connecting> [IPv4 ('172.18.0.4', 9092)]>: DNS lookup failed for kafka:9092 (0)
[2025-04-18T01:26:23.797+0000] {conn.py:936} ERROR - <BrokerConnection client_id=kafka-python-2.1.5, node_id=1 host=kafka:9092 <connecting> [IPv4 ('172.18.0.4', 9092)]>: Closing connection. KafkaConnectionError: DNS failure
[2025-04-18T01:26:23.798+0000] {client_async.py:388} WARNING - Node 1 connection failed -- refreshing metadata
[2025-04-18T01:26:55.501+0000] {fetcher.py:735} ERROR - Fetch to node 1 failed: NodeNotReadyError: 1
[2025-04-18T01:26:55.531+0000] {conn.py:1532} WARNING - DNS lookup failed for kafka:9092, exception was [Errno -2] Name or service not known. Is your advertised.listeners (called advertised.host.name before Kafka 9) correct and resolvable?
[2025-04-18T01:26:55.534+0000] {conn.py:322} ERROR - <BrokerConnection client_id=kafka-python-2.1.5, node_id=1 host=kafka:9092 <connecting> [IPv4 ('172.18.0.4', 9092)]>: DNS lookup failed for kafka:9092 (0)
[2025-04-18T01:26:55.537+0000] {conn.py:936} ERROR - <BrokerConnection client_id=kafka-python-2.1.5, node_id=1 host=kafka:9092 <connecting> [IPv4 ('172.18.0.4', 9092)]>: Closing connection. KafkaConnectionError: DNS failure
[2025-04-18T01:26:55.540+0000] {client_async.py:388} WARNING - Node 1 connection failed -- refreshing metadata
[2025-04-18T01:27:25.115+0000] {fetcher.py:735} ERROR - Fetch to node 1 failed: NodeNotReadyError: 1
[2025-04-18T01:27:25.125+0000] {conn.py:1532} WARNING - DNS lookup failed for kafka:9092, exception was [Errno -2] Name or service not known. Is your advertised.listeners (called advertised.host.name before Kafka 9) correct and resolvable?
[2025-04-18T01:27:25.125+0000] {conn.py:322} ERROR - <BrokerConnection client_id=kafka-python-2.1.5, node_id=1 host=kafka:9092 <connecting> [IPv4 ('172.18.0.4', 9092)]>: DNS lookup failed for kafka:9092 (0)
[2025-04-18T01:27:25.126+0000] {conn.py:936} ERROR - <BrokerConnection client_id=kafka-python-2.1.5, node_id=1 host=kafka:9092 <connecting> [IPv4 ('172.18.0.4', 9092)]>: Closing connection. KafkaConnectionError: DNS failure
[2025-04-18T01:27:25.127+0000] {client_async.py:388} WARNING - Node 1 connection failed -- refreshing metadata
[2025-04-18T01:27:51.505+0000] {fetcher.py:735} ERROR - Fetch to node 1 failed: NodeNotReadyError: 1
[2025-04-18T01:27:51.515+0000] {conn.py:1532} WARNING - DNS lookup failed for kafka:9092, exception was [Errno -2] Name or service not known. Is your advertised.listeners (called advertised.host.name before Kafka 9) correct and resolvable?
[2025-04-18T01:27:51.516+0000] {conn.py:322} ERROR - <BrokerConnection client_id=kafka-python-2.1.5, node_id=1 host=kafka:9092 <connecting> [IPv4 ('172.18.0.4', 9092)]>: DNS lookup failed for kafka:9092 (0)
[2025-04-18T01:27:51.516+0000] {conn.py:936} ERROR - <BrokerConnection client_id=kafka-python-2.1.5, node_id=1 host=kafka:9092 <connecting> [IPv4 ('172.18.0.4', 9092)]>: Closing connection. KafkaConnectionError: DNS failure
[2025-04-18T01:27:51.517+0000] {client_async.py:388} WARNING - Node 1 connection failed -- refreshing metadata
[2025-04-18T01:28:16.457+0000] {fetcher.py:735} ERROR - Fetch to node 1 failed: NodeNotReadyError: 1
[2025-04-18T01:28:16.468+0000] {conn.py:1532} WARNING - DNS lookup failed for kafka:9092, exception was [Errno -2] Name or service not known. Is your advertised.listeners (called advertised.host.name before Kafka 9) correct and resolvable?
[2025-04-18T01:28:16.469+0000] {conn.py:322} ERROR - <BrokerConnection client_id=kafka-python-2.1.5, node_id=1 host=kafka:9092 <connecting> [IPv4 ('172.18.0.4', 9092)]>: DNS lookup failed for kafka:9092 (0)
[2025-04-18T01:28:16.469+0000] {conn.py:936} ERROR - <BrokerConnection client_id=kafka-python-2.1.5, node_id=1 host=kafka:9092 <connecting> [IPv4 ('172.18.0.4', 9092)]>: Closing connection. KafkaConnectionError: DNS failure
[2025-04-18T01:28:16.470+0000] {client_async.py:388} WARNING - Node 1 connection failed -- refreshing metadata
[2025-04-18T01:28:52.015+0000] {fetcher.py:735} ERROR - Fetch to node 1 failed: NodeNotReadyError: 1
[2025-04-18T01:28:52.027+0000] {conn.py:1532} WARNING - DNS lookup failed for kafka:9092, exception was [Errno -2] Name or service not known. Is your advertised.listeners (called advertised.host.name before Kafka 9) correct and resolvable?
[2025-04-18T01:28:52.028+0000] {conn.py:322} ERROR - <BrokerConnection client_id=kafka-python-2.1.5, node_id=1 host=kafka:9092 <connecting> [IPv4 ('172.18.0.4', 9092)]>: DNS lookup failed for kafka:9092 (0)
[2025-04-18T01:28:52.028+0000] {conn.py:936} ERROR - <BrokerConnection client_id=kafka-python-2.1.5, node_id=1 host=kafka:9092 <connecting> [IPv4 ('172.18.0.4', 9092)]>: Closing connection. KafkaConnectionError: DNS failure
[2025-04-18T01:28:52.029+0000] {client_async.py:388} WARNING - Node 1 connection failed -- refreshing metadata
[2025-04-18T01:29:17.286+0000] {fetcher.py:735} ERROR - Fetch to node 1 failed: NodeNotReadyError: 1
[2025-04-18T01:29:17.300+0000] {conn.py:1532} WARNING - DNS lookup failed for kafka:9092, exception was [Errno -2] Name or service not known. Is your advertised.listeners (called advertised.host.name before Kafka 9) correct and resolvable?
[2025-04-18T01:29:17.301+0000] {conn.py:322} ERROR - <BrokerConnection client_id=kafka-python-2.1.5, node_id=1 host=kafka:9092 <connecting> [IPv4 ('172.18.0.4', 9092)]>: DNS lookup failed for kafka:9092 (0)
[2025-04-18T01:29:17.301+0000] {conn.py:936} ERROR - <BrokerConnection client_id=kafka-python-2.1.5, node_id=1 host=kafka:9092 <connecting> [IPv4 ('172.18.0.4', 9092)]>: Closing connection. KafkaConnectionError: DNS failure
[2025-04-18T01:29:17.302+0000] {client_async.py:388} WARNING - Node 1 connection failed -- refreshing metadata
[2025-04-18T01:29:50.592+0000] {fetcher.py:735} ERROR - Fetch to node 1 failed: NodeNotReadyError: 1
[2025-04-18T01:29:50.654+0000] {conn.py:1532} WARNING - DNS lookup failed for kafka:9092, exception was [Errno -2] Name or service not known. Is your advertised.listeners (called advertised.host.name before Kafka 9) correct and resolvable?
[2025-04-18T01:29:50.655+0000] {conn.py:322} ERROR - <BrokerConnection client_id=kafka-python-2.1.5, node_id=1 host=kafka:9092 <connecting> [IPv4 ('172.18.0.4', 9092)]>: DNS lookup failed for kafka:9092 (0)
[2025-04-18T01:29:50.655+0000] {conn.py:936} ERROR - <BrokerConnection client_id=kafka-python-2.1.5, node_id=1 host=kafka:9092 <connecting> [IPv4 ('172.18.0.4', 9092)]>: Closing connection. KafkaConnectionError: DNS failure
[2025-04-18T01:29:50.657+0000] {client_async.py:388} WARNING - Node 1 connection failed -- refreshing metadata
[2025-04-18T01:30:19.728+0000] {fetcher.py:735} ERROR - Fetch to node 1 failed: NodeNotReadyError: 1
[2025-04-18T01:30:19.736+0000] {conn.py:1532} WARNING - DNS lookup failed for kafka:9092, exception was [Errno -2] Name or service not known. Is your advertised.listeners (called advertised.host.name before Kafka 9) correct and resolvable?
[2025-04-18T01:30:19.737+0000] {conn.py:322} ERROR - <BrokerConnection client_id=kafka-python-2.1.5, node_id=1 host=kafka:9092 <connecting> [IPv4 ('172.18.0.4', 9092)]>: DNS lookup failed for kafka:9092 (0)
[2025-04-18T01:30:19.737+0000] {conn.py:936} ERROR - <BrokerConnection client_id=kafka-python-2.1.5, node_id=1 host=kafka:9092 <connecting> [IPv4 ('172.18.0.4', 9092)]>: Closing connection. KafkaConnectionError: DNS failure
[2025-04-18T01:30:19.738+0000] {client_async.py:388} WARNING - Node 1 connection failed -- refreshing metadata
[2025-04-18T01:30:46.740+0000] {fetcher.py:735} ERROR - Fetch to node 1 failed: NodeNotReadyError: 1
[2025-04-18T01:30:46.751+0000] {conn.py:1532} WARNING - DNS lookup failed for kafka:9092, exception was [Errno -2] Name or service not known. Is your advertised.listeners (called advertised.host.name before Kafka 9) correct and resolvable?
[2025-04-18T01:30:46.751+0000] {conn.py:322} ERROR - <BrokerConnection client_id=kafka-python-2.1.5, node_id=1 host=kafka:9092 <connecting> [IPv4 ('172.18.0.4', 9092)]>: DNS lookup failed for kafka:9092 (0)
[2025-04-18T01:30:46.752+0000] {conn.py:936} ERROR - <BrokerConnection client_id=kafka-python-2.1.5, node_id=1 host=kafka:9092 <connecting> [IPv4 ('172.18.0.4', 9092)]>: Closing connection. KafkaConnectionError: DNS failure
[2025-04-18T01:30:46.752+0000] {client_async.py:388} WARNING - Node 1 connection failed -- refreshing metadata
[2025-04-18T01:31:19.536+0000] {fetcher.py:735} ERROR - Fetch to node 1 failed: NodeNotReadyError: 1
[2025-04-18T01:31:19.562+0000] {conn.py:1532} WARNING - DNS lookup failed for kafka:9092, exception was [Errno -2] Name or service not known. Is your advertised.listeners (called advertised.host.name before Kafka 9) correct and resolvable?
[2025-04-18T01:31:19.564+0000] {conn.py:322} ERROR - <BrokerConnection client_id=kafka-python-2.1.5, node_id=1 host=kafka:9092 <connecting> [IPv4 ('172.18.0.4', 9092)]>: DNS lookup failed for kafka:9092 (0)
[2025-04-18T01:31:19.564+0000] {conn.py:936} ERROR - <BrokerConnection client_id=kafka-python-2.1.5, node_id=1 host=kafka:9092 <connecting> [IPv4 ('172.18.0.4', 9092)]>: Closing connection. KafkaConnectionError: DNS failure
[2025-04-18T01:31:19.566+0000] {client_async.py:388} WARNING - Node 1 connection failed -- refreshing metadata
[2025-04-18T01:31:47.744+0000] {fetcher.py:735} ERROR - Fetch to node 1 failed: NodeNotReadyError: 1
[2025-04-18T01:31:47.758+0000] {conn.py:1532} WARNING - DNS lookup failed for kafka:9092, exception was [Errno -2] Name or service not known. Is your advertised.listeners (called advertised.host.name before Kafka 9) correct and resolvable?
[2025-04-18T01:31:47.758+0000] {conn.py:322} ERROR - <BrokerConnection client_id=kafka-python-2.1.5, node_id=1 host=kafka:9092 <connecting> [IPv4 ('172.18.0.4', 9092)]>: DNS lookup failed for kafka:9092 (0)
[2025-04-18T01:31:47.759+0000] {conn.py:936} ERROR - <BrokerConnection client_id=kafka-python-2.1.5, node_id=1 host=kafka:9092 <connecting> [IPv4 ('172.18.0.4', 9092)]>: Closing connection. KafkaConnectionError: DNS failure
[2025-04-18T01:31:47.760+0000] {client_async.py:388} WARNING - Node 1 connection failed -- refreshing metadata
[2025-04-18T01:32:17.122+0000] {fetcher.py:735} ERROR - Fetch to node 1 failed: NodeNotReadyError: 1
[2025-04-18T01:32:17.128+0000] {conn.py:1532} WARNING - DNS lookup failed for kafka:9092, exception was [Errno -2] Name or service not known. Is your advertised.listeners (called advertised.host.name before Kafka 9) correct and resolvable?
[2025-04-18T01:32:17.129+0000] {conn.py:322} ERROR - <BrokerConnection client_id=kafka-python-2.1.5, node_id=1 host=kafka:9092 <connecting> [IPv4 ('172.18.0.4', 9092)]>: DNS lookup failed for kafka:9092 (0)
[2025-04-18T01:32:17.129+0000] {conn.py:936} ERROR - <BrokerConnection client_id=kafka-python-2.1.5, node_id=1 host=kafka:9092 <connecting> [IPv4 ('172.18.0.4', 9092)]>: Closing connection. KafkaConnectionError: DNS failure
[2025-04-18T01:32:17.130+0000] {client_async.py:388} WARNING - Node 1 connection failed -- refreshing metadata
[2025-04-18T01:32:50.879+0000] {fetcher.py:735} ERROR - Fetch to node 1 failed: NodeNotReadyError: 1
[2025-04-18T01:32:50.893+0000] {conn.py:1532} WARNING - DNS lookup failed for kafka:9092, exception was [Errno -2] Name or service not known. Is your advertised.listeners (called advertised.host.name before Kafka 9) correct and resolvable?
[2025-04-18T01:32:50.894+0000] {conn.py:322} ERROR - <BrokerConnection client_id=kafka-python-2.1.5, node_id=1 host=kafka:9092 <connecting> [IPv4 ('172.18.0.4', 9092)]>: DNS lookup failed for kafka:9092 (0)
[2025-04-18T01:32:50.895+0000] {conn.py:936} ERROR - <BrokerConnection client_id=kafka-python-2.1.5, node_id=1 host=kafka:9092 <connecting> [IPv4 ('172.18.0.4', 9092)]>: Closing connection. KafkaConnectionError: DNS failure
[2025-04-18T01:32:50.896+0000] {client_async.py:388} WARNING - Node 1 connection failed -- refreshing metadata
[2025-04-18T01:33:01.043+0000] {local_task_job_runner.py:121} ERROR - Received SIGTERM. Terminating subprocesses
[2025-04-18T01:33:01.376+0000] {process_utils.py:131} INFO - Sending 15 to group 4861. PIDs of all processes in the group: [4861]
[2025-04-18T01:33:01.485+0000] {process_utils.py:86} INFO - Sending the signal 15 to group 4861
[2025-04-18T01:33:01.554+0000] {taskinstance.py:2450} ERROR - Received SIGTERM. Terminating subprocesses.
[2025-04-18T01:33:01.667+0000] {connection.py:718} INFO - closed
[2025-04-18T01:33:03.312+0000] {connection.py:724} INFO - No async queries seem to be running, deleting session
[2025-04-18T01:33:03.469+0000] {mbta_kafka_consumer.py:239} INFO - ✅ Snowflake Connection Closed.
[2025-04-18T01:33:03.593+0000] {taskinstance.py:2698} ERROR - Task failed with exception
Traceback (most recent call last):
  File "/home/airflow/.local/lib/python3.9/site-packages/airflow/models/taskinstance.py", line 433, in _execute_task
    result = execute_callable(context=context, **execute_callable_kwargs)
  File "/home/airflow/.local/lib/python3.9/site-packages/airflow/operators/python.py", line 199, in execute
    return_value = self.execute_callable()
  File "/home/airflow/.local/lib/python3.9/site-packages/airflow/operators/python.py", line 216, in execute_callable
    return self.python_callable(*self.op_args, **self.op_kwargs)
  File "/opt/airflow/dags/mbta_ingestion_dag.py", line 36, in load_to_snowflake
    consume_messages()  # pulls and merges into Snowflake
  File "/opt/airflow/dags/mbta_kafka_consumer.py", line 229, in consume_messages
    for message in consumer:
  File "/home/airflow/.local/lib/python3.9/site-packages/kafka/consumer/group.py", line 1188, in __next__
    return next(self._iterator)
  File "/home/airflow/.local/lib/python3.9/site-packages/kafka/consumer/group.py", line 1160, in _message_generator_v2
    record_map = self.poll(timeout_ms=timeout_ms, update_offsets=False)
  File "/home/airflow/.local/lib/python3.9/site-packages/kafka/consumer/group.py", line 693, in poll
    records = self._poll_once(inner_timeout_ms(), max_records, update_offsets=update_offsets)
  File "/home/airflow/.local/lib/python3.9/site-packages/kafka/consumer/group.py", line 736, in _poll_once
    self._client.poll(timeout_ms=inner_timeout_ms(self._coordinator.time_to_next_poll() * 1000))
  File "/home/airflow/.local/lib/python3.9/site-packages/kafka/client_async.py", line 684, in poll
    self._poll(timeout / 1000)
  File "/home/airflow/.local/lib/python3.9/site-packages/kafka/client_async.py", line 727, in _poll
    ready = self._selector.select(timeout)
  File "/usr/local/lib/python3.9/selectors.py", line 469, in select
    fd_event_list = self._selector.poll(timeout, max_ev)
  File "/home/airflow/.local/lib/python3.9/site-packages/airflow/models/taskinstance.py", line 2452, in signal_handler
    raise AirflowException("Task received SIGTERM signal")
airflow.exceptions.AirflowException: Task received SIGTERM signal
[2025-04-18T01:33:03.620+0000] {taskinstance.py:1138} INFO - Marking task as UP_FOR_RETRY. dag_id=mbta_ingestion_dag, task_id=load_to_snowflake, execution_date=20250418T000000, start_date=20250418T010007, end_date=20250418T013303
[2025-04-18T01:33:03.697+0000] {standard_task_runner.py:107} ERROR - Failed to execute job 24 for task load_to_snowflake (Task received SIGTERM signal; 4861)
[2025-04-18T01:33:03.756+0000] {process_utils.py:79} INFO - Process psutil.Process(pid=4861, status='terminated', exitcode=1, started='01:00:06') (4861) terminated with exit code 1
[2025-04-18T01:33:03.773+0000] {local_task_job_runner.py:234} INFO - Task exited with return code 143
[2025-04-18T01:33:03.964+0000] {taskinstance.py:3280} INFO - 0 downstream tasks scheduled from follow-on schedule check
[2025-04-18T01:46:52.128+0000] {taskinstance.py:1956} INFO - Dependencies all met for dep_context=non-requeueable deps ti=<TaskInstance: mbta_ingestion_dag.load_to_snowflake scheduled__2025-04-18T00:00:00+00:00 [queued]>
[2025-04-18T01:46:52.132+0000] {taskinstance.py:1956} INFO - Dependencies all met for dep_context=requeueable deps ti=<TaskInstance: mbta_ingestion_dag.load_to_snowflake scheduled__2025-04-18T00:00:00+00:00 [queued]>
[2025-04-18T01:46:52.133+0000] {taskinstance.py:2170} INFO - Starting attempt 1 of 2
[2025-04-18T01:46:52.141+0000] {taskinstance.py:2191} INFO - Executing <Task(PythonOperator): load_to_snowflake> on 2025-04-18 00:00:00+00:00
[2025-04-18T01:46:52.145+0000] {standard_task_runner.py:60} INFO - Started process 270 to run task
[2025-04-18T01:46:52.148+0000] {standard_task_runner.py:87} INFO - Running: ['***', 'tasks', 'run', 'mbta_ingestion_dag', 'load_to_snowflake', 'scheduled__2025-04-18T00:00:00+00:00', '--job-id', '6', '--raw', '--subdir', 'DAGS_FOLDER/mbta_ingestion_dag.py', '--cfg-path', '/tmp/tmpfdenjoga']
[2025-04-18T01:46:52.149+0000] {standard_task_runner.py:88} INFO - Job 6: Subtask load_to_snowflake
[2025-04-18T01:46:52.174+0000] {task_command.py:423} INFO - Running <TaskInstance: mbta_ingestion_dag.load_to_snowflake scheduled__2025-04-18T00:00:00+00:00 [running]> on host 62d421885c4a
[2025-04-18T01:46:52.208+0000] {taskinstance.py:2480} INFO - Exporting env vars: AIRFLOW_CTX_DAG_OWNER='***' AIRFLOW_CTX_DAG_ID='mbta_ingestion_dag' AIRFLOW_CTX_TASK_ID='load_to_snowflake' AIRFLOW_CTX_EXECUTION_DATE='2025-04-18T00:00:00+00:00' AIRFLOW_CTX_TRY_NUMBER='1' AIRFLOW_CTX_DAG_RUN_ID='scheduled__2025-04-18T00:00:00+00:00'
[2025-04-18T01:46:52.209+0000] {mbta_ingestion_dag.py:35} INFO - 🚀 Launching Kafka consumer to process and load data into Snowflake...
[2025-04-18T01:46:52.209+0000] {connection.py:370} INFO - Snowflake Connector for Python Version: 3.6.0, Python Version: 3.9.18, Platform: Linux-6.10.14-linuxkit-aarch64-with-glibc2.36
[2025-04-18T01:46:52.211+0000] {connection.py:1171} INFO - This connection is in OCSP Fail Open Mode. TLS Certificates would be checked for validity and revocation status. Any other Certificate Revocation related exceptions or OCSP Responder failures would be disregarded in favor of connectivity.
[2025-04-18T01:46:53.419+0000] {mbta_kafka_consumer.py:45} INFO - ✅ Connected to Snowflake successfully.
[2025-04-18T01:46:53.420+0000] {mbta_kafka_consumer.py:219} INFO - 🚀 Starting MBTA Kafka Consumer...
[2025-04-18T01:46:53.426+0000] {conn.py:395} INFO - <BrokerConnection client_id=kafka-python-2.1.5, node_id=bootstrap-0 host=kafka:9092 <connecting> [IPv4 ('172.18.0.6', 9092)]>: connecting to kafka:9092 [('172.18.0.6', 9092) IPv4]
[2025-04-18T01:46:53.584+0000] {conn.py:615} INFO - <BrokerConnection client_id=kafka-python-2.1.5, node_id=bootstrap-0 host=kafka:9092 <checking_api_versions_recv> [IPv4 ('172.18.0.6', 9092)]>: Broker version identified as 2.6
[2025-04-18T01:46:53.585+0000] {conn.py:456} INFO - <BrokerConnection client_id=kafka-python-2.1.5, node_id=bootstrap-0 host=kafka:9092 <connected> [IPv4 ('172.18.0.6', 9092)]>: Connection complete.
[2025-04-18T01:46:53.593+0000] {consumer.py:119} WARNING - group_id is None: disabling auto-commit.
[2025-04-18T01:46:53.597+0000] {subscription_state.py:182} INFO - Updating subscribed topics to: ('mbta_alerts', 'mbta_routes', 'mbta_stops', 'mbta_vehicles', 'mbta_predictions')
[2025-04-18T01:46:53.784+0000] {cluster.py:317} ERROR - Topic mbta_predictions not found in cluster metadata
[2025-04-18T01:46:53.784+0000] {cluster.py:317} ERROR - Topic mbta_routes not found in cluster metadata
[2025-04-18T01:46:53.785+0000] {cluster.py:317} ERROR - Topic mbta_vehicles not found in cluster metadata
[2025-04-18T01:46:53.785+0000] {cluster.py:317} ERROR - Topic mbta_stops not found in cluster metadata
[2025-04-18T01:46:53.786+0000] {cluster.py:314} WARNING - Topic mbta_alerts is not available during auto-create initialization
[2025-04-18T01:46:53.786+0000] {subscription_state.py:254} INFO - Updated partition assignment: []
[2025-04-18T01:51:53.845+0000] {conn.py:395} INFO - <BrokerConnection client_id=kafka-python-2.1.5, node_id=1 host=kafka:9092 <connecting> [IPv4 ('172.18.0.6', 9092)]>: connecting to kafka:9092 [('172.18.0.6', 9092) IPv4]
[2025-04-18T01:51:53.894+0000] {conn.py:456} INFO - <BrokerConnection client_id=kafka-python-2.1.5, node_id=1 host=kafka:9092 <connected> [IPv4 ('172.18.0.6', 9092)]>: Connection complete.
[2025-04-18T01:51:53.899+0000] {conn.py:936} INFO - <BrokerConnection client_id=kafka-python-2.1.5, node_id=bootstrap-0 host=kafka:9092 <connected> [IPv4 ('172.18.0.6', 9092)]>: Closing connection. 
[2025-04-18T01:51:53.939+0000] {subscription_state.py:254} INFO - Updated partition assignment: [('mbta_routes', 0), ('mbta_alerts', 0), ('mbta_vehicles', 0), ('mbta_predictions', 0), ('mbta_stops', 0)]
[2025-04-18T01:56:47.128+0000] {mbta_kafka_consumer.py:232} INFO - 📥 Received 120 records from topic: mbta_alerts
[2025-04-18T01:56:47.335+0000] {mbta_kafka_consumer.py:56} INFO - 🔍 Sample data for MBTA_ALERTS:
[2025-04-18T01:56:47.336+0000] {mbta_kafka_consumer.py:57} INFO - 
  ALERT_ID  ...                 CREATED_AT
0   638240  ...  2025-04-16T10:52:04-04:00
1   435698  ...  2022-03-15T10:13:31-04:00
2   634497  ...  2025-03-27T14:21:07-04:00
3   634495  ...  2025-03-27T14:18:44-04:00
4   416078  ...  2021-11-04T15:14:54-04:00

[5 rows x 6 columns]
[2025-04-18T01:56:47.447+0000] {cursor.py:1028} INFO - query: [SELECT * FROM MBTA_ALERTS WHERE ALERT_ID IN ('638240','435698','634497','634495'...]
[2025-04-18T01:56:48.879+0000] {cursor.py:1041} INFO - query execution done
[2025-04-18T01:56:48.901+0000] {cursor.py:1205} INFO - Number of results in first chunk: 256
[2025-04-18T01:56:49.834+0000] {mbta_kafka_consumer.py:104} INFO - 🔁 562 new/updated records out of 120 incoming records (some may be duplicate VEHICLE_IDs) for MBTA_ALERTS
[2025-04-18T01:56:49.837+0000] {cursor.py:1028} INFO - query: [MERGE INTO MBTA_ALERTS AS target USING (SELECT '638240', 'Orange Line: Shuttle b...]
[2025-04-18T01:56:52.357+0000] {cursor.py:1041} INFO - query execution done
[2025-04-18T01:56:52.365+0000] {cursor.py:1028} INFO - query: [MERGE INTO MBTA_ALERTS AS target USING (SELECT '435698', 'Bowdoin Escalator 125 ...]
[2025-04-18T01:56:55.076+0000] {cursor.py:1041} INFO - query execution done
[2025-04-18T01:56:55.080+0000] {cursor.py:1028} INFO - query: [MERGE INTO MBTA_ALERTS AS target USING (SELECT '435698', 'Bowdoin Escalator 125 ...]
[2025-04-18T01:56:57.707+0000] {cursor.py:1041} INFO - query execution done
[2025-04-18T01:56:57.709+0000] {cursor.py:1028} INFO - query: [MERGE INTO MBTA_ALERTS AS target USING (SELECT '435698', 'Bowdoin Escalator 125 ...]
[2025-04-18T01:57:00.182+0000] {cursor.py:1041} INFO - query execution done
[2025-04-18T01:57:00.184+0000] {cursor.py:1028} INFO - query: [MERGE INTO MBTA_ALERTS AS target USING (SELECT '435698', 'Bowdoin Escalator 125 ...]
[2025-04-18T01:57:02.755+0000] {cursor.py:1041} INFO - query execution done
[2025-04-18T01:57:02.760+0000] {cursor.py:1028} INFO - query: [MERGE INTO MBTA_ALERTS AS target USING (SELECT '435698', 'Bowdoin Escalator 125 ...]
[2025-04-18T01:57:05.402+0000] {cursor.py:1041} INFO - query execution done
[2025-04-18T01:57:05.404+0000] {cursor.py:1028} INFO - query: [MERGE INTO MBTA_ALERTS AS target USING (SELECT '435698', 'Bowdoin Escalator 125 ...]
[2025-04-18T01:57:07.820+0000] {cursor.py:1041} INFO - query execution done
[2025-04-18T01:57:07.827+0000] {cursor.py:1028} INFO - query: [MERGE INTO MBTA_ALERTS AS target USING (SELECT '435698', 'Bowdoin Escalator 125 ...]
[2025-04-18T01:57:10.718+0000] {cursor.py:1041} INFO - query execution done
[2025-04-18T01:57:10.723+0000] {cursor.py:1028} INFO - query: [MERGE INTO MBTA_ALERTS AS target USING (SELECT '435698', 'Bowdoin Escalator 125 ...]
[2025-04-18T01:57:13.688+0000] {cursor.py:1041} INFO - query execution done
[2025-04-18T01:57:13.694+0000] {cursor.py:1028} INFO - query: [MERGE INTO MBTA_ALERTS AS target USING (SELECT '435698', 'Bowdoin Escalator 125 ...]
[2025-04-18T01:57:16.486+0000] {cursor.py:1041} INFO - query execution done
[2025-04-18T01:57:16.492+0000] {cursor.py:1028} INFO - query: [MERGE INTO MBTA_ALERTS AS target USING (SELECT '435698', 'Bowdoin Escalator 125 ...]
[2025-04-18T01:57:18.797+0000] {cursor.py:1041} INFO - query execution done
[2025-04-18T01:57:18.798+0000] {cursor.py:1028} INFO - query: [MERGE INTO MBTA_ALERTS AS target USING (SELECT '435698', 'Bowdoin Escalator 125 ...]
[2025-04-18T01:57:21.442+0000] {cursor.py:1041} INFO - query execution done
[2025-04-18T01:57:21.446+0000] {cursor.py:1028} INFO - query: [MERGE INTO MBTA_ALERTS AS target USING (SELECT '435698', 'Bowdoin Escalator 125 ...]
[2025-04-18T01:57:23.829+0000] {cursor.py:1041} INFO - query execution done
[2025-04-18T01:57:23.830+0000] {cursor.py:1028} INFO - query: [MERGE INTO MBTA_ALERTS AS target USING (SELECT '435698', 'Bowdoin Escalator 125 ...]
[2025-04-18T01:57:26.145+0000] {cursor.py:1041} INFO - query execution done
[2025-04-18T01:57:26.158+0000] {cursor.py:1028} INFO - query: [MERGE INTO MBTA_ALERTS AS target USING (SELECT '435698', 'Bowdoin Escalator 125 ...]
[2025-04-18T01:57:28.702+0000] {cursor.py:1041} INFO - query execution done
[2025-04-18T01:57:28.706+0000] {cursor.py:1028} INFO - query: [MERGE INTO MBTA_ALERTS AS target USING (SELECT '435698', 'Bowdoin Escalator 125 ...]
[2025-04-18T01:57:31.204+0000] {cursor.py:1041} INFO - query execution done
[2025-04-18T01:57:31.210+0000] {cursor.py:1028} INFO - query: [MERGE INTO MBTA_ALERTS AS target USING (SELECT '435698', 'Bowdoin Escalator 125 ...]
[2025-04-18T01:57:33.543+0000] {cursor.py:1041} INFO - query execution done
[2025-04-18T01:57:33.545+0000] {cursor.py:1028} INFO - query: [MERGE INTO MBTA_ALERTS AS target USING (SELECT '435698', 'Bowdoin Escalator 125 ...]
[2025-04-18T01:57:35.934+0000] {cursor.py:1041} INFO - query execution done
[2025-04-18T01:57:35.938+0000] {cursor.py:1028} INFO - query: [MERGE INTO MBTA_ALERTS AS target USING (SELECT '435698', 'Bowdoin Escalator 125 ...]
[2025-04-18T01:57:38.778+0000] {cursor.py:1041} INFO - query execution done
[2025-04-18T01:57:38.781+0000] {cursor.py:1028} INFO - query: [MERGE INTO MBTA_ALERTS AS target USING (SELECT '634497', 'On Saturday, April 5th...]
[2025-04-18T01:57:41.308+0000] {cursor.py:1041} INFO - query execution done
[2025-04-18T01:57:41.311+0000] {cursor.py:1028} INFO - query: [MERGE INTO MBTA_ALERTS AS target USING (SELECT '634495', 'On Saturday, April 5th...]
[2025-04-18T01:57:44.118+0000] {cursor.py:1041} INFO - query execution done
[2025-04-18T01:57:44.120+0000] {cursor.py:1028} INFO - query: [MERGE INTO MBTA_ALERTS AS target USING (SELECT '416078', 'Lynn Parking Garage ar...]
[2025-04-18T01:57:46.616+0000] {cursor.py:1041} INFO - query execution done
[2025-04-18T01:57:46.619+0000] {cursor.py:1028} INFO - query: [MERGE INTO MBTA_ALERTS AS target USING (SELECT '416078', 'Lynn Parking Garage ar...]
[2025-04-18T01:57:48.988+0000] {cursor.py:1041} INFO - query execution done
[2025-04-18T01:57:48.988+0000] {cursor.py:1028} INFO - query: [MERGE INTO MBTA_ALERTS AS target USING (SELECT '416078', 'Lynn Parking Garage ar...]
[2025-04-18T01:57:51.550+0000] {cursor.py:1041} INFO - query execution done
[2025-04-18T01:57:51.551+0000] {cursor.py:1028} INFO - query: [MERGE INTO MBTA_ALERTS AS target USING (SELECT '416078', 'Lynn Parking Garage ar...]
[2025-04-18T01:57:54.058+0000] {cursor.py:1041} INFO - query execution done
[2025-04-18T01:57:54.063+0000] {cursor.py:1028} INFO - query: [MERGE INTO MBTA_ALERTS AS target USING (SELECT '416078', 'Lynn Parking Garage ar...]
[2025-04-18T01:57:56.451+0000] {cursor.py:1041} INFO - query execution done
[2025-04-18T01:57:56.453+0000] {cursor.py:1028} INFO - query: [MERGE INTO MBTA_ALERTS AS target USING (SELECT '416078', 'Lynn Parking Garage ar...]
[2025-04-18T01:57:59.000+0000] {cursor.py:1041} INFO - query execution done
[2025-04-18T01:57:59.003+0000] {cursor.py:1028} INFO - query: [MERGE INTO MBTA_ALERTS AS target USING (SELECT '416078', 'Lynn Parking Garage ar...]
[2025-04-18T01:58:01.387+0000] {cursor.py:1041} INFO - query execution done
[2025-04-18T01:58:01.388+0000] {cursor.py:1028} INFO - query: [MERGE INTO MBTA_ALERTS AS target USING (SELECT '416078', 'Lynn Parking Garage ar...]
[2025-04-18T01:58:03.964+0000] {cursor.py:1041} INFO - query execution done
[2025-04-18T01:58:03.967+0000] {cursor.py:1028} INFO - query: [MERGE INTO MBTA_ALERTS AS target USING (SELECT '416078', 'Lynn Parking Garage ar...]
[2025-04-18T01:58:06.375+0000] {cursor.py:1041} INFO - query execution done
[2025-04-18T01:58:06.378+0000] {cursor.py:1028} INFO - query: [MERGE INTO MBTA_ALERTS AS target USING (SELECT '416078', 'Lynn Parking Garage ar...]
[2025-04-18T01:58:09.101+0000] {cursor.py:1041} INFO - query execution done
[2025-04-18T01:58:09.103+0000] {cursor.py:1028} INFO - query: [MERGE INTO MBTA_ALERTS AS target USING (SELECT '416078', 'Lynn Parking Garage ar...]
[2025-04-18T01:58:11.550+0000] {cursor.py:1041} INFO - query execution done
[2025-04-18T01:58:11.556+0000] {cursor.py:1028} INFO - query: [MERGE INTO MBTA_ALERTS AS target USING (SELECT '416078', 'Lynn Parking Garage ar...]
[2025-04-18T01:58:14.071+0000] {cursor.py:1041} INFO - query execution done
[2025-04-18T01:58:14.073+0000] {cursor.py:1028} INFO - query: [MERGE INTO MBTA_ALERTS AS target USING (SELECT '416078', 'Lynn Parking Garage ar...]
[2025-04-18T01:58:16.519+0000] {cursor.py:1041} INFO - query execution done
[2025-04-18T01:58:16.522+0000] {cursor.py:1028} INFO - query: [MERGE INTO MBTA_ALERTS AS target USING (SELECT '416078', 'Lynn Parking Garage ar...]
[2025-04-18T01:58:19.102+0000] {cursor.py:1041} INFO - query execution done
[2025-04-18T01:58:19.104+0000] {cursor.py:1028} INFO - query: [MERGE INTO MBTA_ALERTS AS target USING (SELECT '416078', 'Lynn Parking Garage ar...]
[2025-04-18T01:58:21.578+0000] {cursor.py:1041} INFO - query execution done
[2025-04-18T01:58:21.580+0000] {cursor.py:1028} INFO - query: [MERGE INTO MBTA_ALERTS AS target USING (SELECT '416078', 'Lynn Parking Garage ar...]
[2025-04-18T01:58:24.030+0000] {cursor.py:1041} INFO - query execution done
[2025-04-18T01:58:24.031+0000] {cursor.py:1028} INFO - query: [MERGE INTO MBTA_ALERTS AS target USING (SELECT '416078', 'Lynn Parking Garage ar...]
[2025-04-18T01:58:26.863+0000] {cursor.py:1041} INFO - query execution done
[2025-04-18T01:58:26.866+0000] {cursor.py:1028} INFO - query: [MERGE INTO MBTA_ALERTS AS target USING (SELECT '416078', 'Lynn Parking Garage ar...]
[2025-04-18T01:58:29.855+0000] {cursor.py:1041} INFO - query execution done
[2025-04-18T01:58:29.857+0000] {cursor.py:1028} INFO - query: [MERGE INTO MBTA_ALERTS AS target USING (SELECT '637996', 'Route 52 service will ...]
[2025-04-18T01:58:32.841+0000] {cursor.py:1041} INFO - query execution done
[2025-04-18T01:58:32.847+0000] {cursor.py:1028} INFO - query: [MERGE INTO MBTA_ALERTS AS target USING (SELECT '637987', 'Route 66 will be rerou...]
[2025-04-18T01:58:35.496+0000] {cursor.py:1041} INFO - query execution done
[2025-04-18T01:58:35.498+0000] {cursor.py:1028} INFO - query: [MERGE INTO MBTA_ALERTS AS target USING (SELECT '638452', 'Route 44 is experienci...]
[2025-04-18T01:58:38.175+0000] {cursor.py:1041} INFO - query execution done
[2025-04-18T01:58:38.179+0000] {cursor.py:1028} INFO - query: [MERGE INTO MBTA_ALERTS AS target USING (SELECT '636938', 'Due to Boston Marathon...]
[2025-04-18T01:58:40.660+0000] {cursor.py:1041} INFO - query execution done
[2025-04-18T01:58:40.668+0000] {cursor.py:1028} INFO - query: [MERGE INTO MBTA_ALERTS AS target USING (SELECT '633908', 'From March 24 to June ...]
[2025-04-18T01:58:43.131+0000] {cursor.py:1041} INFO - query execution done
[2025-04-18T01:58:43.137+0000] {cursor.py:1028} INFO - query: [MERGE INTO MBTA_ALERTS AS target USING (SELECT '637986', 'Route 504 will be rero...]
[2025-04-18T01:58:45.939+0000] {cursor.py:1041} INFO - query execution done
[2025-04-18T01:58:45.944+0000] {cursor.py:1028} INFO - query: [MERGE INTO MBTA_ALERTS AS target USING (SELECT '630009', 'There is no accessible...]
[2025-04-18T01:58:48.744+0000] {cursor.py:1041} INFO - query execution done
[2025-04-18T01:58:48.752+0000] {cursor.py:1028} INFO - query: [MERGE INTO MBTA_ALERTS AS target USING (SELECT '630009', 'There is no accessible...]
[2025-04-18T01:58:51.312+0000] {cursor.py:1041} INFO - query execution done
[2025-04-18T01:58:51.314+0000] {cursor.py:1028} INFO - query: [MERGE INTO MBTA_ALERTS AS target USING (SELECT '630009', 'There is no accessible...]
[2025-04-18T01:58:53.813+0000] {cursor.py:1041} INFO - query execution done
[2025-04-18T01:58:53.814+0000] {cursor.py:1028} INFO - query: [MERGE INTO MBTA_ALERTS AS target USING (SELECT '630009', 'There is no accessible...]
[2025-04-18T01:58:56.312+0000] {cursor.py:1041} INFO - query execution done
[2025-04-18T01:58:56.313+0000] {cursor.py:1028} INFO - query: [MERGE INTO MBTA_ALERTS AS target USING (SELECT '630009', 'There is no accessible...]
[2025-04-18T01:58:58.822+0000] {cursor.py:1041} INFO - query execution done
[2025-04-18T01:58:58.824+0000] {cursor.py:1028} INFO - query: [MERGE INTO MBTA_ALERTS AS target USING (SELECT '630009', 'There is no accessible...]
[2025-04-18T01:59:01.338+0000] {cursor.py:1041} INFO - query execution done
[2025-04-18T01:59:01.348+0000] {cursor.py:1028} INFO - query: [MERGE INTO MBTA_ALERTS AS target USING (SELECT '630009', 'There is no accessible...]
[2025-04-18T01:59:03.941+0000] {cursor.py:1041} INFO - query execution done
[2025-04-18T01:59:03.944+0000] {cursor.py:1028} INFO - query: [MERGE INTO MBTA_ALERTS AS target USING (SELECT '630009', 'There is no accessible...]
[2025-04-18T01:59:06.607+0000] {cursor.py:1041} INFO - query execution done
[2025-04-18T01:59:06.613+0000] {cursor.py:1028} INFO - query: [MERGE INTO MBTA_ALERTS AS target USING (SELECT '630009', 'There is no accessible...]
[2025-04-18T01:59:09.464+0000] {cursor.py:1041} INFO - query execution done
[2025-04-18T01:59:09.472+0000] {cursor.py:1028} INFO - query: [MERGE INTO MBTA_ALERTS AS target USING (SELECT '630009', 'There is no accessible...]
[2025-04-18T01:59:12.452+0000] {cursor.py:1041} INFO - query execution done
[2025-04-18T01:59:12.458+0000] {cursor.py:1028} INFO - query: [MERGE INTO MBTA_ALERTS AS target USING (SELECT '630009', 'There is no accessible...]
[2025-04-18T01:59:15.179+0000] {cursor.py:1041} INFO - query execution done
[2025-04-18T01:59:15.183+0000] {cursor.py:1028} INFO - query: [MERGE INTO MBTA_ALERTS AS target USING (SELECT '630009', 'There is no accessible...]
[2025-04-18T01:59:17.722+0000] {cursor.py:1041} INFO - query execution done
[2025-04-18T01:59:17.727+0000] {cursor.py:1028} INFO - query: [MERGE INTO MBTA_ALERTS AS target USING (SELECT '630009', 'There is no accessible...]
[2025-04-18T01:59:20.161+0000] {cursor.py:1041} INFO - query execution done
[2025-04-18T01:59:20.167+0000] {cursor.py:1028} INFO - query: [MERGE INTO MBTA_ALERTS AS target USING (SELECT '630009', 'There is no accessible...]
[2025-04-18T01:59:23.056+0000] {cursor.py:1041} INFO - query execution done
[2025-04-18T01:59:23.058+0000] {cursor.py:1028} INFO - query: [MERGE INTO MBTA_ALERTS AS target USING (SELECT '630009', 'There is no accessible...]
[2025-04-18T01:59:25.783+0000] {cursor.py:1041} INFO - query execution done
[2025-04-18T01:59:25.792+0000] {cursor.py:1028} INFO - query: [MERGE INTO MBTA_ALERTS AS target USING (SELECT '630009', 'There is no accessible...]
[2025-04-18T01:59:28.420+0000] {cursor.py:1041} INFO - query execution done
[2025-04-18T01:59:28.422+0000] {cursor.py:1028} INFO - query: [MERGE INTO MBTA_ALERTS AS target USING (SELECT '630009', 'There is no accessible...]
[2025-04-18T01:59:31.008+0000] {cursor.py:1041} INFO - query execution done
[2025-04-18T01:59:31.012+0000] {cursor.py:1028} INFO - query: [MERGE INTO MBTA_ALERTS AS target USING (SELECT '630009', 'There is no accessible...]
[2025-04-18T01:59:33.575+0000] {cursor.py:1041} INFO - query execution done
[2025-04-18T01:59:33.578+0000] {cursor.py:1028} INFO - query: [MERGE INTO MBTA_ALERTS AS target USING (SELECT '637983', 'Route 62 and 76 detour...]
[2025-04-18T01:59:36.280+0000] {cursor.py:1041} INFO - query execution done
[2025-04-18T01:59:36.282+0000] {cursor.py:1028} INFO - query: [MERGE INTO MBTA_ALERTS AS target USING (SELECT '637989', 'Route 59 will be rerou...]
[2025-04-18T01:59:39.331+0000] {cursor.py:1041} INFO - query execution done
[2025-04-18T01:59:39.337+0000] {cursor.py:1028} INFO - query: [MERGE INTO MBTA_ALERTS AS target USING (SELECT '626250', 'Aquarium Escalator 405...]
[2025-04-18T01:59:41.983+0000] {cursor.py:1041} INFO - query execution done
[2025-04-18T01:59:41.984+0000] {cursor.py:1028} INFO - query: [MERGE INTO MBTA_ALERTS AS target USING (SELECT '626250', 'Aquarium Escalator 405...]
[2025-04-18T01:59:44.701+0000] {cursor.py:1041} INFO - query execution done
[2025-04-18T01:59:44.707+0000] {cursor.py:1028} INFO - query: [MERGE INTO MBTA_ALERTS AS target USING (SELECT '626250', 'Aquarium Escalator 405...]
[2025-04-18T01:59:47.140+0000] {cursor.py:1041} INFO - query execution done
[2025-04-18T01:59:47.145+0000] {cursor.py:1028} INFO - query: [MERGE INTO MBTA_ALERTS AS target USING (SELECT '626250', 'Aquarium Escalator 405...]
[2025-04-18T01:59:49.841+0000] {cursor.py:1041} INFO - query execution done
[2025-04-18T01:59:49.843+0000] {cursor.py:1028} INFO - query: [MERGE INTO MBTA_ALERTS AS target USING (SELECT '626250', 'Aquarium Escalator 405...]
[2025-04-18T01:59:52.214+0000] {cursor.py:1041} INFO - query execution done
[2025-04-18T01:59:52.222+0000] {cursor.py:1028} INFO - query: [MERGE INTO MBTA_ALERTS AS target USING (SELECT '626250', 'Aquarium Escalator 405...]
[2025-04-18T01:59:54.717+0000] {cursor.py:1041} INFO - query execution done
[2025-04-18T01:59:54.718+0000] {cursor.py:1028} INFO - query: [MERGE INTO MBTA_ALERTS AS target USING (SELECT '626250', 'Aquarium Escalator 405...]
[2025-04-18T01:59:57.291+0000] {cursor.py:1041} INFO - query execution done
[2025-04-18T01:59:57.298+0000] {cursor.py:1028} INFO - query: [MERGE INTO MBTA_ALERTS AS target USING (SELECT '626250', 'Aquarium Escalator 405...]
[2025-04-18T01:59:59.968+0000] {cursor.py:1041} INFO - query execution done
[2025-04-18T01:59:59.968+0000] {cursor.py:1028} INFO - query: [MERGE INTO MBTA_ALERTS AS target USING (SELECT '626250', 'Aquarium Escalator 405...]
[2025-04-18T02:00:02.984+0000] {cursor.py:1041} INFO - query execution done
[2025-04-18T02:00:02.987+0000] {cursor.py:1028} INFO - query: [MERGE INTO MBTA_ALERTS AS target USING (SELECT '626250', 'Aquarium Escalator 405...]
[2025-04-18T02:00:05.642+0000] {cursor.py:1041} INFO - query execution done
[2025-04-18T02:00:05.647+0000] {cursor.py:1028} INFO - query: [MERGE INTO MBTA_ALERTS AS target USING (SELECT '626250', 'Aquarium Escalator 405...]
[2025-04-18T02:00:08.283+0000] {cursor.py:1041} INFO - query execution done
[2025-04-18T02:00:08.286+0000] {cursor.py:1028} INFO - query: [MERGE INTO MBTA_ALERTS AS target USING (SELECT '626250', 'Aquarium Escalator 405...]
[2025-04-18T02:00:10.901+0000] {cursor.py:1041} INFO - query execution done
[2025-04-18T02:00:10.905+0000] {cursor.py:1028} INFO - query: [MERGE INTO MBTA_ALERTS AS target USING (SELECT '626250', 'Aquarium Escalator 405...]
[2025-04-18T02:00:13.992+0000] {cursor.py:1041} INFO - query execution done
[2025-04-18T02:00:13.999+0000] {cursor.py:1028} INFO - query: [MERGE INTO MBTA_ALERTS AS target USING (SELECT '626250', 'Aquarium Escalator 405...]
[2025-04-18T02:00:17.259+0000] {cursor.py:1041} INFO - query execution done
[2025-04-18T02:00:17.265+0000] {cursor.py:1028} INFO - query: [MERGE INTO MBTA_ALERTS AS target USING (SELECT '626250', 'Aquarium Escalator 405...]
[2025-04-18T02:00:20.016+0000] {cursor.py:1041} INFO - query execution done
[2025-04-18T02:00:20.020+0000] {cursor.py:1028} INFO - query: [MERGE INTO MBTA_ALERTS AS target USING (SELECT '626250', 'Aquarium Escalator 405...]
[2025-04-18T02:00:22.774+0000] {cursor.py:1041} INFO - query execution done
[2025-04-18T02:00:22.778+0000] {cursor.py:1028} INFO - query: [MERGE INTO MBTA_ALERTS AS target USING (SELECT '626250', 'Aquarium Escalator 405...]
[2025-04-18T02:00:25.657+0000] {cursor.py:1041} INFO - query execution done
[2025-04-18T02:00:25.662+0000] {cursor.py:1028} INFO - query: [MERGE INTO MBTA_ALERTS AS target USING (SELECT '626250', 'Aquarium Escalator 405...]
[2025-04-18T02:00:28.485+0000] {cursor.py:1041} INFO - query execution done
[2025-04-18T02:00:28.492+0000] {cursor.py:1028} INFO - query: [MERGE INTO MBTA_ALERTS AS target USING (SELECT '638576', 'Route 77 is experienci...]
[2025-04-18T02:00:31.887+0000] {cursor.py:1041} INFO - query execution done
[2025-04-18T02:00:31.893+0000] {cursor.py:1028} INFO - query: [MERGE INTO MBTA_ALERTS AS target USING (SELECT '637998', 'Route 47 will be rerou...]
[2025-04-18T02:00:35.099+0000] {cursor.py:1041} INFO - query execution done
[2025-04-18T02:00:35.106+0000] {cursor.py:1028} INFO - query: [MERGE INTO MBTA_ALERTS AS target USING (SELECT '638540', 'Route 23 is experienci...]
[2025-04-18T02:00:37.706+0000] {cursor.py:1041} INFO - query execution done
[2025-04-18T02:00:37.714+0000] {cursor.py:1028} INFO - query: [MERGE INTO MBTA_ALERTS AS target USING (SELECT '633776', 'Long Wharf South is cl...]
[2025-04-18T02:00:40.540+0000] {cursor.py:1041} INFO - query execution done
[2025-04-18T02:00:40.545+0000] {cursor.py:1028} INFO - query: [MERGE INTO MBTA_ALERTS AS target USING (SELECT '625935', 'Littleton/Route 495 pa...]
[2025-04-18T02:00:43.553+0000] {cursor.py:1041} INFO - query execution done
[2025-04-18T02:00:43.554+0000] {cursor.py:1028} INFO - query: [MERGE INTO MBTA_ALERTS AS target USING (SELECT '625935', 'Littleton/Route 495 pa...]
[2025-04-18T02:00:46.073+0000] {cursor.py:1041} INFO - query execution done
[2025-04-18T02:00:46.084+0000] {cursor.py:1028} INFO - query: [MERGE INTO MBTA_ALERTS AS target USING (SELECT '625935', 'Littleton/Route 495 pa...]
[2025-04-18T02:00:48.973+0000] {cursor.py:1041} INFO - query execution done
[2025-04-18T02:00:48.977+0000] {cursor.py:1028} INFO - query: [MERGE INTO MBTA_ALERTS AS target USING (SELECT '625935', 'Littleton/Route 495 pa...]
[2025-04-18T02:00:51.946+0000] {cursor.py:1041} INFO - query execution done
[2025-04-18T02:00:51.954+0000] {cursor.py:1028} INFO - query: [MERGE INTO MBTA_ALERTS AS target USING (SELECT '625935', 'Littleton/Route 495 pa...]
[2025-04-18T02:00:55.037+0000] {cursor.py:1041} INFO - query execution done
[2025-04-18T02:00:55.039+0000] {cursor.py:1028} INFO - query: [MERGE INTO MBTA_ALERTS AS target USING (SELECT '625935', 'Littleton/Route 495 pa...]
[2025-04-18T02:00:57.796+0000] {cursor.py:1041} INFO - query execution done
[2025-04-18T02:00:57.800+0000] {cursor.py:1028} INFO - query: [MERGE INTO MBTA_ALERTS AS target USING (SELECT '625935', 'Littleton/Route 495 pa...]
[2025-04-18T02:01:00.496+0000] {cursor.py:1041} INFO - query execution done
[2025-04-18T02:01:00.496+0000] {cursor.py:1028} INFO - query: [MERGE INTO MBTA_ALERTS AS target USING (SELECT '625935', 'Littleton/Route 495 pa...]
[2025-04-18T02:01:03.423+0000] {cursor.py:1041} INFO - query execution done
[2025-04-18T02:01:03.430+0000] {cursor.py:1028} INFO - query: [MERGE INTO MBTA_ALERTS AS target USING (SELECT '625935', 'Littleton/Route 495 pa...]
[2025-04-18T02:01:05.981+0000] {cursor.py:1041} INFO - query execution done
[2025-04-18T02:01:06.108+0000] {cursor.py:1028} INFO - query: [MERGE INTO MBTA_ALERTS AS target USING (SELECT '625935', 'Littleton/Route 495 pa...]
[2025-04-18T02:01:09.236+0000] {cursor.py:1041} INFO - query execution done
[2025-04-18T02:01:09.237+0000] {cursor.py:1028} INFO - query: [MERGE INTO MBTA_ALERTS AS target USING (SELECT '625935', 'Littleton/Route 495 pa...]
[2025-04-18T02:01:11.998+0000] {cursor.py:1041} INFO - query execution done
[2025-04-18T02:01:11.999+0000] {cursor.py:1028} INFO - query: [MERGE INTO MBTA_ALERTS AS target USING (SELECT '625935', 'Littleton/Route 495 pa...]
[2025-04-18T02:01:14.723+0000] {cursor.py:1041} INFO - query execution done
[2025-04-18T02:01:14.725+0000] {cursor.py:1028} INFO - query: [MERGE INTO MBTA_ALERTS AS target USING (SELECT '625935', 'Littleton/Route 495 pa...]
[2025-04-18T02:01:17.502+0000] {cursor.py:1041} INFO - query execution done
[2025-04-18T02:01:17.515+0000] {cursor.py:1028} INFO - query: [MERGE INTO MBTA_ALERTS AS target USING (SELECT '625935', 'Littleton/Route 495 pa...]
[2025-04-18T02:01:20.183+0000] {cursor.py:1041} INFO - query execution done
[2025-04-18T02:01:20.189+0000] {cursor.py:1028} INFO - query: [MERGE INTO MBTA_ALERTS AS target USING (SELECT '625935', 'Littleton/Route 495 pa...]
[2025-04-18T02:01:23.226+0000] {cursor.py:1041} INFO - query execution done
[2025-04-18T02:01:23.230+0000] {cursor.py:1028} INFO - query: [MERGE INTO MBTA_ALERTS AS target USING (SELECT '625935', 'Littleton/Route 495 pa...]
[2025-04-18T02:01:26.290+0000] {cursor.py:1041} INFO - query execution done
[2025-04-18T02:01:26.298+0000] {cursor.py:1028} INFO - query: [MERGE INTO MBTA_ALERTS AS target USING (SELECT '625935', 'Littleton/Route 495 pa...]
[2025-04-18T02:01:29.146+0000] {cursor.py:1041} INFO - query execution done
[2025-04-18T02:01:29.153+0000] {cursor.py:1028} INFO - query: [MERGE INTO MBTA_ALERTS AS target USING (SELECT '625935', 'Littleton/Route 495 pa...]
[2025-04-18T02:01:31.704+0000] {cursor.py:1041} INFO - query execution done
[2025-04-18T02:01:31.708+0000] {cursor.py:1028} INFO - query: [MERGE INTO MBTA_ALERTS AS target USING (SELECT '637949', 'Park Street Escalator ...]
[2025-04-18T02:01:34.562+0000] {cursor.py:1041} INFO - query execution done
[2025-04-18T02:01:34.563+0000] {cursor.py:1028} INFO - query: [MERGE INTO MBTA_ALERTS AS target USING (SELECT '638604', 'Route 62 is experienci...]
[2025-04-18T02:01:38.273+0000] {cursor.py:1041} INFO - query execution done
[2025-04-18T02:01:38.276+0000] {cursor.py:1028} INFO - query: [MERGE INTO MBTA_ALERTS AS target USING (SELECT '637835', 'Due to the 250th anniv...]
[2025-04-18T02:01:41.071+0000] {cursor.py:1041} INFO - query execution done
[2025-04-18T02:01:41.078+0000] {cursor.py:1028} INFO - query: [MERGE INTO MBTA_ALERTS AS target USING (SELECT '584862', 'Commuter Rail train se...]
[2025-04-18T02:01:44.528+0000] {cursor.py:1041} INFO - query execution done
[2025-04-18T02:01:44.537+0000] {cursor.py:1028} INFO - query: [MERGE INTO MBTA_ALERTS AS target USING (SELECT '584862', 'Commuter Rail train se...]
[2025-04-18T02:01:47.367+0000] {cursor.py:1041} INFO - query execution done
[2025-04-18T02:01:47.370+0000] {cursor.py:1028} INFO - query: [MERGE INTO MBTA_ALERTS AS target USING (SELECT '584862', 'Commuter Rail train se...]
[2025-04-18T02:01:49.860+0000] {cursor.py:1041} INFO - query execution done
[2025-04-18T02:01:49.864+0000] {cursor.py:1028} INFO - query: [MERGE INTO MBTA_ALERTS AS target USING (SELECT '584862', 'Commuter Rail train se...]
[2025-04-18T02:01:52.451+0000] {cursor.py:1041} INFO - query execution done
[2025-04-18T02:01:52.461+0000] {cursor.py:1028} INFO - query: [MERGE INTO MBTA_ALERTS AS target USING (SELECT '584862', 'Commuter Rail train se...]
[2025-04-18T02:01:55.624+0000] {cursor.py:1041} INFO - query execution done
[2025-04-18T02:01:55.629+0000] {cursor.py:1028} INFO - query: [MERGE INTO MBTA_ALERTS AS target USING (SELECT '584862', 'Commuter Rail train se...]
[2025-04-18T02:01:59.512+0000] {cursor.py:1041} INFO - query execution done
[2025-04-18T02:01:59.524+0000] {cursor.py:1028} INFO - query: [MERGE INTO MBTA_ALERTS AS target USING (SELECT '584862', 'Commuter Rail train se...]
[2025-04-18T02:02:02.176+0000] {cursor.py:1041} INFO - query execution done
[2025-04-18T02:02:02.182+0000] {cursor.py:1028} INFO - query: [MERGE INTO MBTA_ALERTS AS target USING (SELECT '584862', 'Commuter Rail train se...]
[2025-04-18T02:02:04.692+0000] {cursor.py:1041} INFO - query execution done
[2025-04-18T02:02:04.696+0000] {cursor.py:1028} INFO - query: [MERGE INTO MBTA_ALERTS AS target USING (SELECT '584862', 'Commuter Rail train se...]
[2025-04-18T02:02:07.369+0000] {cursor.py:1041} INFO - query execution done
[2025-04-18T02:02:07.373+0000] {cursor.py:1028} INFO - query: [MERGE INTO MBTA_ALERTS AS target USING (SELECT '584862', 'Commuter Rail train se...]
[2025-04-18T02:02:10.334+0000] {cursor.py:1041} INFO - query execution done
[2025-04-18T02:02:10.343+0000] {cursor.py:1028} INFO - query: [MERGE INTO MBTA_ALERTS AS target USING (SELECT '584862', 'Commuter Rail train se...]
[2025-04-18T02:02:13.231+0000] {cursor.py:1041} INFO - query execution done
[2025-04-18T02:02:13.233+0000] {cursor.py:1028} INFO - query: [MERGE INTO MBTA_ALERTS AS target USING (SELECT '584862', 'Commuter Rail train se...]
[2025-04-18T02:02:15.945+0000] {cursor.py:1041} INFO - query execution done
[2025-04-18T02:02:15.953+0000] {cursor.py:1028} INFO - query: [MERGE INTO MBTA_ALERTS AS target USING (SELECT '584862', 'Commuter Rail train se...]
[2025-04-18T02:02:18.648+0000] {cursor.py:1041} INFO - query execution done
[2025-04-18T02:02:18.658+0000] {cursor.py:1028} INFO - query: [MERGE INTO MBTA_ALERTS AS target USING (SELECT '584862', 'Commuter Rail train se...]
[2025-04-18T02:02:21.603+0000] {cursor.py:1041} INFO - query execution done
[2025-04-18T02:02:21.609+0000] {cursor.py:1028} INFO - query: [MERGE INTO MBTA_ALERTS AS target USING (SELECT '584862', 'Commuter Rail train se...]
[2025-04-18T02:02:24.254+0000] {local_task_job_runner.py:121} ERROR - Received SIGTERM. Terminating subprocesses
[2025-04-18T02:02:24.663+0000] {process_utils.py:131} INFO - Sending 15 to group 270. PIDs of all processes in the group: [270]
[2025-04-18T02:02:24.700+0000] {process_utils.py:86} INFO - Sending the signal 15 to group 270
[2025-04-18T02:02:24.725+0000] {taskinstance.py:2450} ERROR - Received SIGTERM. Terminating subprocesses.
[2025-04-18T02:02:24.826+0000] {mbta_kafka_consumer.py:212} ERROR - ❌ Error processing topic mbta_alerts: Task received SIGTERM signal
[2025-04-18T02:02:32.450+0000] {mbta_kafka_consumer.py:232} INFO - 📥 Received 354 records from topic: mbta_vehicles
[2025-04-18T02:02:32.517+0000] {mbta_kafka_consumer.py:56} INFO - 🔍 Sample data for MBTA_VEHICLES:
[2025-04-18T02:02:32.523+0000] {mbta_kafka_consumer.py:57} INFO - 
   VEHICLE_ID ROUTE_ID  ...         STATUS                 CREATED_AT
0     dLF 958      714  ...  IN_TRANSIT_TO 2025-04-18 02:02:32.457126
1  O-5482910A   Orange  ...     STOPPED_AT 2025-04-18 02:02:32.457170
2       y2078      137  ...     STOPPED_AT 2025-04-18 02:02:32.457191
3       y3258       11  ...     STOPPED_AT 2025-04-18 02:02:32.457194
4       y0832      240  ...     STOPPED_AT 2025-04-18 02:02:32.457200

[5 rows x 8 columns]
[2025-04-18T02:02:32.555+0000] {cursor.py:1028} INFO - query: [SELECT * FROM MBTA_VEHICLES WHERE VEHICLE_ID IN ('dLF 958','O-5482910A','y2078',...]
[2025-04-18T02:02:32.991+0000] {cursor.py:1041} INFO - query execution done
[2025-04-18T02:02:32.995+0000] {cursor.py:1205} INFO - Number of results in first chunk: 227
[2025-04-18T02:02:33.092+0000] {mbta_kafka_consumer.py:104} INFO - 🔁 386 new/updated records out of 354 incoming records (some may be duplicate VEHICLE_IDs) for MBTA_VEHICLES
[2025-04-18T02:02:33.093+0000] {cursor.py:1028} INFO - query: [MERGE INTO MBTA_VEHICLES AS target USING (SELECT 'dLF 958', '714', 42.265598249,...]
[2025-04-18T02:02:33.867+0000] {cursor.py:1041} INFO - query execution done
[2025-04-18T02:02:33.884+0000] {cursor.py:1028} INFO - query: [MERGE INTO MBTA_VEHICLES AS target USING (SELECT 'O-5482910A', 'Orange', 42.3365...]
